Workbook

Sheet Exe Sum
M3: DASHBOARD AREA
O5: McDonalds | AH5: All
P23: 2024

Sheet ChartData
C2: Revenue | I2: Gross Profit | O2: Sales
C3: 2024 | D3: 2023 | E3: 2022 | F3: 2021 | I3: {=C3:F3} -> 2024 | J3: 2023 | K3: 2022 | L3: 2021 | O3: {=_xlfn.ANCHORARRAY(I3)} -> 2024 | P3: 2023 | Q3: 2022 | R3: 2021
B4: Chipotle | C4: {='C24-21'!B4:E4} -> 11313.85 | D4: 9871.65 | E4: 8634.65 | F4: 7547.06 | H4: {=B4:B7} -> Chipotle | I4: =_xlfn.XLOOKUP($I$2,'C24-21'!$A$4:$A$70,'C24-21'!B4:B70)*1000000 -> 3017690000 | J4: =_xlfn.XLOOKUP($I$2,'C24-21'!$A$4:$A$70,'C24-21'!C4:C70)*1000000 -> 2586090000 | K4: =_xlfn.XLOOKUP($I$2,'C24-21'!$A$4:$A$70,'C24-21'!D4:D70)*1000000 -> 2062120000 | L4: =_xlfn.XLOOKUP($I$2,'C24-21'!$A$4:$A$70,'C24-21'!E4:E70)*1000000 -> 1707010000 | N4: {=_xlfn.ANCHORARRAY(H4)} -> Chipotle | O4: =IF('Exe Sum'!$AH$5="All",_xlfn.XLOOKUP($N$4,$B$4:$B$7,C4:C7),IF($N$4='Exe Sum'!$AH$5,_xlfn.XLOOKUP(ChartData!$N$4,ChartData!$B$4:$B$7,ChartData!C4:C7),NA())) -> 11313.85 | P4: =IF('Exe Sum'!$AH$5="All",_xlfn.XLOOKUP($N$4,$B$4:$B$7,D4:D7),IF($N$4='Exe Sum'!$AH$5,_xlfn.XLOOKUP(ChartData!$N$4,ChartData!$B$4:$B$7,ChartData!D4:D7),NA())) -> 9871.65 | Q4: =IF('Exe Sum'!$AH$5="All",_xlfn.XLOOKUP($N$4,$B$4:$B$7,E4:E7),IF($N$4='Exe Sum'!$AH$5,_xlfn.XLOOKUP(ChartData!$N$4,ChartData!$B$4:$B$7,ChartData!E4:E7),NA())) -> 8634.65 | R4: =IF('Exe Sum'!$AH$5="All",_xlfn.XLOOKUP($N$4,$B$4:$B$7,F4:F7),IF($N$4='Exe Sum'!$AH$5,_xlfn.XLOOKUP(ChartData!$N$4,ChartData!$B$4:$B$7,ChartData!F4:F7),NA())) -> 7547.06
B5: Shake Shack | C5: {='S24-21'!B4:E4} -> 1252.61 | D5: 1087.53 | E5: 900.49 | F5: 739.89 | H5: Shake Shack | I5: =_xlfn.XLOOKUP($I$2,'S24-21'!$A$4:$A$71,'S24-21'!B4:B71)*1000000 -> 302470000 | J5: =_xlfn.XLOOKUP($I$2,'S24-21'!$A$4:$A$71,'S24-21'!C4:C71)*1000000 -> 248940000 | K5: =_xlfn.XLOOKUP($I$2,'S24-21'!$A$4:$A$71,'S24-21'!D4:D71)*1000000 -> 183390000 | L5: =_xlfn.XLOOKUP($I$2,'S24-21'!$A$4:$A$71,'S24-21'!E4:E71)*1000000 -> 145260000 | N5: Shake Shack | O5: =IF('Exe Sum'!$AH$5="All",_xlfn.XLOOKUP(ChartData!$N$5,ChartData!$B$4:$B$7,ChartData!C4:C7),IF($N$5='Exe Sum'!$AH$5,_xlfn.XLOOKUP(ChartData!$N$5,ChartData!$B$4:$B$7,ChartData!C4:C7),NA())) -> 1252.61 | P5: =IF('Exe Sum'!$AH$5="All",_xlfn.XLOOKUP(ChartData!$N$5,ChartData!$B$4:$B$7,ChartData!D4:D7),IF($N$5='Exe Sum'!$AH$5,_xlfn.XLOOKUP(ChartData!$N$5,ChartData!$B$4:$B$7,ChartData!D4:D7),NA())) -> 1087.53 | Q5: =IF('Exe Sum'!$AH$5="All",_xlfn.XLOOKUP(ChartData!$N$5,ChartData!$B$4:$B$7,ChartData!E4:E7),IF($N$5='Exe Sum'!$AH$5,_xlfn.XLOOKUP(ChartData!$N$5,ChartData!$B$4:$B$7,ChartData!E4:E7),NA())) -> 900.49 | R5: =IF('Exe Sum'!$AH$5="All",_xlfn.XLOOKUP(ChartData!$N$5,ChartData!$B$4:$B$7,ChartData!F4:F7),IF($N$5='Exe Sum'!$AH$5,_xlfn.XLOOKUP(ChartData!$N$5,ChartData!$B$4:$B$7,ChartData!F4:F7),NA())) -> 739.89
B6: McDonalds | C6: {='M24-21'!B4:E4} -> 25920 | D6: 25494 | E6: 23183 | F6: 23222.9 | H6: McDonalds | I6: =_xlfn.XLOOKUP($I$2,'M24-21'!$A$4:$A$71,'M24-21'!B4:B71)*1000000 -> 14710000000 | J6: =_xlfn.XLOOKUP($I$2,'M24-21'!$A$4:$A$71,'M24-21'!C4:C71)*1000000 -> 14563000000 | K6: =_xlfn.XLOOKUP($I$2,'M24-21'!$A$4:$A$71,'M24-21'!D4:D71)*1000000 -> 13208000000 | L6: =_xlfn.XLOOKUP($I$2,'M24-21'!$A$4:$A$71,'M24-21'!E4:E71)*1000000 -> 12580200000 | N6: McDonalds | O6: =IF('Exe Sum'!$AH$5="All",_xlfn.XLOOKUP(ChartData!$N$6,ChartData!$B$4:$B$7,ChartData!C4:C7),IF($N$6='Exe Sum'!$AH$5,_xlfn.XLOOKUP(ChartData!$N$6,ChartData!$B$4:$B$7,ChartData!C4:C7),NA())) -> 25920 | P6: =IF('Exe Sum'!$AH$5="All",_xlfn.XLOOKUP(ChartData!$N$6,ChartData!$B$4:$B$7,ChartData!D4:D7),IF($N$6='Exe Sum'!$AH$5,_xlfn.XLOOKUP(ChartData!$N$6,ChartData!$B$4:$B$7,ChartData!D4:D7),NA())) -> 25494 | Q6: =IF('Exe Sum'!$AH$5="All",_xlfn.XLOOKUP(ChartData!$N$6,ChartData!$B$4:$B$7,ChartData!E4:E7),IF($N$6='Exe Sum'!$AH$5,_xlfn.XLOOKUP(ChartData!$N$6,ChartData!$B$4:$B$7,ChartData!E4:E7),NA())) -> 23183 | R6: =IF('Exe Sum'!$AH$5="All",_xlfn.XLOOKUP(ChartData!$N$6,ChartData!$B$4:$B$7,ChartData!F4:F7),IF($N$6='Exe Sum'!$AH$5,_xlfn.XLOOKUP(ChartData!$N$6,ChartData!$B$4:$B$7,ChartData!F4:F7),NA())) -> 23222.9
B7: Yum | C7: {='Y24-21'!B4:E4} -> 7549 | D7: 7076 | E7: 6842 | F7: 6584 | H7: Yum | I7: =_xlfn.XLOOKUP($I$2,'Y24-21'!$A$4:$A$72,'Y24-21'!B4:B72)*1000000 -> 5429000000 | J7: =_xlfn.XLOOKUP($I$2,'Y24-21'!$A$4:$A$72,'Y24-21'!C4:C72)*1000000 -> 5302000000 | K7: =_xlfn.XLOOKUP($I$2,'Y24-21'!$A$4:$A$72,'Y24-21'!D4:D72)*1000000 -> 5097000000 | L7: =_xlfn.XLOOKUP($I$2,'Y24-21'!$A$4:$A$72,'Y24-21'!E4:E72)*1000000 -> 4859000000 | N7: Yum | O7: =IF('Exe Sum'!$AH$5="All",_xlfn.XLOOKUP(ChartData!$N$7,ChartData!$B$4:$B$7,ChartData!C4:C7),IF($N$7='Exe Sum'!$AH$5,_xlfn.XLOOKUP(ChartData!$N$7,ChartData!$B$4:$B$7,ChartData!C4:C7),NA())) -> 7549 | P7: =IF('Exe Sum'!$AH$5="All",_xlfn.XLOOKUP(ChartData!$N$7,ChartData!$B$4:$B$7,ChartData!D4:D7),IF($N$7='Exe Sum'!$AH$5,_xlfn.XLOOKUP(ChartData!$N$7,ChartData!$B$4:$B$7,ChartData!D4:D7),NA())) -> 7076 | Q7: =IF('Exe Sum'!$AH$5="All",_xlfn.XLOOKUP(ChartData!$N$7,ChartData!$B$4:$B$7,ChartData!E4:E7),IF($N$7='Exe Sum'!$AH$5,_xlfn.XLOOKUP(ChartData!$N$7,ChartData!$B$4:$B$7,ChartData!E4:E7),NA())) -> 6842 | R7: =IF('Exe Sum'!$AH$5="All",_xlfn.XLOOKUP(ChartData!$N$7,ChartData!$B$4:$B$7,ChartData!F4:F7),IF($N$7='Exe Sum'!$AH$5,_xlfn.XLOOKUP(ChartData!$N$7,ChartData!$B$4:$B$7,ChartData!F4:F7),NA())) -> 6584
B8: All
C9: Revenue | I9: EPS | O9: Gross Profit
C10: {=C3:F3} -> 2024 | D10: 2023 | E10: 2022 | F10: 2021 | I10: {=_xlfn.ANCHORARRAY(I3)} -> 2024 | J10: 2023 | K10: 2022 | L10: 2021 | O10: YOY % Change 2024 2023 | P10: YOY % Change 2023 2022 | Q10: YOY % Change 2022 2021
B11: ='Exe Sum'!O5 -> McDonalds | C11: =_xlfn.XLOOKUP($B$11,$B$4:$B$7,C4:C7) -> 25920 | D11: =_xlfn.XLOOKUP($B$11,$B$4:$B$7,D4:D7) -> 25494 | E11: =_xlfn.XLOOKUP($B$11,$B$4:$B$7,E4:E7) -> 23183 | F11: =_xlfn.XLOOKUP($B$11,$B$4:$B$7,F4:F7) -> 23222.9 | H11: {=_xlfn.ANCHORARRAY(H4)} -> Chipotle | I11: =_xlfn.XLOOKUP(ChartData!$I$9,'YOY CMG'!$A$22:$A$44,'YOY CMG'!C22:C44) -> 1.1211468 | J11: =_xlfn.XLOOKUP(ChartData!$I$9,'YOY CMG'!$A$22:$A$44,'YOY CMG'!D22:D44) -> 0.89183245 | K11: =_xlfn.XLOOKUP(ChartData!$I$9,'YOY CMG'!$A$22:$A$44,'YOY CMG'!F22:F44) -> 0.6456547 | L11: =_xlfn.XLOOKUP(ChartData!$I$9,'YOY CMG'!$A$22:$A$44,'YOY CMG'!H22:H44) -> 0.46422579 | N11: {=_xlfn.ANCHORARRAY(N4)} -> Chipotle | O11: =IF('Exe Sum'!$AH$5="All",_xlfn.XLOOKUP($O$9,'YOY CMG'!$A$3:$A$19,'YOY CMG'!$E$3:$E$19),IF('Exe Sum'!$AH$5=ChartData!$N$11,_xlfn.XLOOKUP($O$9,'YOY CMG'!$A$3:$A$19,'YOY CMG'!$E$3:$E$19),NA())) -> 0.16689288 | P11: =IF('Exe Sum'!$AH$5="All",_xlfn.XLOOKUP($O$9,'YOY CMG'!$A$3:$A$19,'YOY CMG'!$G$3:$G$19),IF('Exe Sum'!$AH$5=ChartData!$N$11,_xlfn.XLOOKUP($O$9,'YOY CMG'!$A$3:$A$19,'YOY CMG'!$G$3:$G$19),NA())) -> 0.25409288 | Q11: =IF('Exe Sum'!$AH$5="All",_xlfn.XLOOKUP($O$9,'YOY CMG'!$A$3:$A$19,'YOY CMG'!$I$3:$I$19),IF('Exe Sum'!$AH$5=ChartData!$N$11,_xlfn.XLOOKUP($O$9,'YOY CMG'!$A$3:$A$19,'YOY CMG'!$I$3:$I$19),NA())) -> 0.20803042
H12: Shake Shack | I12: =_xlfn.XLOOKUP($I$9,'YOY SHAK'!$A$22:$A$44,'YOY SHAK'!C22:C44) -> 0.25633944 | J12: =_xlfn.XLOOKUP($I$9,'YOY SHAK'!$A$22:$A$44,'YOY SHAK'!D22:D44) -> 0.51395231 | K12: =_xlfn.XLOOKUP($I$9,'YOY SHAK'!$A$22:$A$44,'YOY SHAK'!F22:F44) -> -0.54102956 | L12: =_xlfn.XLOOKUP($I$9,'YOY SHAK'!$A$22:$A$44,'YOY SHAK'!H22:H44) -> -0.11665388 | N12: Shake Shack | O12: =IF('Exe Sum'!$AH$5="All",_xlfn.XLOOKUP($O$9,'YOY SHAK'!$A$3:$A$19,'YOY SHAK'!$E$3:$E$19),IF('Exe Sum'!$AH$5=$N$12,_xlfn.XLOOKUP($O$9,'YOY SHAK'!$A$3:$A$19,'YOY SHAK'!$E$3:$E$19),NA())) -> 0.21503173 | P12: =IF('Exe Sum'!$AH$5="All",_xlfn.XLOOKUP($O$9,'YOY SHAK'!$A$3:$A$19,'YOY SHAK'!$G$3:$G$19),IF('Exe Sum'!$AH$5=$N$12,_xlfn.XLOOKUP($O$9,'YOY SHAK'!$A$3:$A$19,'YOY SHAK'!$G$3:$G$19),NA())) -> 0.35743497 | Q12: =IF('Exe Sum'!$AH$5="All",_xlfn.XLOOKUP($O$9,'YOY SHAK'!$A$3:$A$19,'YOY SHAK'!$I$3:$I$19),IF('Exe Sum'!$AH$5=$N$12,_xlfn.XLOOKUP($O$9,'YOY SHAK'!$A$3:$A$19,'YOY SHAK'!$I$3:$I$19),NA())) -> 0.26249484
C13: Net Income | H13: McDonalds | I13: =_xlfn.XLOOKUP($I$9,'YOY MCD'!$A$22:$A$44,'YOY MCD'!C22:C44) -> 11.447863 | J13: =_xlfn.XLOOKUP($I$9,'YOY MCD'!$A$22:$A$44,'YOY MCD'!D22:D44) -> 11.63484 | K13: =_xlfn.XLOOKUP($I$9,'YOY MCD'!$A$22:$A$44,'YOY MCD'!F22:F44) -> 8.3869654 | L13: =_xlfn.XLOOKUP($I$9,'YOY MCD'!$A$22:$A$44,'YOY MCD'!H22:H44) -> 10.110143 | N13: McDonalds | O13: =IF('Exe Sum'!$AH$5="All",_xlfn.XLOOKUP(ChartData!$O$9,'YOY MCD'!$A$3:$A$19,'YOY MCD'!$E$3:$E$19),IF('Exe Sum'!$AH$5=$N$13,_xlfn.XLOOKUP(ChartData!$O$9,'YOY MCD'!$A$3:$A$19,'YOY MCD'!$E$3:$E$19),NA())) -> 0.010094074 | P13: =IF('Exe Sum'!$AH$5="All",_xlfn.XLOOKUP(ChartData!$O$9,'YOY MCD'!$A$3:$A$19,'YOY MCD'!$G$3:$G$19),IF('Exe Sum'!$AH$5=$N$13,_xlfn.XLOOKUP(ChartData!$O$9,'YOY MCD'!$A$3:$A$19,'YOY MCD'!$G$3:$G$19),NA())) -> 0.10258934 | Q13: =IF('Exe Sum'!$AH$5="All",_xlfn.XLOOKUP(ChartData!$O$9,'YOY MCD'!$A$3:$A$19,'YOY MCD'!$I$3:$I$19),IF('Exe Sum'!$AH$5=$N$13,_xlfn.XLOOKUP(ChartData!$O$9,'YOY MCD'!$A$3:$A$19,'YOY MCD'!$I$3:$I$19),NA())) -> 0.049903817
C14: {=_xlfn.ANCHORARRAY(C10)} -> 2024 | D14: 2023 | E14: 2022 | F14: 2021 | H14: Yum | I14: =_xlfn.XLOOKUP($I$9,'YOY Yum'!$A$22:$A$44,'YOY Yum'!C22:C44) -> 5.2695035 | J14: =_xlfn.XLOOKUP($I$9,'YOY Yum'!$A$22:$A$44,'YOY Yum'!D22:D44) -> 5.683274 | K14: =_xlfn.XLOOKUP($I$9,'YOY Yum'!$A$22:$A$44,'YOY Yum'!F22:F44) -> 4.6328671 | L14: =_xlfn.XLOOKUP($I$9,'YOY Yum'!$A$22:$A$44,'YOY Yum'!H22:H44) -> 5.3030303 | N14: Yum | O14: =IF('Exe Sum'!$AH$5="All",_xlfn.XLOOKUP($O$9,'YOY Yum'!$A$3:$A$19,'YOY Yum'!$E$3:$E$19),IF('Exe Sum'!$AH$5=$N$14,_xlfn.XLOOKUP($O$9,'YOY CMG'!$A$3:$A$19,'YOY CMG'!$E$3:$E$19),NA())) -> 0.023953225 | P14: =IF('Exe Sum'!$AH$5="All",_xlfn.XLOOKUP($O$9,'YOY Yum'!$A$3:$A$19,'YOY Yum'!$G$3:$G$19),IF('Exe Sum'!AH5=N14,_xlfn.XLOOKUP($O$9,'YOY Yum'!$A$3:$A$19,'YOY Yum'!$G$3:$G$19),NA())) -> 0.040219737 | Q14: =IF('Exe Sum'!$AH$5="All",_xlfn.XLOOKUP($O$9,'YOY Yum'!$A$3:$A$19,'YOY Yum'!$I$3:$I$19),IF('Exe Sum'!AH5=N14,_xlfn.XLOOKUP($O$9,'YOY Yum'!$A$3:$A$19,'YOY Yum'!$I$3:$I$19),NA())) -> 0.048981272
B15: {=B4:B7} -> Chipotle | C15: {='C24-21'!B15:E15} -> 1534.11 | D15: 1228.74 | E15: 899.1 | F15: 652.98
B16: Shake Shack | C16: {='S24-21'!B18:E18} -> 10.21 | D16: 20.26 | E16: -21.23 | F16: -4.56 | I16: EPS
B17: McDonalds | C17: {='M24-21'!B17:E17} -> 8223 | D17: 8469 | E17: 6177 | F17: 7545.2 | I17: {=_xlfn.ANCHORARRAY(I10)} -> 2024 | J17: 2023 | K17: 2022 | L17: 2021
B18: Yum | C18: {='Y24-21'!B17:E17} -> 1486 | D18: 1597 | E18: 1325 | F18: 1575 | H18: {=_xlfn.ANCHORARRAY(H11)} -> Chipotle | I18: =IF('Exe Sum'!$AH$5="All",_xlfn.XLOOKUP($H$18,$H$11:$H$14,I11:I14),IF($H$18='Exe Sum'!$AH$5,_xlfn.XLOOKUP('Exe Sum'!$AH$5,ChartData!$H$11:$H$14,ChartData!I11:I14),NA())) -> 1.1211468 | J18: =IF('Exe Sum'!$AH$5="All",_xlfn.XLOOKUP($H$18,$H$11:$H$14,J11:J14),IF($H$18='Exe Sum'!$AH$5,_xlfn.XLOOKUP('Exe Sum'!$AH$5,ChartData!$H$11:$H$14,ChartData!J11:J14),NA())) -> 0.89183245 | K18: =IF('Exe Sum'!$AH$5="All",_xlfn.XLOOKUP($H$18,$H$11:$H$14,K11:K14),IF($H$18='Exe Sum'!$AH$5,_xlfn.XLOOKUP('Exe Sum'!$AH$5,ChartData!$H$11:$H$14,ChartData!K11:K14),NA())) -> 0.6456547 | L18: =IF('Exe Sum'!$AH$5="All",_xlfn.XLOOKUP($H$18,$H$11:$H$14,L11:L14),IF($H$18='Exe Sum'!$AH$5,_xlfn.XLOOKUP('Exe Sum'!$AH$5,ChartData!$H$11:$H$14,ChartData!L11:L14),NA())) -> 0.46422579
H19: Shake Shack | I19: {=IF('Exe Sum'!$AH$5="All",_xlfn.XLOOKUP(ChartData!$H$19,ChartData!$H$11:$H$14,ChartData!I11:I14),IF($H$19='Exe Sum'!$AH$5,_xlfn.XLOOKUP('Exe Sum'!$AH$5,_xlfn.ANCHORARRAY(ChartData!$H$11),ChartData!I11:I14),NA()))} -> 0.25633944 | J19: {=IF('Exe Sum'!$AH$5="All",_xlfn.XLOOKUP(ChartData!$H$19,ChartData!$H$11:$H$14,ChartData!J11:J14),IF($H$19='Exe Sum'!$AH$5,_xlfn.XLOOKUP('Exe Sum'!$AH$5,_xlfn.ANCHORARRAY(ChartData!$H$11),ChartData!J11:J14),NA()))} -> 0.51395231 | K19: {=IF('Exe Sum'!$AH$5="All",_xlfn.XLOOKUP(ChartData!$H$19,ChartData!$H$11:$H$14,ChartData!K11:K14),IF($H$19='Exe Sum'!$AH$5,_xlfn.XLOOKUP('Exe Sum'!$AH$5,_xlfn.ANCHORARRAY(ChartData!$H$11),ChartData!K11:K14),NA()))} -> -0.54102956 | L19: {=IF('Exe Sum'!$AH$5="All",_xlfn.XLOOKUP(ChartData!$H$19,ChartData!$H$11:$H$14,ChartData!L11:L14),IF($H$19='Exe Sum'!$AH$5,_xlfn.XLOOKUP('Exe Sum'!$AH$5,_xlfn.ANCHORARRAY(ChartData!$H$11),ChartData!L11:L14),NA()))} -> -0.11665388
C20: Net Income | H20: McDonalds | I20: {=IF('Exe Sum'!$AH$5="All",_xlfn.XLOOKUP(ChartData!$H$20,ChartData!$H$11:$H$14,ChartData!I11:I14),IF($H$20='Exe Sum'!$AH$5,_xlfn.XLOOKUP('Exe Sum'!$AH$5,_xlfn.ANCHORARRAY(ChartData!$H$11),ChartData!I11:I14),NA()))} -> 11.447863 | J20: {=IF('Exe Sum'!$AH$5="All",_xlfn.XLOOKUP(ChartData!$H$20,ChartData!$H$11:$H$14,ChartData!J11:J14),IF($H$20='Exe Sum'!$AH$5,_xlfn.XLOOKUP('Exe Sum'!$AH$5,_xlfn.ANCHORARRAY(ChartData!$H$11),ChartData!J11:J14),NA()))} -> 11.63484 | K20: {=IF('Exe Sum'!$AH$5="All",_xlfn.XLOOKUP(ChartData!$H$20,ChartData!$H$11:$H$14,ChartData!K11:K14),IF($H$20='Exe Sum'!$AH$5,_xlfn.XLOOKUP('Exe Sum'!$AH$5,_xlfn.ANCHORARRAY(ChartData!$H$11),ChartData!K11:K14),NA()))} -> 8.3869654 | L20: {=IF('Exe Sum'!$AH$5="All",_xlfn.XLOOKUP(ChartData!$H$20,ChartData!$H$11:$H$14,ChartData!L11:L14),IF($H$20='Exe Sum'!$AH$5,_xlfn.XLOOKUP('Exe Sum'!$AH$5,_xlfn.ANCHORARRAY(ChartData!$H$11),ChartData!L11:L14),NA()))} -> 10.110143
C21: {=_xlfn.ANCHORARRAY(C14)} -> 2024 | D21: 2023 | E21: 2022 | F21: 2021 | H21: Yum | I21: {=IF('Exe Sum'!$AH$5="All",_xlfn.XLOOKUP(ChartData!$H$21,ChartData!$H$11:$H$14,ChartData!I11:I14),IF($H$21='Exe Sum'!$AH$5,_xlfn.XLOOKUP('Exe Sum'!$AH$5,_xlfn.ANCHORARRAY(ChartData!$H$11),ChartData!I11:I14),NA()))} -> 5.2695035 | J21: {=IF('Exe Sum'!$AH$5="All",_xlfn.XLOOKUP(ChartData!$H$21,ChartData!$H$11:$H$14,ChartData!J11:J14),IF($H$21='Exe Sum'!$AH$5,_xlfn.XLOOKUP('Exe Sum'!$AH$5,_xlfn.ANCHORARRAY(ChartData!$H$11),ChartData!J11:J14),NA()))} -> 5.683274 | K21: {=IF('Exe Sum'!$AH$5="All",_xlfn.XLOOKUP(ChartData!$H$21,ChartData!$H$11:$H$14,ChartData!K11:K14),IF($H$21='Exe Sum'!$AH$5,_xlfn.XLOOKUP('Exe Sum'!$AH$5,_xlfn.ANCHORARRAY(ChartData!$H$11),ChartData!K11:K14),NA()))} -> 4.6328671 | L21: {=IF('Exe Sum'!$AH$5="All",_xlfn.XLOOKUP(ChartData!$H$21,ChartData!$H$11:$H$14,ChartData!L11:L14),IF($H$21='Exe Sum'!$AH$5,_xlfn.XLOOKUP('Exe Sum'!$AH$5,_xlfn.ANCHORARRAY(ChartData!$H$11),ChartData!L11:L14),NA()))} -> 5.3030303
B22: ='Exe Sum'!O5 -> McDonalds | C22: =_xlfn.XLOOKUP($B$22,$B$15:$B$18,C15:C18) -> 8223 | D22: =_xlfn.XLOOKUP($B$22,$B$15:$B$18,D15:D18) -> 8469 | E22: =_xlfn.XLOOKUP($B$22,$B$15:$B$18,E15:E18) -> 6177 | F22: =_xlfn.XLOOKUP($B$22,$B$15:$B$18,F15:F18) -> 7545.2
I23: P/E
C24: Net Profit Margin | I24: {=_xlfn.ANCHORARRAY(I17)} -> 2024 | J24: 2023 | K24: 2022 | L24: 2021
C25: {=_xlfn.ANCHORARRAY(C21)} -> 2024 | D25: 2023 | E25: 2022 | F25: 2021 | H25: {=_xlfn.ANCHORARRAY(H18)} -> Chipotle | I25: =_xlfn.XLOOKUP($I$23,'YOY CMG'!$A$22:$A$44,'YOY CMG'!C22:C44) -> 53.596907 | J25: =_xlfn.XLOOKUP($I$23,'YOY CMG'!$A$22:$A$44,'YOY CMG'!D22:D44) -> 51.28766 | K25: =_xlfn.XLOOKUP($I$23,'YOY CMG'!$A$22:$A$44,'YOY CMG'!F22:F44) -> 42.97963 | L25: =_xlfn.XLOOKUP($I$23,'YOY CMG'!$A$22:$A$44,'YOY CMG'!H22:H44) -> 75.265098
B26: {=_xlfn.ANCHORARRAY(B15)} -> Chipotle | C26: {='C24-21'!B23:E23} -> 0.1356 | D26: 0.1245 | E26: 0.1041 | F26: 0.0865 | H26: Shake Shack | I26: =_xlfn.XLOOKUP($I$23,'YOY SHAK'!$A$22:$A$44,'YOY SHAK'!C22:C44) -> 505.22853 | J26: =_xlfn.XLOOKUP($I$23,'YOY SHAK'!$A$22:$A$44,'YOY SHAK'!D22:D44) -> 144.21572 | K26: =_xlfn.XLOOKUP($I$23,'YOY SHAK'!$A$22:$A$44,'YOY SHAK'!F22:F44) -> -76.761055 | L26: =_xlfn.XLOOKUP($I$23,'YOY SHAK'!$A$22:$A$44,'YOY SHAK'!H22:H44) -> -626.38296
B27: Shake Shack | C27: {='S24-21'!B26:E26} -> 0.0081 | D27: 0.0186 | E27: -0.0236 | F27: -0.0062 | H27: McDonalds | I27: =_xlfn.XLOOKUP($I$23,'YOY MCD'!$A$22:$A$44,'YOY MCD'!C22:C44) -> 25.297298 | J27: =_xlfn.XLOOKUP($I$23,'YOY MCD'!$A$22:$A$44,'YOY MCD'!D22:D44) -> 25.484665 | K27: =_xlfn.XLOOKUP($I$23,'YOY MCD'!$A$22:$A$44,'YOY MCD'!F22:F44) -> 31.421377 | L27: =_xlfn.XLOOKUP($I$23,'YOY MCD'!$A$22:$A$44,'YOY MCD'!H22:H44) -> 26.429892
B28: McDonalds | C28: {='M24-21'!B25:E25} -> 0.3172 | D28: 0.3322 | E28: 0.2664 | F28: 0.3249 | H28: Yum | I28: =_xlfn.XLOOKUP($I$23,'YOY Yum'!$A$22:$A$44,'YOY Yum'!C22:C44) -> 25.33825 | J28: =_xlfn.XLOOKUP($I$23,'YOY Yum'!$A$22:$A$44,'YOY Yum'!D22:D44) -> 22.990269 | K28: =_xlfn.XLOOKUP($I$23,'YOY Yum'!$A$22:$A$44,'YOY Yum'!F22:F44) -> 27.645947 | L28: =_xlfn.XLOOKUP($I$23,'YOY Yum'!$A$22:$A$44,'YOY Yum'!H22:H44) -> 26.0964
B29: Yum | C29: {='Y24-21'!B25:E25} -> 0.1968 | D29: 0.2257 | E29: 0.1937 | F29: 0.2392
I30: P/E
C31: Net Profit Margin | I31: {=_xlfn.ANCHORARRAY(I24)} -> 2024 | J31: 2023 | K31: 2022 | L31: 2021
C32: {=_xlfn.ANCHORARRAY(C25)} -> 2024 | D32: 2023 | E32: 2022 | F32: 2021 | H32: {=_xlfn.ANCHORARRAY(H25)} -> Chipotle | I32: =IF('Exe Sum'!$P$23=ChartData!$I$31,_xlfn.XLOOKUP(ChartData!H32,ChartData!$H$25:$H$28,ChartData!$I$25:$I$28),NA()) -> 53.596907 | J32: {=IF($J$31='Exe Sum'!$P$23,_xlfn.XLOOKUP(ChartData!H32,_xlfn.ANCHORARRAY(ChartData!$H$25),ChartData!$J$25:$J$28),NA())} -> #N/A | K32: {=IF($K$31='Exe Sum'!$P$23,_xlfn.XLOOKUP(ChartData!H32,_xlfn.ANCHORARRAY(ChartData!$H$25),ChartData!$K$25:$K$28),NA())} -> #N/A | L32: {=IF($L$31='Exe Sum'!$P$23,_xlfn.XLOOKUP(ChartData!H32,_xlfn.ANCHORARRAY(ChartData!$H$25),ChartData!$L$25:$L$28),NA())} -> #N/A
B33: ='Exe Sum'!O5 -> McDonalds | C33: {=_xlfn.XLOOKUP($B$33,_xlfn.ANCHORARRAY($B$26),C26:C29)} -> 0.3172 | D33: {=_xlfn.XLOOKUP($B$33,_xlfn.ANCHORARRAY($B$26),D26:D29)} -> 0.3322 | E33: {=_xlfn.XLOOKUP($B$33,_xlfn.ANCHORARRAY($B$26),E26:E29)} -> 0.2664 | F33: {=_xlfn.XLOOKUP($B$33,_xlfn.ANCHORARRAY($B$26),F26:F29)} -> 0.3249 | H33: Shake Shack | I33: =IF('Exe Sum'!$P$23=ChartData!$I$31,_xlfn.XLOOKUP(ChartData!H33,ChartData!$H$25:$H$28,ChartData!$I$25:$I$28),NA()) -> 505.22853 | J33: {=IF($J$31='Exe Sum'!$P$23,_xlfn.XLOOKUP(ChartData!H33,_xlfn.ANCHORARRAY(ChartData!$H$25),ChartData!$J$25:$J$28),NA())} -> #N/A | K33: {=IF($K$31='Exe Sum'!$P$23,_xlfn.XLOOKUP(ChartData!H33,_xlfn.ANCHORARRAY(ChartData!$H$25),ChartData!$K$25:$K$28),NA())} -> #N/A | L33: {=IF($L$31='Exe Sum'!$P$23,_xlfn.XLOOKUP(ChartData!H33,_xlfn.ANCHORARRAY(ChartData!$H$25),ChartData!$L$25:$L$28),NA())} -> #N/A
H34: McDonalds | I34: =IF('Exe Sum'!$P$23=ChartData!$I$31,_xlfn.XLOOKUP(ChartData!H34,ChartData!$H$25:$H$28,ChartData!$I$25:$I$28),NA()) -> 25.297298 | J34: {=IF($J$31='Exe Sum'!$P$23,_xlfn.XLOOKUP(ChartData!H34,_xlfn.ANCHORARRAY(ChartData!$H$25),ChartData!$J$25:$J$28),NA())} -> #N/A | K34: {=IF($K$31='Exe Sum'!$P$23,_xlfn.XLOOKUP(ChartData!H34,_xlfn.ANCHORARRAY(ChartData!$H$25),ChartData!$K$25:$K$28),NA())} -> #N/A | L34: {=IF($L$31='Exe Sum'!$P$23,_xlfn.XLOOKUP(ChartData!H34,_xlfn.ANCHORARRAY(ChartData!$H$25),ChartData!$L$25:$L$28),NA())} -> #N/A
H35: Yum | I35: =IF('Exe Sum'!$P$23=ChartData!$I$31,_xlfn.XLOOKUP(ChartData!H35,ChartData!$H$25:$H$28,ChartData!$I$25:$I$28),NA()) -> 25.33825 | J35: {=IF($J$31='Exe Sum'!$P$23,_xlfn.XLOOKUP(ChartData!H35,_xlfn.ANCHORARRAY(ChartData!$H$25),ChartData!$J$25:$J$28),NA())} -> #N/A | K35: {=IF($K$31='Exe Sum'!$P$23,_xlfn.XLOOKUP(ChartData!H35,_xlfn.ANCHORARRAY(ChartData!$H$25),ChartData!$K$25:$K$28),NA())} -> #N/A | L35: {=IF($L$31='Exe Sum'!$P$23,_xlfn.XLOOKUP(ChartData!H35,_xlfn.ANCHORARRAY(ChartData!$H$25),ChartData!$L$25:$L$28),NA())} -> #N/A

Sheet MEMO

Sheet Industry
A1: Industry Analysis 2024
A2: Company Name | B2: CMG | C2: SHAK | D2: MCD | E2: YUM | F2: Industry
A3: *Numbers in Millions | B3: 2024 | C3: 2024 | D3: 2024 | E3: 2024 | F3: Average
A4: Stock Price | B4: =_xlfn.XLOOKUP(A4,'YOY CMG'!$A$3:$A$44,'YOY CMG'!$C$3:$C$44) -> 60.09 | C4: =_xlfn.XLOOKUP(A4,'YOY SHAK'!$A$3:$A$44,'YOY SHAK'!$C$3:$C$44) -> 129.51 | D4: =_xlfn.XLOOKUP(A4,'YOY MCD'!$A$3:$A$44,'YOY MCD'!$C$3:$C$44) -> 289.6 | E4: =_xlfn.XLOOKUP(A4,'YOY Yum'!$A$3:$A$44,'YOY Yum'!$C$3:$C$44) -> 133.52 | F4: =AVERAGE(B4:E4) -> 153.18
A5: Revenue | B5: =_xlfn.XLOOKUP(A5,'YOY CMG'!$A$3:$A$44,'YOY CMG'!$C$3:$C$44) -> 11313.85 | C5: =_xlfn.XLOOKUP(A5,'YOY SHAK'!$A$3:$A$44,'YOY SHAK'!$C$3:$C$44) -> 1252.61 | D5: =_xlfn.XLOOKUP(A5,'YOY MCD'!$A$3:$A$44,'YOY MCD'!$C$3:$C$44) -> 25920 | E5: =_xlfn.XLOOKUP(A5,'YOY Yum'!$A$3:$A$44,'YOY Yum'!$C$3:$C$44) -> 7549 | F5: =AVERAGE(B5:E5) -> 11508.865
A6: Cost of Revenue | B6: =_xlfn.XLOOKUP(A6,'YOY CMG'!$A$3:$A$44,'YOY CMG'!$C$3:$C$44) -> 8296.16 | C6: =_xlfn.XLOOKUP(A6,'YOY SHAK'!$A$3:$A$44,'YOY SHAK'!$C$3:$C$44) -> 950.14 | D6: =_xlfn.XLOOKUP(A6,'YOY MCD'!$A$3:$A$44,'YOY MCD'!$C$3:$C$44) -> 11210 | E6: =_xlfn.XLOOKUP(A6,'YOY Yum'!$A$3:$A$44,'YOY Yum'!$C$3:$C$44) -> 2120 | F6: =AVERAGE(B6:E6) -> 5644.075
A7: Gross Profit | B7: =_xlfn.XLOOKUP(A7,'YOY CMG'!$A$3:$A$44,'YOY CMG'!$C$3:$C$44) -> 3017.69 | C7: =_xlfn.XLOOKUP(A7,'YOY SHAK'!$A$3:$A$44,'YOY SHAK'!$C$3:$C$44) -> 302.47 | D7: =_xlfn.XLOOKUP(A7,'YOY MCD'!$A$3:$A$44,'YOY MCD'!$C$3:$C$44) -> 14710 | E7: =_xlfn.XLOOKUP(A7,'YOY Yum'!$A$3:$A$44,'YOY Yum'!$C$3:$C$44) -> 5429 | F7: =AVERAGE(B7:E7) -> 5864.79
A8: SG&A Expenses | B8: =_xlfn.XLOOKUP(A8,'YOY CMG'!$A$3:$A$44,'YOY CMG'!$C$3:$C$44) -> 697.48 | C8: =_xlfn.XLOOKUP(A8,'YOY SHAK'!$A$3:$A$44,'YOY SHAK'!$C$3:$C$44) -> 149.05 | D8: =_xlfn.XLOOKUP(A8,'YOY MCD'!$A$3:$A$44,'YOY MCD'!$C$3:$C$44) -> 2412 | E8: =_xlfn.XLOOKUP(A8,'YOY Yum'!$A$3:$A$44,'YOY Yum'!$C$3:$C$44) -> 2892 | F8: =AVERAGE(B8:E8) -> 1537.6325
A9: Operating Income | B9: =_xlfn.XLOOKUP(A9,'YOY CMG'!$A$3:$A$44,'YOY CMG'!$C$3:$C$44) -> 1916.33 | C9: =_xlfn.XLOOKUP(A9,'YOY SHAK'!$A$3:$A$44,'YOY SHAK'!$C$3:$C$44) -> 3.04 | D9: =_xlfn.XLOOKUP(A9,'YOY MCD'!$A$3:$A$44,'YOY MCD'!$C$3:$C$44) -> 11712 | E9: =_xlfn.XLOOKUP(A9,'YOY Yum'!$A$3:$A$44,'YOY Yum'!$C$3:$C$44) -> 2403 | F9: =AVERAGE(B9:E9) -> 4008.5925
A10: Net Income Common | B10: =_xlfn.XLOOKUP(A10,'YOY CMG'!$A$3:$A$44,'YOY CMG'!$C$3:$C$44) -> 1534.11 | C10: =_xlfn.XLOOKUP(A10,'YOY SHAK'!$A$3:$A$44,'YOY SHAK'!$C$3:$C$44) -> 10.21 | D10: =_xlfn.XLOOKUP(A10,'YOY MCD'!$A$3:$A$44,'YOY MCD'!$C$3:$C$44) -> 8223 | E10: =_xlfn.XLOOKUP(A10,'YOY Yum'!$A$3:$A$44,'YOY Yum'!$C$3:$C$44) -> 1486 | F10: =AVERAGE(B10:E10) -> 2813.33
A11: Cash and Short Term Investments | B11: =_xlfn.XLOOKUP(A11,'YOY CMG'!$A$3:$A$44,'YOY CMG'!$C$3:$C$44) -> 1422.91 | C11: =_xlfn.XLOOKUP(A11,'YOY SHAK'!$A$3:$A$44,'YOY SHAK'!$C$3:$C$44) -> 320.71 | D11: =_xlfn.XLOOKUP(A11,'YOY MCD'!$A$3:$A$44,'YOY MCD'!$C$3:$C$44) -> 1085 | E11: =_xlfn.XLOOKUP(A11,'YOY Yum'!$A$3:$A$44,'YOY Yum'!$C$3:$C$44) -> 616 | F11: =AVERAGE(B11:E11) -> 861.155
A12: Receivables | B12: =_xlfn.XLOOKUP(A12,'YOY CMG'!$A$3:$A$44,'YOY CMG'!$C$3:$C$44) -> 211.19 | C12: =_xlfn.XLOOKUP(A12,'YOY SHAK'!$A$3:$A$44,'YOY SHAK'!$C$3:$C$44) -> 19.69 | D12: =_xlfn.XLOOKUP(A12,'YOY MCD'!$A$3:$A$44,'YOY MCD'!$C$3:$C$44) -> 2383 | E12: =_xlfn.XLOOKUP(A12,'YOY Yum'!$A$3:$A$44,'YOY Yum'!$C$3:$C$44) -> 775 | F12: =AVERAGE(B12:E12) -> 847.22
A13: Inventory | B13: =_xlfn.XLOOKUP(A13,'YOY CMG'!$A$3:$A$44,'YOY CMG'!$C$3:$C$44) -> 48.94 | C13: =_xlfn.XLOOKUP(A13,'YOY SHAK'!$A$3:$A$44,'YOY SHAK'!$C$3:$C$44) -> 6.01 | D13: =_xlfn.XLOOKUP(A13,'YOY MCD'!$A$3:$A$44,'YOY MCD'!$C$3:$C$44) -> 56 | E13: =_xlfn.XLOOKUP(A13,'YOY Yum'!$A$3:$A$44,'YOY Yum'!$C$3:$C$44) -> 10 | F13: =AVERAGE(B13:E13) -> 30.2375
A14: Total current assets | B14: =_xlfn.XLOOKUP(A14,'YOY CMG'!$A$3:$A$44,'YOY CMG'!$C$3:$C$44) -> 1780.59 | C14: =_xlfn.XLOOKUP(A14,'YOY SHAK'!$A$3:$A$44,'YOY SHAK'!$C$3:$C$44) -> 368.22 | D14: =_xlfn.XLOOKUP(A14,'YOY MCD'!$A$3:$A$44,'YOY MCD'!$C$3:$C$44) -> 4599 | E14: =_xlfn.XLOOKUP(A14,'YOY Yum'!$A$3:$A$44,'YOY Yum'!$C$3:$C$44) -> 1871 | F14: =AVERAGE(B14:E14) -> 2154.7025
A15: Total Assets | B15: =_xlfn.XLOOKUP(A15,'YOY CMG'!$A$3:$A$44,'YOY CMG'!$C$3:$C$44) -> 9204.37 | C15: =_xlfn.XLOOKUP(A15,'YOY SHAK'!$A$3:$A$44,'YOY SHAK'!$C$3:$C$44) -> 1696.97 | D15: =_xlfn.XLOOKUP(A15,'YOY MCD'!$A$3:$A$44,'YOY MCD'!$C$3:$C$44) -> 55182 | E15: =_xlfn.XLOOKUP(A15,'YOY Yum'!$A$3:$A$44,'YOY Yum'!$C$3:$C$44) -> 6727 | F15: =AVERAGE(B15:E15) -> 18202.585
... A20: Shares (Basic, Weighted) | B20: =_xlfn.XLOOKUP(A20,'YOY CMG'!$A$3:$A$44,'YOY CMG'!$C$3:$C$44) -> 1368.34 | C20: =_xlfn.XLOOKUP(A20,'YOY SHAK'!$A$3:$A$44,'YOY SHAK'!$C$3:$C$44) -> 39.83 | D20: =_xlfn.XLOOKUP(A20,'YOY MCD'!$A$3:$A$44,'YOY MCD'!$C$3:$C$44) -> 718.3 | E20: =_xlfn.XLOOKUP(A20,'YOY Yum'!$A$3:$A$44,'YOY Yum'!$C$3:$C$44) -> 282 | F20: =AVERAGE(B20:E20) -> 602.1175
A21: Financial Ratio's
A22: Liquidity
A23: Current Ratio | B23: =_xlfn.XLOOKUP(A23,'YOY CMG'!$A$3:$A$44,'YOY CMG'!$C$3:$C$44) -> 1.5234734 | C23: =_xlfn.XLOOKUP(A23,'YOY SHAK'!$A$3:$A$44,'YOY SHAK'!$C$3:$C$44) -> 1.965832 | D23: =_xlfn.XLOOKUP(A23,'YOY MCD'!$A$3:$A$44,'YOY MCD'!$C$3:$C$44) -> 1.1911422 | E23: =_xlfn.XLOOKUP(A23,'YOY Yum'!$A$3:$A$44,'YOY Yum'!$C$3:$C$44) -> 1.4743893 | F23: =AVERAGE(B23:E23) -> 1.5387092
A24: Quick Ratio | B24: =_xlfn.XLOOKUP(A24,'YOY CMG'!$A$3:$A$44,'YOY CMG'!$C$3:$C$44) -> 1.4816003 | C24: =_xlfn.XLOOKUP(A24,'YOY SHAK'!$A$3:$A$44,'YOY SHAK'!$C$3:$C$44) -> 1.9337462 | D24: =_xlfn.XLOOKUP(A24,'YOY MCD'!$A$3:$A$44,'YOY MCD'!$C$3:$C$44) -> 1.1766382 | E24: =_xlfn.XLOOKUP(A24,'YOY Yum'!$A$3:$A$44,'YOY Yum'!$C$3:$C$44) -> 1.4665091 | F24: =AVERAGE(B24:E24) -> 1.5146234
A25: Net Working Capital | B25: =_xlfn.XLOOKUP(A25,'YOY CMG'!$A$3:$A$44,'YOY CMG'!$C$3:$C$44) -> 611.82 | C25: =_xlfn.XLOOKUP(A25,'YOY SHAK'!$A$3:$A$44,'YOY SHAK'!$C$3:$C$44) -> 180.91 | D25: =_xlfn.XLOOKUP(A25,'YOY MCD'!$A$3:$A$44,'YOY MCD'!$C$3:$C$44) -> 738 | E25: =_xlfn.XLOOKUP(A25,'YOY Yum'!$A$3:$A$44,'YOY Yum'!$C$3:$C$44) -> 602 | F25: =AVERAGE(B25:E25) -> 533.1825
A26: Asset Management
A27: Accounts Rec. Turnover | B27: =_xlfn.XLOOKUP(A27,'YOY CMG'!$A$3:$A$44,'YOY CMG'!$C$3:$C$44) -> 53.571902 | C27: =_xlfn.XLOOKUP(A27,'YOY SHAK'!$A$3:$A$44,'YOY SHAK'!$C$3:$C$44) -> 63.616557 | D27: =_xlfn.XLOOKUP(A27,'YOY MCD'!$A$3:$A$44,'YOY MCD'!$C$3:$C$44) -> 10.877046 | E27: =_xlfn.XLOOKUP(A27,'YOY Yum'!$A$3:$A$44,'YOY Yum'!$C$3:$C$44) -> 9.7406452 | F27: =AVERAGE(B27:E27) -> 34.451537
A28: Inventory Turnover | B28: =_xlfn.XLOOKUP(A28,'YOY CMG'!$A$3:$A$44,'YOY CMG'!$C$3:$C$44) -> 231.17797 | C28: =_xlfn.XLOOKUP(A28,'YOY SHAK'!$A$3:$A$44,'YOY SHAK'!$C$3:$C$44) -> 208.42097 | D28: =_xlfn.XLOOKUP(A28,'YOY MCD'!$A$3:$A$44,'YOY MCD'!$C$3:$C$44) -> 462.85714 | E28: =_xlfn.XLOOKUP(A28,'YOY Yum'!$A$3:$A$44,'YOY Yum'!$C$3:$C$44) -> 754.9 | F28: =AVERAGE(B28:E28) -> 414.33902
A29: Total Asset Turnover | B29: =_xlfn.XLOOKUP(A29,'YOY CMG'!$A$3:$A$44,'YOY CMG'!$C$3:$C$44) -> 1.2291824 | C29: =_xlfn.XLOOKUP(A29,'YOY SHAK'!$A$3:$A$44,'YOY SHAK'!$C$3:$C$44) -> 0.73814505 | D29: =_xlfn.XLOOKUP(A29,'YOY MCD'!$A$3:$A$44,'YOY MCD'!$C$3:$C$44) -> 0.46971839 | E29: =_xlfn.XLOOKUP(A29,'YOY Yum'!$A$3:$A$44,'YOY Yum'!$C$3:$C$44) -> 1.1221941 | F29: =AVERAGE(B29:E29) -> 0.88981
A30: Debt Management
A31: Debt to Equity Ratio | B31: =_xlfn.XLOOKUP(A31,'YOY CMG'!$A$3:$A$44,'YOY CMG'!$C$3:$C$44) -> 0.0027355665 | C31: =_xlfn.XLOOKUP(A31,'YOY SHAK'!$A$3:$A$44,'YOY SHAK'!$C$3:$C$44) -> 0.49972652 | D31: =_xlfn.XLOOKUP(A31,'YOY MCD'!$A$3:$A$44,'YOY MCD'!$C$3:$C$44) -> -10.122234 | E31: =_xlfn.XLOOKUP(A31,'YOY Yum'!$A$3:$A$44,'YOY Yum'!$C$3:$C$44) -> -1.478295 | F31: =AVERAGE(B31:E31) -> -2.7745167
A32: Equity multiplier | B32: =_xlfn.XLOOKUP(A32,'YOY CMG'!$A$3:$A$44,'YOY CMG'!$C$3:$C$44) -> 2.5179166 | C32: =_xlfn.XLOOKUP(A32,'YOY SHAK'!$A$3:$A$44,'YOY SHAK'!$C$3:$C$44) -> 3.4377368 | D32: =_xlfn.XLOOKUP(A32,'YOY MCD'!$A$3:$A$44,'YOY MCD'!$C$3:$C$44) -> -14.536881 | E32: =_xlfn.XLOOKUP(A32,'YOY Yum'!$A$3:$A$44,'YOY Yum'!$C$3:$C$44) -> -0.87957636 | F32: =AVERAGE(B32:E32) -> -2.365201
A33: Profitability
A34: Net Profit Margin | B34: =_xlfn.XLOOKUP(A34,'YOY CMG'!$A$3:$A$44,'YOY CMG'!$C$3:$C$44) -> 0.1356 | C34: =_xlfn.XLOOKUP(A34,'YOY SHAK'!$A$3:$A$44,'YOY SHAK'!$C$3:$C$44) -> 0.0081 | D34: =_xlfn.XLOOKUP(A34,'YOY MCD'!$A$3:$A$44,'YOY MCD'!$C$3:$C$44) -> 0.3172 | E34: =_xlfn.XLOOKUP(A34,'YOY Yum'!$A$3:$A$44,'YOY Yum'!$C$3:$C$44) -> 0.1968 | F34: =AVERAGE(B34:E34) -> 0.164425
A35: Gross Profit Margin | B35: =_xlfn.XLOOKUP(A35,'YOY CMG'!$A$3:$A$44,'YOY CMG'!$C$3:$C$44) -> 0.2667 | C35: =_xlfn.XLOOKUP(A35,'YOY SHAK'!$A$3:$A$44,'YOY SHAK'!$C$3:$C$44) -> 0.2415 | D35: =_xlfn.XLOOKUP(A35,'YOY MCD'!$A$3:$A$44,'YOY MCD'!$C$3:$C$44) -> 0.5675 | E35: =_xlfn.XLOOKUP(A35,'YOY Yum'!$A$3:$A$44,'YOY Yum'!$C$3:$C$44) -> 0.7192 | F35: =AVERAGE(B35:E35) -> 0.448725
A36: Return On Assets ROA | B36: =_xlfn.XLOOKUP(A36,'YOY CMG'!$A$3:$A$44,'YOY CMG'!$C$3:$C$44) -> 0.16667714 | C36: =_xlfn.XLOOKUP(A36,'YOY SHAK'!$A$3:$A$44,'YOY SHAK'!$C$3:$C$44) -> 0.0059789749 | D36: =_xlfn.XLOOKUP(A36,'YOY MCD'!$A$3:$A$44,'YOY MCD'!$C$3:$C$44) -> 0.14899467 | E36: =_xlfn.XLOOKUP(A36,'YOY Yum'!$A$3:$A$44,'YOY Yum'!$C$3:$C$44) -> 0.22084781 | F36: =AVERAGE(B36:E36) -> 0.13562465
A37: Return On Equity ROE | B37: =_xlfn.XLOOKUP(A37,'YOY CMG'!$A$3:$A$44,'YOY CMG'!$C$3:$C$44) -> 0.41967913 | C37: =_xlfn.XLOOKUP(A37,'YOY SHAK'!$A$3:$A$44,'YOY SHAK'!$C$3:$C$44) -> 0.020554142 | D37: =_xlfn.XLOOKUP(A37,'YOY MCD'!$A$3:$A$44,'YOY MCD'!$C$3:$C$44) -> -2.1659178 | E37: =_xlfn.XLOOKUP(A37,'YOY Yum'!$A$3:$A$44,'YOY Yum'!$C$3:$C$44) -> -0.19425251 | F37: =AVERAGE(B37:E37) -> -0.47998426
A38: Market Value
A39: EPS | B39: =_xlfn.XLOOKUP(A39,'YOY CMG'!$A$3:$A$44,'YOY CMG'!$C$3:$C$44) -> 1.1211468 | C39: =_xlfn.XLOOKUP(A39,'YOY SHAK'!$A$3:$A$44,'YOY SHAK'!$C$3:$C$44) -> 0.25633944 | D39: =_xlfn.XLOOKUP(A39,'YOY MCD'!$A$3:$A$44,'YOY MCD'!$C$3:$C$44) -> 11.447863 | E39: =_xlfn.XLOOKUP(A39,'YOY Yum'!$A$3:$A$44,'YOY Yum'!$C$3:$C$44) -> 5.2695035 | F39: =AVERAGE(B39:E39) -> 4.5237132
A40: P/E | B40: =_xlfn.XLOOKUP(A40,'YOY CMG'!$A$3:$A$44,'YOY CMG'!$C$3:$C$44) -> 53.596907 | C40: =_xlfn.XLOOKUP(A40,'YOY SHAK'!$A$3:$A$44,'YOY SHAK'!$C$3:$C$44) -> 505.22853 | D40: =_xlfn.XLOOKUP(A40,'YOY MCD'!$A$3:$A$44,'YOY MCD'!$C$3:$C$44) -> 25.297298 | E40: =_xlfn.XLOOKUP(A40,'YOY Yum'!$A$3:$A$44,'YOY Yum'!$C$3:$C$44) -> 25.33825 | F40: =AVERAGE(B40:E40) -> 152.36525
A41: Book Value Per Share | B41: =_xlfn.XLOOKUP(A41,'YOY CMG'!$A$3:$A$44,'YOY CMG'!$C$3:$C$44) -> 2.6715217 | C41: =_xlfn.XLOOKUP(A41,'YOY SHAK'!$A$3:$A$44,'YOY SHAK'!$C$3:$C$44) -> 12.393422 | D41: =_xlfn.XLOOKUP(A41,'YOY MCD'!$A$3:$A$44,'YOY MCD'!$C$3:$C$44) -> -5.2847 | E41: =_xlfn.XLOOKUP(A41,'YOY Yum'!$A$3:$A$44,'YOY Yum'!$C$3:$C$44) -> -27.120567 | F41: =AVERAGE(B41:E41) -> -4.3350809
A42: Market Capitalization (Stock Price * Shares) | B42: =_xlfn.XLOOKUP(A42,'YOY CMG'!$A$3:$A$44,'YOY CMG'!$C$3:$C$44) -> 82223.551 | C42: =_xlfn.XLOOKUP(A42,'YOY SHAK'!$A$3:$A$44,'YOY SHAK'!$C$3:$C$44) -> 5158.3833 | D42: =_xlfn.XLOOKUP(A42,'YOY MCD'!$A$3:$A$44,'YOY MCD'!$C$3:$C$44) -> 208019.68 | E42: =_xlfn.XLOOKUP(A42,'YOY Yum'!$A$3:$A$44,'YOY Yum'!$C$3:$C$44) -> 37652.64 | F42: =AVERAGE(B42:E42) -> 83263.563
A43: Cash Per Share | B43: =_xlfn.XLOOKUP(A43,'YOY CMG'!$A$3:$A$44,'YOY CMG'!$C$3:$C$44) -> 1.0398804 | C43: =_xlfn.XLOOKUP(A43,'YOY SHAK'!$A$3:$A$44,'YOY SHAK'!$C$3:$C$44) -> 8.0519709 | D43: =_xlfn.XLOOKUP(A43,'YOY MCD'!$A$3:$A$44,'YOY MCD'!$C$3:$C$44) -> 1.5105109 | E43: =_xlfn.XLOOKUP(A43,'YOY Yum'!$A$3:$A$44,'YOY Yum'!$C$3:$C$44) -> 2.1843972 | F43: =AVERAGE(B43:E43) -> 3.1966899
A44: Revenue Per Share | B44: =_xlfn.XLOOKUP(A44,'YOY CMG'!$A$3:$A$44,'YOY CMG'!$C$3:$C$44) -> 8.2683032 | C44: =_xlfn.XLOOKUP(A44,'YOY SHAK'!$A$3:$A$44,'YOY SHAK'!$C$3:$C$44) -> 31.448908 | D44: =_xlfn.XLOOKUP(A44,'YOY MCD'!$A$3:$A$44,'YOY MCD'!$C$3:$C$44) -> 36.085201 | E44: =_xlfn.XLOOKUP(A44,'YOY Yum'!$A$3:$A$44,'YOY Yum'!$C$3:$C$44) -> 26.769504 | F44: =AVERAGE(B44:E44) -> 25.642979
...

Sheet C24-21
A1: In the Millions | G1: In the Millions
B2: Dec '24 | C2: Dec '23 | D2: Dec '22 | E2: Dec '21 | H2: Dec '24 | I2: Dec '23 | J2: Dec '22 | K2: Dec '21
A3: Income Statement | G3: Balance Sheet
A4: Revenue | B4: 11313.85 | C4: 9871.65 | D4: 8634.65 | E4: 7547.06 | G4: Cash and Short Term Investments | H4: 1422.91 | I4: 1295.45 | J4: 899.14 | K4: 1076.32
A5: Revenue Growth | B5: 0.1461 | C5: 0.1433 | D5: 0.1441 | E5: 0.2611 | G5: Receivables | H5: 211.19 | I5: 168.5 | J5: 154.62 | K5: 193.66
A6: Cost of Revenue | B6: 8296.16 | C6: 7285.56 | D6: 6572.53 | E6: 5840.05 | G6: Inventory | H6: 48.94 | I6: 39.31 | J6: 35.67 | K6: 32.83
A7: Gross Profit | B7: 3017.69 | C7: 2586.09 | D7: 2062.12 | E7: 1707.01 | G7: Other current assets | H7: — | I7: — | J7: 86 | K7: 79
A8: SG&A Expenses | B8: 697.48 | C8: 633.58 | D8: 564.19 | E8: 606.85 | G8: Total current assets | H8: 1780.59 | I8: 1620.71 | J8: 1175.84 | K8: 1381.56
A9: Operating Income | B9: 1916.33 | C9: 1557.81 | D9: 1160.4 | E9: 804.94 | G9: Property, Plant, Equipment (Net) | H9: 2390.13 | I9: 2170.04 | J9: 1951.15 | K9: 1769.28
A10: Non-operating Income/Expense | B10: 93.9 | C10: 62.69 | D10: 21.13 | E10: 7.82 | G10: Long-Term Investments | H10: 868.02 | I10: 564.49 | J10: 388.06 | K10: 274.31
A11: Non-operating Interest Expenses | B11: — | C11: — | D11: — | E11: — | G11: Goodwill and Intangible Assets (Total) | H11: 21.94 | I11: 21.94 | J11: 21.94 | K11: 21.94
A12: EBT | B12: 2010.23 | C12: 1620.51 | D12: 1181.53 | E12: 812.76 | G12: Long-term assets (Other) | H12: 143.57 | I12: 88.64 | J12: 88.12 | K12: 87.57
A13: Income Tax Provision | B13: 476.12 | C13: 391.77 | D13: 282.43 | E13: 159.78 | G13: Total non-current assets | H13: 7423.79 | I13: 6423.65 | J13: 5751.67 | K13: 5271.39
A14: Income after Tax | B14: 1534.11 | C14: 1228.74 | D14: 899.1 | E14: 652.98 | G14: Total Assets | H14: 9204.37 | I14: 8044.36 | J14: 6927.5 | K14: 6652.96
A15: Net Income Common | B15: 1534.11 | C15: 1228.74 | D15: 899.1 | E15: 652.98 | G15: Accounts Payable | H15: 210.69 | I15: 197.65 | J15: 184.57 | K15: 163.16
A16: EPS (Basic) | B16: 1.12 | C16: 0.89 | D16: 0.65 | E16: 0.46 | G16: Accrued Expenses | H16: 179.75 | I16: 147.69 | J16: 147.54 | K16: 173.05
A17: EPS (Diluted) | B17: 1.11 | C17: 0.89 | D17: 0.64 | E17: 0.46 | G17: Current Part of Debt | H17: — | I17: — | J17: 236 | K17: 219
A18: Shares (Basic, Weighted) | B18: 1368.34 | C18: 1377.77 | D18: 1392.54 | E18: 1406.6 | G18: Current Part of Taxes to Pay | H18: — | I18: — | J18: — | K18: —
A19: Shares (Diluted, Weighted) | B19: 1376.56 | C19: 1385.5 | D19: 1403.08 | E19: 1425.55 | G19: Current Revenue (Deferred) | H19: 238.58 | I19: 209.68 | J19: 183.07 | K19: 156.35
A20: Gross Margin | B20: 0.2667 | C20: 0.262 | D20: 0.2388 | E20: 0.2262 | G20: Other current liabilities | H20: — | I20: — | J20: 465 | K20: 460
A21: EBIT Margin | B21: 0.1694 | C21: 0.1578 | D21: 0.1344 | E21: 0.1067 | G21: Total current liabilities | H21: 1168.77 | I21: 1030.63 | J21: 921.88 | K21: 873.68
A22: EBT margin | B22: 0.1777 | C22: 0.1642 | D22: 0.1368 | E22: 0.1077 | G22: Long Term Debt (Total) | H22: — | I22: — | J22: 3495 | K22: 3302
A23: Net Profit Margin | B23: 0.1356 | C23: 0.1245 | D23: 0.1041 | E23: 0.0865 | G23: Non-current Revenue (Deferred) | H23: — | I23: — | J23: — | K23: —
A24: Free Cash Flow Margin | B24: 0.1354 | C24: 0.1239 | D24: 0.0977 | E24: 0.1118 | G24: Long Term Tax Liability (Deferred) | H24: 46.21 | I24: 89.11 | J24: 98.62 | K24: 141.76
A25: EBITDA | B25: 2251.36 | C25: 1877.21 | D25: 1447.23 | E25: 1059.6 | G25: Non-current Liabilities (Other) | H25: 71.07 | I25: 58.87 | J25: 43.82 | K25: 38.54
A26: EBIT | B26: 1916.33 | C26: 1557.81 | D26: 1160.4 | E26: 804.94 | G26: Total non-current liabilities | H26: 4380.06 | I26: 3951.53 | J26: 3637.6 | K26: 3481.9
A27: Income from Continuous Operations | B27: 1534.11 | C27: 1228.74 | D27: 899.1 | E27: 652.98 | G27: Total liabilities | H27: 5548.83 | I27: 4982.15 | J27: 4559.48 | K27: 4355.58
A28: Consolidated Net Income/Loss | B28: 1534.11 | C28: 1228.74 | D28: 899.1 | E28: 652.98 | G28: Additional Paid In Capital | H28: 2078.01 | I28: 1937.79 | J28: 1829.3 | K28: 1729.31
A29: EPS (Basic, from Continuous Ops) | B29: 1.12 | C29: 0.89 | D29: 0.65 | E29: 0.46 | G29: Common Stock (Net) | H29: 13.59 | I29: 18.74 | J29: 0.37 | K29: 0.37
A30: EPS (Basic, Consolidated) | B30: 1.12 | C30: 0.89 | D30: 0.65 | E30: 0.46 | G30: Retained Earnings | H30: 1574.23 | I30: 6056.98 | J30: 4828.25 | K30: 3929.15
A31: EPS (Diluted, from Cont. Ops) | B31: 1.11 | C31: 0.89 | D31: 0.64 | E31: 0.46 | G31: Treasury Stock | H31: — | I31: 4944.66 | J31: 4282.01 | K31: 3356.1
A32: Shares (Diluted, Average) | B32: 1376.56 | C32: 1385.5 | D32: 1403.1 | E32: 1425.55 | G32: Common Equity (Total) | H32: 3655.55 | I32: 3062.21 | J32: 2368.02 | K32: 2297.37
A33: EPS (Diluted, Consolidated) | B33: 1.11 | C33: 0.89 | D33: 0.64 | E33: 0.46 | G33: Shareholders Equity (Total) | H33: 3655.55 | I33: 3062.21 | J33: 2368.02 | K33: 2297.37
A34: EBITDA Margin | B34: 0.199 | C34: 0.1902 | D34: 0.1676 | E34: 0.1404 | G34: Shareholders Equity and Liabilities (Total) | H34: 9204.37 | I34: 8044.36 | J34: 6927.5 | K34: 6652.96
A35: Operating Cash Flow Margin | B35: 0.1861 | C35: 0.1807 | D35: 0.1532 | E35: 0.1699 | G35: Shares (Common) | H35: 1358.75 | I35: 1371.3 | J35: 1381.35 | K35: 1404
A36: Cash and Short Term Investments | B36: 1422.91 | C36: 1295.45 | D36: 899.14 | E36: 1076.32 | G36: Shareholders Equity (Tangible) | H36: 3633.61 | I36: 3040.27 | J36: 2346.08 | K36: 2275.43
A37: Receivables | B37: 211.19 | C37: 168.5 | D37: 154.62 | E37: 193.66 | G37: Net Debt | H37: -1422.91 | I37: -1295.45 | J37: 2831.86 | K37: 2444.68
A38: Inventory | B38: 48.94 | C38: 39.31 | D38: 35.67 | E38: 32.83 | G38: Total Debt | H38: — | I38: — | J38: 3731 | K38: 3521
A39: Other current assets | B39: — | C39: — | D39: 86 | E39: 79
A40: Total current assets | B40: 1780.59 | C40: 1620.71 | D40: 1175.84 | E40: 1381.56
...

Sheet YOY CMG
A1: Company Name | C1: CMG | D1: CMG | E1: YOY % Change 2024 2023 | F1: CMG | G1: YOY % Change 2023 2022 | H1: CMG | I1: YOY % Change 2022 2021
A2: Year ending: | C2: 2024 | D2: 2023 | F2: 2022 | H2: 2021
A3: Stock Price | C3: 60.09 | D3: 45.74 | E3: =+(C3-D3)/D3 -> 0.31372978 | F3: 27.75 | G3: =+(D3-F3)/F3 -> 0.64828829 | H3: 34.94 | I3: =(F3-H3)/H3 -> -0.20578134
A4: Revenue | C4: =_xlfn.XLOOKUP(A4,'C24-21'!$A$4:$A$70,'C24-21'!$B$4:$B$70,"LOOK",0) -> 11313.85 | D4: =_xlfn.XLOOKUP(A4,'C24-21'!$A$4:$A$70,'C24-21'!$C$4:$C$70,"LOOK",0) -> 9871.65 | E4: =+(C4-D4)/D4 -> 0.14609513 | F4: =_xlfn.XLOOKUP(A4,'C24-21'!$A$4:$A$70,'C24-21'!$D$4:$D$70,"LOOK",0) -> 8634.65 | G4: =+(D4-F4)/F4 -> 0.14326 | H4: =_xlfn.XLOOKUP(A4,'C24-21'!$A$4:$A$70,'C24-21'!$E$4:$E$70,"LOOK") -> 7547.06 | I4: =(F4-H4)/H4 -> 0.14410777
A5: Cost of Revenue | C5: =_xlfn.XLOOKUP(A5,'C24-21'!$A$4:$A$70,'C24-21'!$B$4:$B$70,"LOOK",0) -> 8296.16 | D5: =_xlfn.XLOOKUP(A5,'C24-21'!$A$4:$A$70,'C24-21'!$C$4:$C$70,"LOOK",0) -> 7285.56 | E5: =+(C5-D5)/D5 -> 0.13871274 | F5: =_xlfn.XLOOKUP(A5,'C24-21'!$A$4:$A$70,'C24-21'!$D$4:$D$70,"LOOK",0) -> 6572.53 | G5: =+(D5-F5)/F5 -> 0.10848638 | H5: =_xlfn.XLOOKUP(A5,'C24-21'!$A$4:$A$70,'C24-21'!$E$4:$E$70,"LOOK") -> 5840.05 | I5: =(F5-H5)/H5 -> 0.12542358
A6: Gross Profit | C6: =_xlfn.XLOOKUP(A6,'C24-21'!$A$4:$A$70,'C24-21'!$B$4:$B$70,"LOOK",0) -> 3017.69 | D6: =_xlfn.XLOOKUP(A6,'C24-21'!$A$4:$A$70,'C24-21'!$C$4:$C$70,"LOOK",0) -> 2586.09 | E6: =+(C6-D6)/D6 -> 0.16689288 | F6: =_xlfn.XLOOKUP(A6,'C24-21'!$A$4:$A$70,'C24-21'!$D$4:$D$70,"LOOK",0) -> 2062.12 | G6: =+(D6-F6)/F6 -> 0.25409288 | H6: =_xlfn.XLOOKUP(A6,'C24-21'!$A$4:$A$70,'C24-21'!$E$4:$E$70,"LOOK") -> 1707.01 | I6: =(F6-H6)/H6 -> 0.20803042
A7: SG&A Expenses | C7: =_xlfn.XLOOKUP(A7,'C24-21'!$A$4:$A$70,'C24-21'!$B$4:$B$70,"LOOK",0) -> 697.48 | D7: =_xlfn.XLOOKUP(A7,'C24-21'!$A$4:$A$70,'C24-21'!$C$4:$C$70,"LOOK",0) -> 633.58 | E7: =+(C7-D7)/D7 -> 0.10085546 | F7: =_xlfn.XLOOKUP(A7,'C24-21'!$A$4:$A$70,'C24-21'!$D$4:$D$70,"LOOK",0) -> 564.19 | G7: =+(D7-F7)/F7 -> 0.12299048 | H7: =_xlfn.XLOOKUP(A7,'C24-21'!$A$4:$A$70,'C24-21'!$E$4:$E$70,"LOOK") -> 606.85 | I7: =(F7-H7)/H7 -> -0.070297438
A8: Operating Income | C8: =_xlfn.XLOOKUP(A8,'C24-21'!$A$4:$A$70,'C24-21'!$B$4:$B$70,"LOOK",0) -> 1916.33 | D8: =_xlfn.XLOOKUP(A8,'C24-21'!$A$4:$A$70,'C24-21'!$C$4:$C$70,"LOOK",0) -> 1557.81 | E8: =+(C8-D8)/D8 -> 0.2301436 | F8: =_xlfn.XLOOKUP(A8,'C24-21'!$A$4:$A$70,'C24-21'!$D$4:$D$70,"LOOK",0) -> 1160.4 | G8: =+(D8-F8)/F8 -> 0.34247673 | H8: =_xlfn.XLOOKUP(A8,'C24-21'!$A$4:$A$70,'C24-21'!$E$4:$E$70,"LOOK") -> 804.94 | I8: =(F8-H8)/H8 -> 0.44159813
A9: Net Income Common | C9: =_xlfn.XLOOKUP(A9,'C24-21'!$A$4:$A$70,'C24-21'!$B$4:$B$70,"LOOK",0) -> 1534.11 | D9: =_xlfn.XLOOKUP(A9,'C24-21'!$A$4:$A$70,'C24-21'!$C$4:$C$70,"LOOK",0) -> 1228.74 | E9: =+(C9-D9)/D9 -> 0.24852288 | F9: =_xlfn.XLOOKUP(A9,'C24-21'!$A$4:$A$70,'C24-21'!$D$4:$D$70,"LOOK",0) -> 899.1 | G9: =+(D9-F9)/F9 -> 0.3666333 | H9: =_xlfn.XLOOKUP(A9,'C24-21'!$A$4:$A$70,'C24-21'!$E$4:$E$70,"LOOK") -> 652.98 | I9: =(F9-H9)/H9 -> 0.37691813
A10: Cash and Short Term Investments | C10: =_xlfn.XLOOKUP(A10,'C24-21'!$A$4:$A$70,'C24-21'!$B$4:$B$70,"LOOK",0) -> 1422.91 | D10: =_xlfn.XLOOKUP(A10,'C24-21'!$A$4:$A$70,'C24-21'!$C$4:$C$70,"LOOK",0) -> 1295.45 | E10: =+(C10-D10)/D10 -> 0.098390521 | F10: =_xlfn.XLOOKUP(A10,'C24-21'!$A$4:$A$70,'C24-21'!$D$4:$D$70,"LOOK",0) -> 899.14 | G10: =+(D10-F10)/F10 -> 0.44076562 | H10: =_xlfn.XLOOKUP(A10,'C24-21'!$A$4:$A$70,'C24-21'!$E$4:$E$70,"LOOK") -> 1076.32 | I10: =(F10-H10)/H10 -> -0.16461647
A11: Receivables | C11: =_xlfn.XLOOKUP(A11,'C24-21'!$A$4:$A$70,'C24-21'!$B$4:$B$70,"LOOK",0) -> 211.19 | D11: =_xlfn.XLOOKUP(A11,'C24-21'!$A$4:$A$70,'C24-21'!$C$4:$C$70,"LOOK",0) -> 168.5 | E11: =+(C11-D11)/D11 -> 0.25335312 | F11: =_xlfn.XLOOKUP(A11,'C24-21'!$A$4:$A$70,'C24-21'!$D$4:$D$70,"LOOK",0) -> 154.62 | G11: =+(D11-F11)/F11 -> 0.089768465 | H11: =_xlfn.XLOOKUP(A11,'C24-21'!$A$4:$A$70,'C24-21'!$E$4:$E$70,"LOOK") -> 193.66 | I11: =(F11-H11)/H11 -> -0.20159042
A12: Inventory | C12: =_xlfn.XLOOKUP(A12,'C24-21'!$A$4:$A$70,'C24-21'!$B$4:$B$70,"LOOK",0) -> 48.94 | D12: =_xlfn.XLOOKUP(A12,'C24-21'!$A$4:$A$70,'C24-21'!$C$4:$C$70,"LOOK",0) -> 39.31 | E12: =+(C12-D12)/D12 -> 0.24497583 | F12: =_xlfn.XLOOKUP(A12,'C24-21'!$A$4:$A$70,'C24-21'!$D$4:$D$70,"LOOK",0) -> 35.67 | G12: =+(D12-F12)/F12 -> 0.10204654 | H12: =_xlfn.XLOOKUP(A12,'C24-21'!$A$4:$A$70,'C24-21'!$E$4:$E$70,"LOOK") -> 32.83 | I12: =(F12-H12)/H12 -> 0.086506244
A13: Total current assets | C13: =_xlfn.XLOOKUP(A13,'C24-21'!$A$4:$A$70,'C24-21'!$B$4:$B$70,"LOOK",0) -> 1780.59 | D13: =_xlfn.XLOOKUP(A13,'C24-21'!$A$4:$A$70,'C24-21'!$C$4:$C$70,"LOOK",0) -> 1620.71 | E13: =+(C13-D13)/D13 -> 0.098648123 | F13: =_xlfn.XLOOKUP(A13,'C24-21'!$A$4:$A$70,'C24-21'!$D$4:$D$70,"LOOK",0) -> 1175.84 | G13: =+(D13-F13)/F13 -> 0.37834229 | H13: =_xlfn.XLOOKUP(A13,'C24-21'!$A$4:$A$70,'C24-21'!$E$4:$E$70,"LOOK") -> 1381.56 | I13: =(F13-H13)/H13 -> -0.14890414
A14: Total Assets | C14: =_xlfn.XLOOKUP(A14,'C24-21'!$A$4:$A$70,'C24-21'!$B$4:$B$70,"LOOK",0) -> 9204.37 | D14: =_xlfn.XLOOKUP(A14,'C24-21'!$A$4:$A$70,'C24-21'!$C$4:$C$70,"LOOK",0) -> 8044.36 | E14: =+(C14-D14)/D14 -> 0.14420165 | F14: =_xlfn.XLOOKUP(A14,'C24-21'!$A$4:$A$70,'C24-21'!$D$4:$D$70,"LOOK",0) -> 6927.5 | G14: =+(D14-F14)/F14 -> 0.16122122 | H14: =_xlfn.XLOOKUP(A14,'C24-21'!$A$4:$A$70,'C24-21'!$E$4:$E$70,"LOOK") -> 6652.96 | I14: =(F14-H14)/H14 -> 0.041265843
A15: Total current liabilities | C15: =_xlfn.XLOOKUP(A15,'C24-21'!$A$4:$A$70,'C24-21'!$B$4:$B$70,"LOOK",0) -> 1168.77 | D15: =_xlfn.XLOOKUP(A15,'C24-21'!$A$4:$A$70,'C24-21'!$C$4:$C$70,"LOOK",0) -> 1030.63 | E15: =+(C15-D15)/D15 -> 0.13403452 | F15: =_xlfn.XLOOKUP(A15,'C24-21'!$A$4:$A$70,'C24-21'!$D$4:$D$70,"LOOK",0) -> 921.88 | G15: =+(D15-F15)/F15 -> 0.11796546 | H15: =_xlfn.XLOOKUP(A15,'C24-21'!$A$4:$A$70,'C24-21'!$E$4:$E$70,"LOOK") -> 873.68 | I15: =(F15-H15)/H15 -> 0.055168941
A16: Long Term Debt (Total) | C16: 10 | D16: 10 | E16: =+(C16-D16)/D16 -> 0 | F16: =_xlfn.XLOOKUP(A16,'C24-21'!$A$4:$A$70,'C24-21'!$D$4:$D$70,"LOOK",0) -> 3495 | G16: =+(D16-F16)/F16 -> -0.99713877 | H16: =_xlfn.XLOOKUP(A16,'C24-21'!$A$4:$A$70,'C24-21'!$E$4:$E$70,"LOOK") -> 3302 | I16: =(F16-H16)/H16 -> 0.058449425
A17: Total liabilities | C17: =_xlfn.XLOOKUP(A17,'C24-21'!$A$4:$A$70,'C24-21'!$B$4:$B$70,"LOOK",0) -> 5548.83 | D17: =_xlfn.XLOOKUP(A17,'C24-21'!$A$4:$A$70,'C24-21'!$C$4:$C$70,"LOOK",0) -> 4982.15 | E17: =+(C17-D17)/D17 -> 0.11374206 | F17: =_xlfn.XLOOKUP(A17,'C24-21'!$A$4:$A$70,'C24-21'!$D$4:$D$70,"LOOK",0) -> 4559.48 | G17: =+(D17-F17)/F17 -> 0.092701361 | H17: =_xlfn.XLOOKUP(A17,'C24-21'!$A$4:$A$70,'C24-21'!$E$4:$E$70,"LOOK") -> 4355.58 | I17: =(F17-H17)/H17 -> 0.046813513
A18: Common Equity (Total) | C18: =_xlfn.XLOOKUP(A18,'C24-21'!$A$4:$A$70,'C24-21'!$B$4:$B$70,"LOOK",0) -> 3655.55 | D18: =_xlfn.XLOOKUP(A18,'C24-21'!$A$4:$A$70,'C24-21'!$C$4:$C$70,"LOOK",0) -> 3062.21 | E18: =+(C18-D18)/D18 -> 0.19376202 | F18: =_xlfn.XLOOKUP(A18,'C24-21'!$A$4:$A$70,'C24-21'!$D$4:$D$70,"LOOK",0) -> 2368.02 | G18: =+(D18-F18)/F18 -> 0.29315208 | H18: =_xlfn.XLOOKUP(A18,'C24-21'!$A$4:$A$70,'C24-21'!$E$4:$E$70,"LOOK") -> 2297.37 | I18: =(F18-H18)/H18 -> 0.030752556
A19: Shares (Basic, Weighted) | C19: =_xlfn.XLOOKUP(A19,'C24-21'!$A$4:$A$70,'C24-21'!$B$4:$B$70,"LOOK",0) -> 1368.34 | D19: =_xlfn.XLOOKUP(A19,'C24-21'!$A$4:$A$70,'C24-21'!$C$4:$C$70,"LOOK",0) -> 1377.77 | E19: =+(C19-D19)/D19 -> -0.0068443935 | F19: =_xlfn.XLOOKUP(A19,'C24-21'!$A$4:$A$70,'C24-21'!$D$4:$D$70,"LOOK",0) -> 1392.54 | G19: =+(D19-F19)/F19 -> -0.010606518 | H19: =_xlfn.XLOOKUP(A19,'C24-21'!$A$4:$A$70,'C24-21'!$E$4:$E$70,"LOOK") -> 1406.6 | I19: =(F19-H19)/H19 -> -0.0099957344
A20: Financial Ratio's | C20: CMG | D20: CMG | E20: YOY % Change 2024 2023 | F20: CMG | G20: YOY % Change 2023 2022 | H20: CMG | I20: YOY % Change 2022 2021
A21: Liquidity | C21: 2024 | D21: 2023 | F21: 2022 | H21: 2021
A22: Current Ratio | C22: =C13/C15 -> 1.5234734 | D22: =D13/D15 -> 1.572543 | E22: =(C22-D22)/D22 -> -0.031203988 | F22: =F13/F15 -> 1.2754805 | G22: =(D22-F22)/F22 -> 0.23290239 | H22: =H13/H15 -> 1.5813112 | I22: =(F22-H22)/H22 -> -0.19340323
A23: Quick Ratio | C23: =(C13-C12)/C15 -> 1.4816003 | D23: =(D13-D12)/D15 -> 1.5344013 | E23: =(C23-D23)/D23 -> -0.03441145 | F23: =(F13-F12)/F15 -> 1.2367879 | G23: =(D23-F23)/F23 -> 0.24063417 | H23: =(H13-H12)/H15 -> 1.5437345 | I23: =(F23-H23)/H23 -> -0.19883385
A24: Net Working Capital | C24: =C13-C15 -> 611.82 | D24: =D13-D15 -> 590.08 | E24: =(C24-D24)/D24 -> 0.036842462 | F24: =F13-F15 -> 253.96 | G24: =(D24-F24)/F24 -> 1.3235155 | H24: =H13-H15 -> 507.88 | I24: =(F24-H24)/H24 -> -0.49996062
A25: Asset Management
A26: Accounts Rec. Turnover | C26: =C4/C11 -> 53.571902 | D26: =D4/D11 -> 58.58546 | E26: =(C26-D26)/D26 -> -0.085576829 | F26: =F4/F11 -> 55.844328 | G26: =(D26-F26)/F26 -> 0.049085234 | H26: =H4/H11 -> 38.97067 | I26: =(F26-H26)/H26 -> 0.43298351
A27: Inventory Turnover | C27: =C4/C12 -> 231.17797 | D27: =D4/D12 -> 251.12312 | E27: =(C27-D27)/D27 -> -0.079423792 | F27: =F4/F12 -> 242.07037 | G27: =(D27-F27)/F27 -> 0.037397211 | H27: =H4/H12 -> 229.88303 | I27: =(F27-H27)/H27 -> 0.053015367
A28: Total Asset Turnover | C28: =C4/C14 -> 1.2291824 | D28: =D4/D14 -> 1.2271517 | E28: =(C28-D28)/D28 -> 0.0016548474 | F28: =F4/F14 -> 1.2464309 | G28: =(D28-F28)/F28 -> -0.015467522 | H28: =H4/H14 -> 1.1343913 | I28: =(F28-H28)/H28 -> 0.098766256
A29: Debt Management
A30: Debt to Equity Ratio | C30: =C16/C18 -> 0.0027355665 | D30: =D16/D18 -> 0.0032656154 | E30: =(C30-D30)/D30 -> -0.1623121 | F30: =F16/F18 -> 1.4759166 | G30: =(D30-F30)/F30 -> -0.9977874 | H30: =H16/H18 -> 1.4372957 | I30: =(F30-H30)/H30 -> 0.026870531
A31: Equity multiplier | C31: =C14/C18 -> 2.5179166 | D31: =D14/D18 -> 2.6269786 | E31: =(C31-D31)/D31 -> -0.041516122 | F31: =F14/F18 -> 2.9254398 | G31: =(D31-F31)/F31 -> -0.1020227 | H31: =H14/H18 -> 2.8959027 | I31: =(F31-H31)/H31 -> 0.010199622
A32: Profitability
A33: Net Profit Margin | C33: 0.1356 | D33: 0.1245 | E33: =(C33-D33)/D33 -> 0.089156627 | F33: 0.2388 | G33: =(D33-F33)/F33 -> -0.47864322 | H33: 0.2262 | I33: =(F33-H33)/H33 -> 0.055702918
A34: Gross Profit Margin | C34: 0.2667 | D34: 0.262 | E34: =(C34-D34)/D34 -> 0.017938931 | F34: 0.1041 | G34: =(D34-F34)/F34 -> 1.5168108 | H34: 0.0865 | I34: =(F34-H34)/H34 -> 0.20346821
A35: Return On Assets ROA | C35: =C33*C28 -> 0.16667714 | D35: =D33*D28 -> 0.15278039 | E35: =(C35-D35)/D35 -> 0.090959015 | F35: =F33*F28 -> 0.2976477 | G35: =(D35-F35)/F35 -> -0.48670731 | H35: =H33*H28 -> 0.25659931 | I35: =(F35-H35)/H35 -> 0.15997074
A36: Return On Equity ROE | C36: =C35*C31 -> 0.41967913 | D36: =D35*D31 -> 0.4013508 | E36: =(C36-D36)/D36 -> 0.045666627 | F36: =F35*F31 -> 0.87075042 | G36: =(D36-F36)/F36 -> -0.53907482 | H36: =H35*H31 -> 0.74308665 | I36: =(F36-H36)/H36 -> 0.17180201
A37: Market Value
A38: EPS | C38: =C9/C19 -> 1.1211468 | D38: =D9/D19 -> 0.89183245 | E38: =(C38-D38)/D38 -> 0.25712715 | F38: =F9/F19 -> 0.6456547 | G38: =(D38-F38)/F38 -> 0.38128391 | H38: =H9/H19 -> 0.46422579 | I38: =(F38-H38)/H38 -> 0.3908204
A39: P/E | C39: =C3/C38 -> 53.596907 | D39: =D3/D38 -> 51.28766 | E39: =(C39-D39)/D39 -> 0.04502538 | F39: =F3/F38 -> 42.97963 | G39: =(D39-F39)/F39 -> 0.19330159 | H39: =H3/H38 -> 75.265098 | I39: =(F39-H39)/H39 -> -0.42895671
A40: Book Value Per Share | C40: =C18/C19 -> 2.6715217 | D40: =D18/D19 -> 2.2225843 | E40: =(C40-D40)/D40 -> 0.20198891 | F40: =F18/F19 -> 1.7005041 | G40: =(D40-F40)/F40 -> 0.30701496 | H40: =H18/H19 -> 1.6332788 | I40: =(F40-H40)/H40 -> 0.041159712
...

Sheet S24-21
A1: In the Millions | G1: In the Millions
A3: Income Statement | B3: Dec '24 | C3: Dec '23 | D3: Dec '22 | E3: Dec '21 | G3: Balance Sheet | H3: Dec '24 | I3: Dec '23 | J3: Dec '22 | K3: Dec '21
A4: Revenue | B4: 1252.61 | C4: 1087.53 | D4: 900.49 | E4: 739.89 | G4: Cash and Short Term Investments | H4: 320.71 | I4: 293.21 | J4: 311.23 | K4: 382.41
A5: Revenue Growth | B5: 0.1518 | C5: 0.2077 | D5: 0.217 | E5: 0.4151 | G5: Receivables | H5: 19.69 | I5: 16.85 | J5: 13.88 | K5: 13.66
A6: Cost of Revenue | B6: 950.14 | C6: 838.59 | D6: 717.1 | E6: 594.64 | G6: Inventory | H6: 6.01 | I6: 5.4 | J6: 4.18 | K6: 3.85
A7: Gross Profit | B7: 302.47 | C7: 248.94 | D7: 183.39 | E7: 145.26 | G7: Other current assets | H7: — | I7: — | J7: 15 | K7: 10
A8: SG&A Expenses | B8: 149.05 | C8: 129.54 | D8: 120.01 | E8: 87.2 | G8: Total current assets | H8: 368.22 | I8: 334.43 | J8: 343.99 | K8: 409.68
A9: Operating Income | B9: 3.04 | C9: 5.92 | D9: -26.89 | E9: -15.85 | G9: Property, Plant, Equipment (Net) | H9: 551.6 | I9: 531 | J9: 467.03 | K9: 389.39
A10: Interest Expense (Operating) | B10: — | C10: — | D10: 1.52 | E10: 1.58 | G10: Long-Term Investments | H10: — | I10: — | J10: — | K10: —
A11: Non-operating Income/Expense | B11: 11.21 | C11: 11.06 | D11: 2.61 | E11: -1.48 | G11: Goodwill and Intangible Assets (Total) | H11: — | I11: — | J11: 2 | K11: 1
A12: Non-operating Interest Expenses | B12: 2.04 | C12: 1.72 | D12: 1.52 | E12: 1.58 | G12: Long Term Assets (Tax, Deferred) | H12: 341.59 | I12: 326.21 | J12: 317.63 | K12: 298.67
A13: EBT | B13: 14.24 | C13: 16.98 | D13: -24.29 | E13: -17.34 | G13: Long-term assets (Other) | H13: 10.96 | I13: 15.93 | J13: 15.82 | K13: 12.56
A14: Income Tax Provision | B14: 3.42 | C14: -4.01 | D14: -1.18 | E14: -11.32 | G14: Total non-current assets | H14: 1328.76 | I14: 1271.42 | J14: 1167.96 | K14: 1047.89
A15: Income after Tax | B15: 10.82 | C15: 20.99 | D15: -23.11 | E15: -6.02 | G15: Total Assets | H15: 1696.97 | I15: 1605.86 | J15: 1511.95 | K15: 1457.57
A16: Dividends (Preferred) | B16: — | C16: 0 | D16: — | E16: 0 | G16: Accounts Payable | H16: 23.61 | I16: 22.27 | J16: 20.41 | K16: 19.95
A17: Non-Controlling Interest | B17: 0.61 | C17: 0.73 | D17: -1.88 | E17: -1.46 | G17: Accrued Expenses | H17: 63.01 | I17: 54.74 | J17: 47.95 | K17: 36.89
A18: Net Income Common | B18: 10.21 | C18: 20.26 | D18: -21.23 | E18: -4.56 | G18: Current Part of Debt | H18: — | I18: — | J18: 45 | K18: 38
A19: EPS (Basic) | B19: 0.26 | C19: 0.5 | D19: -0.61 | E19: -0.22 | G19: Other current liabilities | H19: 19.54 | I19: 17.1 | J19: 19.55 | K19: 14.5
A20: EPS (Diluted) | B20: 0.24 | C20: 0.47 | D20: -0.61 | E20: -0.22 | G20: Total current liabilities | H20: 187.31 | I20: 164.07 | J20: 147.72 | K20: 121.5
A21: Shares (Basic, Weighted) | B21: 39.83 | C21: 39.42 | D21: 39.24 | E21: 39.09 | G21: Long Term Debt (Total) | H21: 246.68 | I21: 245.64 | J21: 244.59 | K21: 243.54
A22: Shares (Diluted, Weighted) | B22: 44.2 | C22: 43.9 | D22: 39.24 | E22: 39.09 | G22: Non-current Revenue (Deferred) | H22: — | I22: — | J22: 14 | K22: 13
A23: Gross Margin | B23: 0.2415 | C23: 0.2289 | D23: 0.2037 | E23: 0.1963 | G23: Long Term Tax Liability (Deferred) | H23: — | I23: — | J23: -301 | K23: -299
A24: EBIT Margin | B24: 0.0024 | C24: 0.0054 | D24: -0.0299 | E24: -0.0214 | G24: Non-current Liabilities (Other) | H24: 274.85 | I24: 262.25 | J24: 255.58 | K24: 256.82
A25: EBT margin | B25: 0.0114 | C25: 0.0156 | D25: -0.027 | E25: -0.0234 | G25: Total non-current liabilities | H25: 1016.03 | I25: 972.42 | J25: 927.4 | K25: 900.47
A26: Net Profit Margin | B26: 0.0081 | C26: 0.0186 | D26: -0.0236 | E26: -0.0062 | G26: Total liabilities | H26: 1203.35 | I26: 1136.49 | J26: 1075.11 | K26: 1021.97
A27: Free Cash Flow Margin | B27: 0.0285 | C27: -0.0129 | D27: -0.0731 | E27: -0.0582 | G27: Additional Paid In Capital | H27: 442.99 | I27: 426.6 | J27: 415.65 | K27: 405.94
A28: EBITDA | B28: 108.25 | C28: 98.39 | D28: 48.45 | E28: 45.25 | G28: Common Stock (Net) | H28: 0.04 | I28: 0.04 | J28: 0.04 | K28: 0.04
A29: EBIT | B29: 3.04 | C29: 5.92 | D29: -26.89 | E29: -15.85 | G29: Retained Earnings | H29: 26.98 | I29: 16.78 | J29: -3.49 | K29: 3.55
A30: Income from Continuous Operations | B30: 10.82 | C30: 20.99 | D30: -23.11 | E30: -6.02 | G30: Common Equity (Total) | H30: 493.63 | I30: 469.37 | J30: 436.84 | K30: 435.6
A31: Consolidated Net Income/Loss | B31: 10.82 | C31: 20.99 | D31: -23.11 | E31: -6.02 | G31: Shareholders Equity (Total) | H31: 493.63 | I31: 469.37 | J31: 436.84 | K31: 435.6
A32: EPS (Basic, from Continuous Ops) | B32: 0.27 | C32: 0.53 | D32: -0.59 | E32: -0.15 | G32: Shareholders Equity and Liabilities (Total) | H32: 1696.97 | I32: 1605.86 | J32: 1511.95 | K32: 1457.57
A33: EPS (Basic, Consolidated) | B33: 0.27 | C33: 0.53 | D33: -0.59 | E33: -0.15 | G33: Shares (Common) | H33: 42.52 | I33: 42.31 | J33: 42.16 | K33: 42.06
A34: EPS (Diluted, from Cont. Ops) | B34: 0.24 | C34: 0.48 | D34: -0.59 | E34: -0.15 | G34: Shareholders Equity (Tangible) | H34: 493.63 | I34: 469.37 | J34: 436.84 | K34: 435.6
A35: Shares (Diluted, Average) | B35: 44.2 | C35: 43.9 | D35: 39.24 | E35: 39.09 | G35: Net Debt | H35: -74.03 | I35: -47.58 | J35: -21.64 | K35: -100.86
A36: EPS (Diluted, Consolidated) | B36: 0.24 | C36: 0.48 | D36: -0.59 | E36: -0.15 | G36: Total Debt | H36: 246.68 | I36: 245.64 | J36: 289.59 | K36: 281.54
A37: EBITDA Margin | B37: 0.0864 | C37: 0.0905 | D37: 0.0538 | E37: 0.0612
A38: Operating Cash Flow Margin | B38: 0.1366 | C38: 0.1215 | D38: 0.0852 | E38: 0.0789
A39: Cash and Short Term Investments | B39: 320.71 | C39: 293.21 | D39: 311.23 | E39: 382.41
A40: Receivables | B40: 19.69 | C40: 16.85 | D40: 13.88 | E40: 13.66
A41: Inventory | B41: 6.01 | C41: 5.4 | D41: 4.18 | E41: 3.85
...

Sheet YOY SHAK
A1: Company Name | C1: SHAK | D1: SHAK | E1: YOY % Change 2024 2023 | F1: SHAK | G1: YOY % Change 2023 2022 | H1: SHAK | I1: YOY % Change 2022 2021
A2: Year ending: | C2: 2024 | D2: 2023 | F2: 2022 | H2: 2021
A3: Stock Price | C3: 129.51 | D3: 74.12 | E3: =+(C3-D3)/D3 -> 0.74730167 | F3: 41.53 | G3: =+(D3-F3)/F3 -> 0.78473393 | H3: 73.07 | I3: =(F3-H3)/H3 -> -0.43164089
A4: Revenue | C4: =_xlfn.XLOOKUP(A4,'S24-21'!$A$4:$A$71,'S24-21'!$B$4:$B$71,"LOOK",0) -> 1252.61 | D4: =_xlfn.XLOOKUP(A4,'S24-21'!$A$4:$A$71,'S24-21'!$C$4:$C$71,"LOOK",0) -> 1087.53 | E4: =+(C4-D4)/D4 -> 0.15179351 | F4: =_xlfn.XLOOKUP(A4,'S24-21'!$A$4:$A$71,'S24-21'!$D$4:$D$71) -> 900.49 | G4: =+(D4-F4)/F4 -> 0.20770914 | H4: =_xlfn.XLOOKUP(A4,'S24-21'!$A$4:$A$71,'S24-21'!$E$4:$E$71) -> 739.89 | I4: =(F4-H4)/H4 -> 0.21705929
A5: Cost of Revenue | C5: =_xlfn.XLOOKUP(A5,'S24-21'!$A$4:$A$71,'S24-21'!$B$4:$B$71,"LOOK",0) -> 950.14 | D5: =_xlfn.XLOOKUP(A5,'S24-21'!$A$4:$A$71,'S24-21'!$C$4:$C$71,"LOOK",0) -> 838.59 | E5: =+(C5-D5)/D5 -> 0.1330209 | F5: =_xlfn.XLOOKUP(A5,'S24-21'!$A$4:$A$71,'S24-21'!$D$4:$D$71) -> 717.1 | G5: =+(D5-F5)/F5 -> 0.16941849 | H5: =_xlfn.XLOOKUP(A5,'S24-21'!$A$4:$A$71,'S24-21'!$E$4:$E$71) -> 594.64 | I5: =(F5-H5)/H5 -> 0.20593973
A6: Gross Profit | C6: =_xlfn.XLOOKUP(A6,'S24-21'!$A$4:$A$71,'S24-21'!$B$4:$B$71,"LOOK",0) -> 302.47 | D6: =_xlfn.XLOOKUP(A6,'S24-21'!$A$4:$A$71,'S24-21'!$C$4:$C$71,"LOOK",0) -> 248.94 | E6: =+(C6-D6)/D6 -> 0.21503173 | F6: =_xlfn.XLOOKUP(A6,'S24-21'!$A$4:$A$71,'S24-21'!$D$4:$D$71) -> 183.39 | G6: =+(D6-F6)/F6 -> 0.35743497 | H6: =_xlfn.XLOOKUP(A6,'S24-21'!$A$4:$A$71,'S24-21'!$E$4:$E$71) -> 145.26 | I6: =(F6-H6)/H6 -> 0.26249484
A7: SG&A Expenses | C7: =_xlfn.XLOOKUP(A7,'S24-21'!$A$4:$A$71,'S24-21'!$B$4:$B$71,"LOOK",0) -> 149.05 | D7: =_xlfn.XLOOKUP(A7,'S24-21'!$A$4:$A$71,'S24-21'!$C$4:$C$71,"LOOK",0) -> 129.54 | E7: =+(C7-D7)/D7 -> 0.15060985 | F7: =_xlfn.XLOOKUP(A7,'S24-21'!$A$4:$A$71,'S24-21'!$D$4:$D$71) -> 120.01 | G7: =+(D7-F7)/F7 -> 0.079410049 | H7: =_xlfn.XLOOKUP(A7,'S24-21'!$A$4:$A$71,'S24-21'!$E$4:$E$71) -> 87.2 | I7: =(F7-H7)/H7 -> 0.37626147
A8: Operating Income | C8: =_xlfn.XLOOKUP(A8,'S24-21'!$A$4:$A$71,'S24-21'!$B$4:$B$71,"LOOK",0) -> 3.04 | D8: =_xlfn.XLOOKUP(A8,'S24-21'!$A$4:$A$71,'S24-21'!$C$4:$C$71,"LOOK",0) -> 5.92 | E8: =+(C8-D8)/D8 -> -0.48648649 | F8: =_xlfn.XLOOKUP(A8,'S24-21'!$A$4:$A$71,'S24-21'!$D$4:$D$71) -> -26.89 | G8: =+(D8-F8)/F8 -> -1.2201562 | H8: =_xlfn.XLOOKUP(A8,'S24-21'!$A$4:$A$71,'S24-21'!$E$4:$E$71) -> -15.85 | I8: =(F8-H8)/H8 -> 0.69652997
A9: Net Income Common | C9: =_xlfn.XLOOKUP(A9,'S24-21'!$A$4:$A$71,'S24-21'!$B$4:$B$71,"LOOK",0) -> 10.21 | D9: =_xlfn.XLOOKUP(A9,'S24-21'!$A$4:$A$71,'S24-21'!$C$4:$C$71,"LOOK",0) -> 20.26 | E9: =+(C9-D9)/D9 -> -0.49605133 | F9: =_xlfn.XLOOKUP(A9,'S24-21'!$A$4:$A$71,'S24-21'!$D$4:$D$71) -> -21.23 | G9: =+(D9-F9)/F9 -> -1.9543099 | H9: =_xlfn.XLOOKUP(A9,'S24-21'!$A$4:$A$71,'S24-21'!$E$4:$E$71) -> -4.56 | I9: =(F9-H9)/H9 -> 3.6557018
A10: Cash and Short Term Investments | C10: =_xlfn.XLOOKUP(A10,'S24-21'!$A$4:$A$71,'S24-21'!$B$4:$B$71,"LOOK",0) -> 320.71 | D10: =_xlfn.XLOOKUP(A10,'S24-21'!$A$4:$A$71,'S24-21'!$C$4:$C$71,"LOOK",0) -> 293.21 | E10: =+(C10-D10)/D10 -> 0.093789434 | F10: =_xlfn.XLOOKUP(A10,'S24-21'!$A$4:$A$71,'S24-21'!$D$4:$D$71) -> 311.23 | G10: =+(D10-F10)/F10 -> -0.057899303 | H10: =_xlfn.XLOOKUP(A10,'S24-21'!$A$4:$A$71,'S24-21'!$E$4:$E$71) -> 382.41 | I10: =(F10-H10)/H10 -> -0.1861353
A11: Receivables | C11: =_xlfn.XLOOKUP(A11,'S24-21'!$A$4:$A$71,'S24-21'!$B$4:$B$71,"LOOK",0) -> 19.69 | D11: =_xlfn.XLOOKUP(A11,'S24-21'!$A$4:$A$71,'S24-21'!$C$4:$C$71,"LOOK",0) -> 16.85 | E11: =+(C11-D11)/D11 -> 0.16854599 | F11: =_xlfn.XLOOKUP(A11,'S24-21'!$A$4:$A$71,'S24-21'!$D$4:$D$71) -> 13.88 | G11: =+(D11-F11)/F11 -> 0.21397695 | H11: =_xlfn.XLOOKUP(A11,'S24-21'!$A$4:$A$71,'S24-21'!$E$4:$E$71) -> 13.66 | I11: =(F11-H11)/H11 -> 0.016105417
A12: Inventory | C12: =_xlfn.XLOOKUP(A12,'S24-21'!$A$4:$A$71,'S24-21'!$B$4:$B$71,"LOOK",0) -> 6.01 | D12: =_xlfn.XLOOKUP(A12,'S24-21'!$A$4:$A$71,'S24-21'!$C$4:$C$71,"LOOK",0) -> 5.4 | E12: =+(C12-D12)/D12 -> 0.11296296 | F12: =_xlfn.XLOOKUP(A12,'S24-21'!$A$4:$A$71,'S24-21'!$D$4:$D$71) -> 4.18 | G12: =+(D12-F12)/F12 -> 0.29186603 | H12: =_xlfn.XLOOKUP(A12,'S24-21'!$A$4:$A$71,'S24-21'!$E$4:$E$71) -> 3.85 | I12: =(F12-H12)/H12 -> 0.085714286
A13: Total current assets | C13: =_xlfn.XLOOKUP(A13,'S24-21'!$A$4:$A$71,'S24-21'!$B$4:$B$71,"LOOK",0) -> 368.22 | D13: =_xlfn.XLOOKUP(A13,'S24-21'!$A$4:$A$71,'S24-21'!$C$4:$C$71,"LOOK",0) -> 334.43 | E13: =+(C13-D13)/D13 -> 0.10103759 | F13: =_xlfn.XLOOKUP(A13,'S24-21'!$A$4:$A$71,'S24-21'!$D$4:$D$71) -> 343.99 | G13: =+(D13-F13)/F13 -> -0.027791506 | H13: =_xlfn.XLOOKUP(A13,'S24-21'!$A$4:$A$71,'S24-21'!$E$4:$E$71) -> 409.68 | I13: =(F13-H13)/H13 -> -0.16034466
