Workbook
Name Top5Stocks: 'Stock Pivot Table'!$F$5:$F$9

Sheet Exe Sum & Dashboard
X3: DASHBOARD AREA
AM47: 5

Sheet Memo

Sheet Stock Pivot Table
A3: Stocks by % Return
A4: Stock | B4: Sum of Invested Dollars 2018 | C4: Sum of Invested Dollars 2025 | D4: Sum of 7 Year Total Return | E4: Average of Current P/E | F4: Sum of Return % | H4: Top 5 Stocks
A5: AZO | B5: 28573764 | C5: 3.7359756e+09 | D5: 3.7074018e+09 | E5: 22.6273 | F5: 129.74846 | H5: Stock | I5: % Return
A6: AJG | B6: 29816868 | C6: 2.7614486e+09 | D6: 2.7316317e+09 | E6: 50.4936 | F6: 91.613636 | H6: {=A5:A9} -> AZO | I6: {=Top5Stocks} -> 129.74846
A7: CMI | B7: 27044211 | C7: 1.6741915e+09 | D7: 1.6471473e+09 | E7: 12.9977 | F7: 60.905724 | H7: AJG | I7: 91.613636
A8: FICO | B8: 35181246 | C8: 2.0061903e+09 | D8: 1.971009e+09 | E8: 79.7386 | F8: 56.024423 | H8: CMI | I8: 60.905724
A9: CW | B9: 17358083 | C9: 6.6702247e+08 | D9: 6.4966439e+08 | E9: 29.9486 | F9: 37.427196 | H9: FICO | I9: 56.024423
A10: CRM | B10: 23783848 | C10: 9.1057744e+08 | D10: 8.8679359e+08 | E10: 50.6199 | F10: 37.285539 | H10: CW | I10: 37.427196
A11: ABT | B11: 43377681 | C11: 1.5780542e+09 | D11: 1.5346765e+09 | E11: 17.5493 | F11: 35.379404
A12: DDS | B12: 35949540 | C12: 1.2852565e+09 | D12: 1.249307e+09 | E12: 12.2372 | F12: 34.751683
A13: AGM | B13: 41531197 | C13: 1.3515457e+09 | D13: 1.3100145e+09 | E13: 0 | F13: 31.542902 | H13: Bottom 5 Stocks
A14: CB | B14: 18191639 | C14: 5.8568789e+08 | D14: 5.6749625e+08 | E14: 11.9143 | F14: 31.195444 | H14: Stock | I14: % Return
A15: AVAV | B15: 24079285 | C15: 6.9667898e+08 | D15: 6.725997e+08 | E15: 89.6554 | F15: 27.93271 | H15: {=A299:A303} -> AGR | I15: {=F299:F303} -> -0.98283568
A16: BSRR | B16: 19816545 | C16: 5.5875249e+08 | D16: 5.3893594e+08 | E16: 11.8379 | F16: 27.196262 | H16: CERS | I16: -0.9853573
A17: BK | B17: 34060850 | C17: 9.4027288e+08 | D17: 9.0621203e+08 | E17: 15.1291 | F17: 26.605678 | H17: DISH | I17: -0.99758298
A18: DJCO | B18: 39558097 | C18: 1.0475636e+09 | D18: 1.0080055e+09 | E18: 7.3334 | F18: 25.481648 | H18: AMD | I18: -0.99898161
A19: ETN | B19: 30526152 | C19: 6.9337311e+08 | D19: 6.6284696e+08 | E19: 30.9396 | F19: 21.714068 | H19: ATO | I19: -1
A20: ECL | B20: 19563313 | C20: 4.2355212e+08 | D20: 4.039888e+08 | E20: 35.8927 | F20: 20.650327
A21: ADSK | B21: 39318934 | C21: 8.5102066e+08 | D21: 8.1170172e+08 | E21: 56.6184 | F21: 20.644042
A22: GFF | B22: 22076485 | C22: 4.7559431e+08 | D22: 4.5351782e+08 | E22: 14.7676 | F22: 20.543027 | H22: Top 5 Stocks
A23: DFS | B23: 39178249 | C23: 8.1477407e+08 | D23: 7.7559582e+08 | E23: 11.0149 | F23: 19.796592 | H23: Stock | I23: Total Invested Dollars
A24: EQT | B24: 25377100 | C24: 5.165684e+08 | D24: 4.911913e+08 | E24: 127.4905 | F24: 19.355691 | H24: {=A308:A312} -> AZO | I24: {=C308:C312} -> 3.7359756e+09
A25: AEL | B25: 32836895 | C25: 6.0369133e+08 | D25: 5.7085443e+08 | E25: 14.37 | F25: 17.384543 | H25: AJG | I25: 2.7614486e+09
A26: ADBE | B26: 29555429 | C26: 4.6567848e+08 | D26: 4.3612305e+08 | E26: 35.8412 | F26: 14.756106 | H26: FICO | I26: 2.0061903e+09
A27: DHR | B27: 34535661 | C27: 4.246487e+08 | D27: 3.9011304e+08 | E27: 40.0645 | F27: 11.295948 | H27: CMI | I27: 1.6741915e+09
A28: EQIX | B28: 37447830 | C28: 4.593864e+08 | D28: 4.2193857e+08 | E28: 107.585 | F28: 11.26737 | H28: ABT | I28: 1.5780542e+09
A29: AVGO | B29: 33364462 | C29: 3.7804436e+08 | D29: 3.446799e+08 | E29: 170.9483 | F29: 10.330749
A30: GHC | B30: 39526443 | C30: 4.1847142e+08 | D30: 3.7894497e+08 | E30: 18.2061 | F30: 9.5871255
A31: ERIE | B31: 24754571 | C31: 2.6151402e+08 | D31: 2.3675945e+08 | E31: 35.8709 | F31: 9.564272 | H31: Bottom 5 Stocks
A32: CADE | B32: 31032617 | C32: 2.9321389e+08 | D32: 2.6218128e+08 | E32: 12.0072 | F32: 8.4485714 | H32: Stock | I32: Total Invested Dollars
A33: CVS | B33: 36223875 | C33: 3.4134036e+08 | D33: 3.0511648e+08 | E33: 17.3163 | F33: 8.4230769 | H33: {=A602:A606} -> GES | I33: {=C602:C606} -> 386755.51
A34: ADC | B34: 16862170 | C34: 1.5101287e+08 | D34: 1.341507e+08 | E34: 40.6362 | F34: 7.9557196 | H34: CNX | I34: 377646.39
A35: DTE | B35: 24343069 | C35: 2.1402827e+08 | D35: 1.896852e+08 | E35: 19.3821 | F35: 7.7921647 | H35: DISH | I35: 41444.706
A36: BC | B36: 18666449 | C36: 1.6361445e+08 | D36: 1.4494801e+08 | E36: 28.2123 | F36: 7.7651622 | H36: AMD | I36: 17311.914
A37: FDX | B37: 30652768 | C37: 2.6267334e+08 | D37: 2.3202057e+08 | E37: 16.1764 | F37: 7.5693186 | H37: ATO | I37: 0
A38: ARMK | B38: 37890986 | C38: 2.9726675e+08 | D38: 2.5937577e+08 | E38: 29.0507 | F38: 6.8453159
A39: GGG | B39: 40381102 | C39: 3.1561693e+08 | D39: 2.7523583e+08 | E39: 30.3511 | F39: 6.8159565
A40: FFIV | B40: 40655436 | C40: 3.1450332e+08 | D40: 2.7384788e+08 | E40: 29.4057 | F40: 6.7358244
A41: CRS | B41: 18149434 | C41: 1.2823083e+08 | D41: 1.1008139e+08 | E41: 37.4631 | F41: 6.0652798
A42: AVY | B42: 31475773 | C42: 2.1823829e+08 | D42: 1.8676252e+08 | E42: 21.138 | F42: 5.9335325
...

Sheet Sector Pivot Table
A2: Sectors by % Return
A3: Sector | B3: Sum of Invested Dollars 2018 | C3: Sum of Invested Dollars 2025 | D3: Sum of 7 Year Total Return | E3: Average of Current P/E | F3: Sum of Return % | H3: Top 5 Sectors
A4: Department Stores | B4: 35949540 | C4: 1.2852565e+09 | D4: 1.249307e+09 | E4: 12.2372 | F4: 34.751683 | H4: Sector | I4: % Return
A5: Insurance Brokers | B5: 1.1468467e+08 | C5: 3.3120961e+09 | D5: 3.1974114e+09 | E5: 45.461875 | F5: 27.880023 | H5: {=A4:A8} -> Department Stores | I5: {=F4:F8} -> 34.751683
A6: Specialty Retail | B6: 1.390297e+08 | C6: 3.9941229e+09 | D6: 3.8550932e+09 | E6: 49.06462 | F6: 27.728559 | H6: Insurance Brokers | I6: 27.880023
A7: Publishing | B7: 62824929 | C7: 1.0496101e+09 | D7: 9.8678518e+08 | E7: 3.6667 | F7: 15.706905 | H7: Specialty Retail | I7: 27.728559
A8: Software - Infrastructure | B8: 1.6426029e+08 | C8: 2.441156e+09 | D8: 2.2768957e+09 | E8: 39.50794 | F8: 13.861511 | H8: Publishing | I8: 15.706905
A9: Building Materials | B9: 50482737 | C9: 6.5674661e+08 | D9: 6.0626387e+08 | E9: 30.05795 | F9: 12.00933 | H9: Software - Infrastructure | I9: 13.861511
A10: Medical Devices | B10: 1.2749634e+08 | C10: 1.6460729e+09 | D10: 1.5185766e+09 | E10: 36.66195 | F10: 11.910746
A11: Asset Management | B11: 1.0015669e+08 | C11: 1.2773021e+09 | D11: 1.1771454e+09 | E11: 25.6026 | F11: 11.753038 | H11: Bottom 5 Sectors
A12: Diversified Industrials | B12: 3.0679147e+08 | C12: 3.8889177e+09 | D12: 3.5821263e+09 | E12: 24.63739 | F12: 11.676095 | H12: Sector | I12: % Return
A13: Software - Application | B13: 2.069748e+08 | C13: 2.5839668e+09 | D13: 2.376992e+09 | E13: 48.699 | F13: 11.484451 | H13: {=A102:A106} -> Farm Products | I13: {=F102:F106} -> -0.78490887
A14: Insurance - Life | B14: 66138049 | C14: 8.0860456e+08 | D14: 7.4246651e+08 | E14: 12.5521 | F14: 11.226012 | H14: Real Estate - General | I14: -0.79432044
A15: Credit Services | B15: 2.0739447e+08 | C15: 2.3751666e+09 | D15: 2.1677722e+09 | E15: 9.8771429 | F15: 10.452411 | H15: Industrial Metals & Minerals | I15: -0.84775878
A16: Aerospace & Defense | B16: 1.0573949e+08 | C16: 9.8187738e+08 | D16: 8.7613789e+08 | E16: 34.572225 | F16: 8.2858157 | H16: REIT - Hotel & Motel | I16: -0.88936731
A17: Home Furnishings & Fixtures | B17: 35896783 | C17: 2.1330452e+08 | D17: 1.7740774e+08 | E17: 10.5707 | F17: 4.9421626 | H17: REIT - Office | I17: -0.94169108
A18: Education & Training Services | B18: 71593091 | C18: 4.1939666e+08 | D18: 3.4780357e+08 | E18: 9.10305 | F18: 4.8580605
A19: Gambling | B19: 26442785 | C19: 1.5050362e+08 | D19: 1.2406084e+08 | E19: 20.5844 | F19: 4.6916707 | H19: Top 5 Sectors
A20: Restaurants | B20: 92749656 | C20: 4.8754256e+08 | D20: 3.9479291e+08 | E20: 20.6809 | F20: 4.2565431 | H20: Sector | I20: Total Invested Dollars
A21: Discount Stores | B21: 55154107 | C21: 2.808643e+08 | D21: 2.2571019e+08 | E21: 36.7176 | F21: 4.0923551 | H21: {=A111:A115} -> Specialty Retail | I21: {=C111:C115} -> 3.9941229e+09
A22: Insurance - Property & Casualty | B22: 1.5419904e+08 | C22: 7.5185101e+08 | D22: 5.9765196e+08 | E22: 6.94226 | F22: 3.8758474 | H22: Diversified Industrials | I22: 3.8889177e+09
A23: Oil & Gas Integrated | B23: 18476525 | C23: 89825657 | D23: 71349132 | E23: 16.2376 | F23: 3.8616099 | H23: Insurance Brokers | I23: 3.3120961e+09
A24: Health Care Plans | B24: 89499844 | C24: 4.2794359e+08 | D24: 3.3844375e+08 | E24: 18.095867 | F24: 3.781501 | H24: Software - Application | I24: 2.5839668e+09
A25: Diagnostics & Research | B25: 2.1573003e+08 | C25: 9.6799093e+08 | D25: 7.5226091e+08 | E25: 27.603471 | F25: 3.4870478 | H25: Software - Infrastructure | I25: 2.441156e+09
A26: Rubber & Plastics | B26: 36941366 | C26: 1.6518896e+08 | D26: 1.282476e+08 | E26: 18.2626 | F26: 3.4716529
A27: Waste Management | B27: 71763046 | C27: 3.1536843e+08 | D27: 2.4360538e+08 | E27: 10.776033 | F27: 3.3945797 | H27: Bottom 5 Sectors
A28: Business Equipment | B28: 54658194 | C28: 2.2527774e+08 | D28: 1.7061954e+08 | E28: 10.569 | F28: 3.121573 | H28: Sector | I28: Total Invested Dollars
A29: Insurance - Diversified | B29: 35854578 | C29: 1.4367766e+08 | D29: 1.0782308e+08 | E29: 5.0087 | F29: 3.0072333 | H29: {=A209:A213} -> REIT - Hotel & Motel | I29: {=C209:C213} -> 8634937.7
A30: Specialty Chemicals | B30: 1.3150585e+08 | C30: 5.1361681e+08 | D30: 3.8211096e+08 | E30: 25.09805 | F30: 2.9056575 | H30: Real Estate - General | I30: 7619785.8
A31: Leisure | B31: 48432905 | C31: 1.8882689e+08 | D31: 1.4039398e+08 | E31: 22.62575 | F31: 2.8987314 | H31: Industrial Metals & Minerals | I31: 5832823.7
A32: Oil & Gas E&P | B32: 2.2502689e+08 | C32: 8.3674508e+08 | D32: 6.1171819e+08 | E32: 48.577213 | F32: 2.7184227 | H32: Steel | I32: 5772230.9
A33: Integrated Shipping & Logistics | B33: 1.0126458e+08 | C33: 3.7262821e+08 | D33: 2.7136363e+08 | E33: 5.3921333 | F33: 2.6797486 | H33: REIT - Office | I33: 3066474
A34: REIT - Diversified | B34: 1.3422423e+08 | C34: 4.8808619e+08 | D34: 3.5386196e+08 | E34: 52.219125 | F34: 2.6363494
A35: Farm & Construction Equipment | B35: 1.3220224e+08 | C35: 4.7688722e+08 | D35: 3.4468498e+08 | E35: 24.15205 | F35: 2.6072552
A36: Specialty Finance | B36: 22042877 | C36: 79405258 | D36: 57362381 | E36: 8.267 | F36: 2.6023092
A37: Metal Fabrication | B37: 50754199 | C37: 1.7018528e+08 | D37: 1.1943108e+08 | E37: 30.1157 | F37: 2.353127
A38: Agricultural Inputs | B38: 81954504 | C38: 2.7460186e+08 | D38: 1.9264735e+08 | E38: 23.0409 | F38: 2.3506622
A39: Capital Markets | B39: 32034994 | C39: 1.0454981e+08 | D39: 72514814 | E39: 31.6782 | F39: 2.2636126
A40: Semiconductors | B40: 1.5000348e+08 | C40: 4.6950894e+08 | D40: 3.1950546e+08 | E40: 50.11808 | F40: 2.129987
A41: Medical Care | B41: 1.2510119e+08 | C41: 3.8969358e+08 | D41: 2.6459239e+08 | E41: 25.45775 | F41: 2.115027
...

Sheet Portfolio
A1: Investment Portfolio Return Case
B2: Portfolio: Mutual Fund 1 | I2: Portfolio | J2: =SUM($D$9:$D$2565) -> 0.96180535
B3: Benchmark:Russell 3000 TR USD | I3: Total Dollars Invested 2018 | J3: 9.7697568e+09
B4: Grouping:Morningstar Industry | I4: Total Dollars Invested 2025 | J4: =SUM(F9:F307) -> 4.3484456e+10
B5: Russel RUA Benchmark Total Return 7 year | C5: =(RUA!E2-RUA!E252)/RUA!E252 -> 1.1606401 | I5: Total Dollar Return in Dollars | J5: =J4-J3 -> 3.3714699e+10
B6: Russel Benchmark CAGR | C6: =((RUA!E2/RUA!E252)^(1/7))-1 -> 0.11634258 | I6: CAGR | J6: =((J4/J3)^(1/7))-1 -> 0.23775804
B7: Investment Portfoilo one | I7: Total Return 2018-2025 % | J7: =(J4-J3)/J3 -> 3.4509251
A8: Sector | B8: Company Name | C8: Stock Symbol | D8: Weights % | E8: Invested Dollars 2018 | F8: Invested Dollars 2025 | G8: 7 Year Total Return | H8: CAGR | I8: Purchased Price Per Share Jan 2018 | J8: Sold Price Per Share FEB 2025 | K8: Current P/E | L8: Total 7 Year % Return | M8: # of shares of Stock
A9: =_xlfn.XLOOKUP(C9,'Sectors & Company Names'!$B$2:$B$2814,'Sectors & Company Names'!$C$2:$C$2814) -> Media - Diversified | B9: =_xlfn.XLOOKUP(C9,'Sectors & Company Names'!$B$2:$B$2814,'Sectors & Company Names'!$A$2:$A$2814) -> 21ST CENTURY FOX CL B FOX | C9: FOX | D9: 0.004050116 | E9: =+$J$3*D9 -> 39568649 | F9: =(L9+1)*E9 -> 1.1293198e+08 | G9: =F9-E9 -> 73363331 | H9: =((F9/E9)^(1/7))-1 -> 0.16162656 | I9: 18.64 | J9: 53.2 | K9: 0 | L9: =+(J9-I9)/I9 -> 1.8540773 | M9: =F9/J9 -> 2122781.6
A10: =_xlfn.XLOOKUP(C10,'Sectors & Company Names'!$B$2:$B$2814,'Sectors & Company Names'!$C$2:$C$2814) -> Building Materials | B10: =_xlfn.XLOOKUP(C10,'Sectors & Company Names'!$B$2:$B$2814,'Sectors & Company Names'!$A$2:$A$2814) -> AAON INC | C10: AAON | D10: 0.00290757 | E10: =+$J$3*D10 -> 28406252 | F10: =(L10+1)*E10 -> 1.811523e+08 | G10: =F10-E10 -> 1.5274605e+08 | H10: =((F10/E10)^(1/7))-1 -> 0.30300815 | I10: 16.49 | J10: 105.16 | K10: 45.3483 | L10: =+(J10-I10)/I10 -> 5.3771983 | M10: =F10/J10 -> 1722635
A11: =_xlfn.XLOOKUP(C11,'Sectors & Company Names'!$B$2:$B$2814,'Sectors & Company Names'!$C$2:$C$2814) -> Medical Devices | B11: =_xlfn.XLOOKUP(C11,'Sectors & Company Names'!$B$2:$B$2814,'Sectors & Company Names'!$A$2:$A$2814) -> ABBOTT LABORATORIES | C11: ABT | D11: 0.004439996 | E11: =+$J$3*D11 -> 43377681 | F11: =(L11+1)*E11 -> 1.5780542e+09 | G11: =F11-E11 -> 1.5346765e+09 | H11: =((F11/E11)^(1/7))-1 -> 0.67101123 | I11: 3.69 | J11: 134.24 | K11: 17.5493 | L11: =+(J11-I11)/I11 -> 35.379404 | M11: =F11/J11 -> 11755469
A12: =_xlfn.XLOOKUP(C12,'Sectors & Company Names'!$B$2:$B$2814,'Sectors & Company Names'!$C$2:$C$2814) -> Drug Manufacturers - Major | B12: =_xlfn.XLOOKUP(C12,'Sectors & Company Names'!$B$2:$B$2814,'Sectors & Company Names'!$A$2:$A$2814) -> ABBVIE INC | C12: ABBV | D12: 0.004232636 | E12: =+$J$3*D12 -> 41351825 | F12: =(L12+1)*E12 -> 55637903 | G12: =F12-E12 -> 14286079 | H12: =((F12/E12)^(1/7))-1 -> 0.04330399 | I12: 149.88 | J12: 201.66 | K12: 84.8449 | L12: =+(J12-I12)/I12 -> 0.34547638 | M12: =F12/J12 -> 275899.55
A13: =_xlfn.XLOOKUP(C13,'Sectors & Company Names'!$B$2:$B$2814,'Sectors & Company Names'!$C$2:$C$2814) -> Business Services | B13: =_xlfn.XLOOKUP(C13,'Sectors & Company Names'!$B$2:$B$2814,'Sectors & Company Names'!$A$2:$A$2814) -> ABM INDUSTRIES INC | C13: ABM | D13: 0.004155956 | E13: =+$J$3*D13 -> 40602680 | F13: =(L13+1)*E13 -> 1.2949627e+08 | G13: =F13-E13 -> 88893586 | H13: =((F13/E13)^(1/7))-1 -> 0.18020515 | I13: 16.53 | J13: 52.72 | K13: 41.2375 | L13: =+(J13-I13)/I13 -> 2.1893527 | M13: =F13/J13 -> 2456302.5
A14: =_xlfn.XLOOKUP(C14,'Sectors & Company Names'!$B$2:$B$2814,'Sectors & Company Names'!$C$2:$C$2814) -> REIT - Retail | B14: =_xlfn.XLOOKUP(C14,'Sectors & Company Names'!$B$2:$B$2814,'Sectors & Company Names'!$A$2:$A$2814) -> ACADIA REALTY TRUST | C14: AKR | D14: 0.004369796 | E14: =+$J$3*D14 -> 42691844 | F14: =(L14+1)*E14 -> 33879240 | G14: =F14-E14 -> -8812604.7 | H14: =((F14/E14)^(1/7))-1 -> -0.032489841 | I14: 28.8 | J14: 22.855 | K14: 124.9322 | L14: =+(J14-I14)/I14 -> -0.20642361 | M14: =F14/J14 -> 1482355.7
A15: =_xlfn.XLOOKUP(C15,'Sectors & Company Names'!$B$2:$B$2814,'Sectors & Company Names'!$C$2:$C$2814) -> Business Equipment | B15: =_xlfn.XLOOKUP(C15,'Sectors & Company Names'!$B$2:$B$2814,'Sectors & Company Names'!$A$2:$A$2814) -> ACCO BRANDS CORP | C15: ACCO | D15: 0.002372876 | E15: =+$J$3*D15 -> 23182422 | F15: =(L15+1)*E15 -> 7039446.3 | G15: =F15-E15 -> -16142975 | H15: =((F15/E15)^(1/7))-1 -> -0.1565599 | I15: 15.05 | J15: 4.57 | K15: 0 | L15: =+(J15-I15)/I15 -> -0.69634551 | M15: =F15/J15 -> 1540360.2
A16: =_xlfn.XLOOKUP(C16,'Sectors & Company Names'!$B$2:$B$2814,'Sectors & Company Names'!$C$2:$C$2814) -> Medical Care | B16: =_xlfn.XLOOKUP(C16,'Sectors & Company Names'!$B$2:$B$2814,'Sectors & Company Names'!$A$2:$A$2814) -> ADDUS HOMECARE CORP | C16: ADUS | D16: 0.002275676 | E16: =+$J$3*D16 -> 22232801 | F16: =(L16+1)*E16 -> 1.0544254e+08 | G16: =F16-E16 -> 83209743 | H16: =((F16/E16)^(1/7))-1 -> 0.24903477 | I16: 22.81 | J16: 108.18 | K16: 25.0149 | L16: =+(J16-I16)/I16 -> 3.7426567 | M16: =F16/J16 -> 974695.36
A17: =_xlfn.XLOOKUP(C17,'Sectors & Company Names'!$B$2:$B$2814,'Sectors & Company Names'!$C$2:$C$2814) -> Auto Parts | B17: =_xlfn.XLOOKUP(C17,'Sectors & Company Names'!$B$2:$B$2814,'Sectors & Company Names'!$A$2:$A$2814) -> ADIENT PLC | C17: ADNT | D17: 0.002673116 | E17: =+$J$3*D17 -> 26115693 | F17: =(L17+1)*E17 -> 14080273 | G17: =F17-E17 -> -12035420 | H17: =((F17/E17)^(1/7))-1 -> -0.08446956 | I17: 31.29 | J17: 16.87 | K17: 0 | L17: =+(J17-I17)/I17 -> -0.46085011 | M17: =F17/J17 -> 834633.86
A18: =_xlfn.XLOOKUP(C18,'Sectors & Company Names'!$B$2:$B$2814,'Sectors & Company Names'!$C$2:$C$2814) -> Software - Application | B18: =_xlfn.XLOOKUP(C18,'Sectors & Company Names'!$B$2:$B$2814,'Sectors & Company Names'!$A$2:$A$2814) -> ADOBE SYSTEMS INC | C18: ADBE | D18: 0.003025196 | E18: =+$J$3*D18 -> 29555429 | F18: =(L18+1)*E18 -> 4.6567848e+08 | G18: =F18-E18 -> 4.3612305e+08 | H18: =((F18/E18)^(1/7))-1 -> 0.48273701 | I18: 28.25 | J18: 445.11 | K18: 35.8412 | L18: =+(J18-I18)/I18 -> 14.756106 | M18: =F18/J18 -> 1046209.9
A19: =_xlfn.XLOOKUP(C19,'Sectors & Company Names'!$B$2:$B$2814,'Sectors & Company Names'!$C$2:$C$2814) -> Semiconductors | B19: =_xlfn.XLOOKUP(C19,'Sectors & Company Names'!$B$2:$B$2814,'Sectors & Company Names'!$A$2:$A$2814) -> ADVANCED MICRO DEVICES | C19: AMD | D19: 0.001739996 | E19: =+$J$3*D19 -> 16999338 | F19: =(L19+1)*E19 -> 17311.914 | G19: =F19-E19 -> -16982026 | H19: =((F19/E19)^(1/7))-1 -> -0.6262691 | I19: 35.35 | J19: 0.036 | K19: 0 | L19: =+(J19-I19)/I19 -> -0.99898161 | M19: =F19/J19 -> 480886.5
A20: =_xlfn.XLOOKUP(C20,'Sectors & Company Names'!$B$2:$B$2814,'Sectors & Company Names'!$C$2:$C$2814) -> Engineering & Construction | B20: =_xlfn.XLOOKUP(C20,'Sectors & Company Names'!$B$2:$B$2814,'Sectors & Company Names'!$A$2:$A$2814) -> AECOM | C20: ACM | D20: 0.003114836 | E20: =+$J$3*D20 -> 30431190 | F20: =(L20+1)*E20 -> 38562855 | G20: =F20-E20 -> 8131664.4 | H20: =((F20/E20)^(1/7))-1 -> 0.03441043 | I20: 77.84 | J20: 98.64 | K20: 22.4609 | L20: =+(J20-I20)/I20 -> 0.2672148 | M20: =F20/J20 -> 390945.41
... A307: =_xlfn.XLOOKUP(C307,'Sectors & Company Names'!$B$2:$B$2814,'Sectors & Company Names'!$C$2:$C$2814) -> Specialty Chemicals | B307: =_xlfn.XLOOKUP(C307,'Sectors & Company Names'!$B$2:$B$2814,'Sectors & Company Names'!$A$2:$A$2814) -> THE CHEMOURS COMPANY CC | C307: CC | D307: 0.004123556 | E307: =+$J$3*D307 -> 40286139 | F307: =(L307+1)*E307 -> 20712923 | G307: =F307-E307 -> -19573217 | H307: =((F307/E307)^(1/7))-1 -> -0.090659501 | I307: 32.52 | J307: 16.72 | K307: 28.3025 | L307: =+(J307-I307)/I307 -> -0.48585486 | M307: =F307/J307 -> 1238811.2
E308: =SUM(E9:E307) -> 9.3966044e+09

Sheet Sectors & Company Names
A1: Company | B1: Ticker | C1: Sector
A2: AGILENT TECHNOLOGIES INC | B2: A | C2: Diagnostics & Research
A3: ALCOA CORPORATION | B3: AA | C3: Aluminum
A4: AAC HOLDINGS INC | B4: AAC | C4: Medical Care
A5: AMERICAN AIRLINES GROUP | B5: AAL | C5: Airlines
A6: AARONS INC | B6: AAN | C6: Rental & Leasing Services
A7: APPLIED OPTOELECTRONICS | B7: AAOI | C7: Semiconductors
A8: AAON INC | B8: AAON | C8: Building Materials
A9: ADVANCE AUTO PARTS INC | B9: AAP | C9: Specialty Retail
A10: APPLE INC | B10: AAPL | C10: Consumer Electronics
A11: AMERICAN ASSETS TRST INC | B11: AAT | C11: REIT - Retail
A12: ATLAS AIR WORLDWIDE HLDG | B12: AAWW | C12: Airports & Air Services
... A109: AK STEEL HOLDING CORP | B109: AKS | C109: Steel
A110: =CONCATENATE(B110, C110," FIRM") -> AKTSWaste Management FIRM | B110: AKTS | C110: Waste Management
A111: AIR LEASE CORP | B111: AL | C111: Rental & Leasing Services
A112: ALBEMARLE CORP | B112: ALB | C112: Specialty Chemicals
A113: ALICO INC | B113: ALCO | C113: Farm Products
A114: ALDER BIOPHARMACEUTICALS | B114: ALDR | C114: Biotechnology
A115: ALLETE INC | B115: ALE | C115: Utilities - Regulated Electric
A116: ALEXANDER & BALDWIN INC | B116: ALEX | C116: Real Estate - General
A117: ALAMO GROUP INC | B117: ALG | C117: Farm & Construction Equipment
A118: ALIGN TECHNOLOGY INC | B118: ALGN | C118: Medical Devices
A119: ALLEGIANT TRAVEL CO | B119: ALGT | C119: Airlines
A120: ALON USA ENERGY INC | B120: ALJ | C120: Oil & Gas Refining & Marketing
A121: ALASKA AIR GROUP INC | B121: ALK | C121: Airlines
A122: ALKERMES PLC | B122: ALKS | C122: Biotechnology
... A195: ARCBEST CORPORATION | B195: ARCB | C195: Trucking
A196: =CONCATENATE(B196, C196," FIRM") -> ARCHWaste Management FIRM | B196: ARCH | C196: Waste Management
A197: ARDELYX INC | B197: ARDX | C197: Biotechnology
A198: ALEXANDRIA REAL ESTATE | B198: ARE | C198: REIT - Office
A199: APOLLO COMMERCIAL RE | B199: ARI | C199: REIT - Diversified
A200: AMERICAN RAILCAR IND | B200: ARII | C200: Railroads
A201: ARAMARK | B201: ARMK | C201: Restaurants
A202: ARENA PHARMACEUTICALS | B202: ARNA | C202: Biotechnology
A203: ARCONIC INC | B203: ARNC | C203: Diversified Industrials
A204: ARCHROCK INC | B204: AROC | C204: Oil & Gas Equipment & Services
A205: ARROW FINANCIAL CORP | B205: AROW | C205: Banks - Regional - US
A206: ARMOUR RESIDENTIAL REIT | B206: ARR | C206: REIT - Residential
A207: ARRIS INTERNATIONAL PLC | B207: ARRS | C207: Communication Equipment
A208: ARRAY BIOPHARMA INC | B208: ARRY | C208: Biotechnology
...

Sheet RUA
A1: Date | B1: Open | C1: High | D1: Low | E1: Close | F1: Adj Close
A2: 45712 | B2: 3432.13 | C2: 3439.4 | D2: 3401.13 | E2: 3421.46 | F2: 3421.46
A3: 45709 | B3: 3492.06 | C3: 3493.89 | D3: 3421.57 | E3: 3424.46 | F3: 3424.46
A4: 45708 | B4: 3505.45 | C4: 3505.45 | D4: 3471.91 | E4: 3490.34 | F4: 3490.34
A5: 45707 | B5: 3497.41 | C5: 3511.9 | D5: 3492.34 | E5: 3509.12 | F5: 3509.12
A6: 45706 | B6: 3499.44 | C6: 3505.03 | D6: 3487.84 | E6: 3505.01 | F6: 3505.01
A7: 45702 | B7: 3498.95 | C7: 3503.65 | D7: 3491.41 | E7: 3495.72 | F7: 3495.72
A8: 45701 | B8: 3466.32 | C8: 3496.93 | D8: 3461.31 | E8: 3496.04 | F8: 3496.04
A9: 45700 | B9: 3444.83 | C9: 3465.96 | D9: 3434.01 | E9: 3459.47 | F9: 3459.47
A10: 45699 | B10: 3460.92 | C10: 3474.25 | D10: 3458.85 | E10: 3470.55 | F10: 3470.55
A11: 45698 | B11: 3462.11 | C11: 3477.52 | D11: 3462.11 | E11: 3473.2 | F11: 3473.2
A12: 45695 | B12: 3485.95 | C12: 3494.28 | D12: 3448.32 | E12: 3451.45 | F12: 3451.45
A13: 45694 | B13: 3482.73 | C13: 3484.63 | D13: 3463.69 | E13: 3484.41 | F13: 3484.41
... A251: 45348 | B251: 2914.85 | C251: 2917.7 | D251: 2904.43 | E251: 2904.9 | F251: 2904.9
A252: 43157 | B252: 1470.37 | C252: 1599.12 | D252: 1436.81 | E252: 1583.54
