Workbook
Name Slicer_Company1: #N/A
Name Slicer_Company3: #N/A
Name Slicer_Year: #N/A

Sheet Exe Sum & Dashboard
M3: DASHBOARD AREA

Sheet Memo

Sheet Capital Requirements
A1: Gaming Software Investment Options - Capital Budget
A2: Initial Investment | B2: Family Games Software Company | C2: RPG Games Software Company | D2: Craft Games Software Company | E2: Action Games Software Company | F2: Starting a New Game Software Company
A3: Purchase Price (or Set up Cost) | B3: 50000000 | C3: 65000000 | D3: 85000000 | E3: 1.0166667e+08 | F3: 15000000
A4: Integration and Administration Costs | B4: 2000000 | C4: 3000000 | D4: 4000000 | E4: 5000000 | F4: 4000000
A5: Miscellaneous Expenses | B5: 200000 | C5: 220000 | D5: 242000 | E5: 262666.67 | F5: 242000
A6: Opening Inventory | B6: 1250000 | C6: 1375000 | D6: 1512500 | E6: 1641666.7 | F6: 600000
A7: Training Expenses (including travel and lodging) | B7: 1500000 | C7: 1650000 | D7: 1815000 | E7: 1970000 | F7: 750000
A8: Legal and Accounting | B8: 500000 | C8: 550000 | D8: 605000 | E8: 656666.67 | F8: 605000
A9: Total Initial Investment | B9: =SUM(B3:B8) -> 55450000 | C9: =SUM(C3:C8) -> 71795000 | D9: =SUM(D3:D8) -> 93174500 | E9: =SUM(E3:E8) -> 1.1119767e+08 | F9: =SUM(F3:F8) -> 21197000
A12: Annual Operating Fixed Costs | B12: Family Games Software Company | C12: RPG Games Software Company | D12: Craft Games Software Company | E12: Action Games Software Company | F12: Starting a New Game Software Company
A13: Building Maintenance & Cleaning | B13: 350000 | C13: 392000 | D13: 439040 | E13: 482720 | F13: 350000
A14: Electric | B14: 15000 | C14: 16800 | D14: 18816 | E14: 20688 | F14: 15000
A15: Gas | B15: 3000 | C15: 3360 | D15: 3763.2 | E15: 4137.6 | F15: 3000
A16: Garbage | B16: 1750 | C16: 1960 | D16: 2195.2 | E16: 2413.6 | F16: 1750
A17: Insurance | B17: 20000 | C17: 22400 | D17: 25088 | E17: 27584 | F17: 20000
A18: Telephone | B18: 2500 | C18: 2800 | D18: 3136 | E18: 3448 | F18: 2500
A19: Labor Costs For Employees | B19: 15000000 | C19: 18000000 | D19: 21000000 | E19: 24000000 | F19: 11000000
A20: Total Fixed Costs | B20: =SUM(B13:B19) -> 15392250 | C20: =SUM(C13:C19) -> 18439320 | D20: =SUM(D13:D19) -> 21492038 | E20: =SUM(E13:E19) -> 24540991 | F20: =SUM(F13:F19) -> 11392250
A23: Depreciation Per Year | B23: 5000000 | C23: 7000000 | D23: 10000000 | E23: 12333333 | F23: 2000000
A25: Sales Revenue Forecast in Dollars | B25: Family Games Software Company | C25: RPG Games Software Company | D25: Craft Games Software Company | E25: Action Games Software Company | F25: Starting a New Game Software Company
A26: Year 1 | B26: 40000000 | C26: 54000000 | D26: 68000000 | E26: 82000000 | F26: 1850000
A27: Year 2 | B27: 48110000 | C27: 64948500 | D27: 81787000 | E27: 98625500 | F27: 4912500
A28: Year 3 | B28: 49253300 | C28: 66491955 | D28: 83730610 | E28: 100969265 | F28: 8303125
A29: Year 4 | B29: 50430899 | C29: 68081714 | D29: 85732528 | E29: 1.0338334e+08 | F29: 29682031
A30: Year 5 | B30: 51643826 | C30: 69719165 | D30: 87794504 | E30: 1.0586984e+08 | F30: 41784570
A31: Year 6 | B31: 52893141 | C31: 71405740 | D31: 89918339 | E31: 1.0843094e+08 | F31: 69015283
A32: Year 7 | B32: 54179935 | C32: 73142912 | D32: 92105889 | E32: 1.1106887e+08 | F32: 93522925
A33: Year 8 | B33: 58252361 | C33: 78640687 | D33: 99029014 | E33: 1.1941734e+08 | F33: 1.0822751e+08
A35: COST OF GOOD SOLD | B35: 10% of Sales | C35: 12% of Sales | D35: 11% of Sales | E35: 9% of Sales | F35: 5% of Sales
A37: Company Tax Rate | B37: 0.21
A38: Base Interest Rate | B38: 0.0725
A40: Risk Factor Rate Premium | D40: Total Discount Rate
A41: Family Games Software Company | B41: Not Risky | C41: 0.01 | D41: =+$B$38+C41 -> 0.0825
A42: RPG Games Software Company | B42: A little Risky | C42: 0.0125 | D42: =+$B$38+C42 -> 0.085
A43: Craft Games Software Company | B43: More Risky | C43: 0.015 | D43: =+$B$38+C43 -> 0.0875
A44: Action Games Software Company | B44: Even more risky | C44: 0.0175 | D44: =+$B$38+C44 -> 0.09
A45: Starting a New Game Software Company | B45: The most risky | C45: 0.02 | D45: =+$B$38+C45 -> 0.0925

Sheet Family
A1: Family Games
A3: Projected Net Cash | E3: Years
A4: Flows (Time line of annual cash flows) | E4: 0 | F4: 1 | G4: 2 | H4: 3 | I4: 4 | J4: 5 | K4: 6 | L4: 7 | M4: 8
A5: Investment Outlays at Time Zero
A6: Initial Investment (opportunity cost) | E6: =-'Capital Requirements'!B9 -> -55450000
A7: Operating Cash Flows over the Project's Life
A8: Sales revenue | F8: 40000000 | G8: 48110000 | H8: 49253300 | I8: 50430899 | J8: 51643826 | K8: 52893141 | L8: 54179935 | M8: 58252361
A9: Cost of Good Sold | F9: =F8*0.1 -> 4000000 | G9: =G8*0.1 -> 4811000 | H9: =H8*0.1 -> 4925330 | I9: =I8*0.1 -> 5043089.9 | J9: =J8*0.1 -> 5164382.6 | K9: =K8*0.1 -> 5289314.1 | L9: =L8*0.1 -> 5417993.5 | M9: =M8*0.1 -> 5825236.1
A10: Gross Profits | F10: =F8-F9 -> 36000000 | G10: =G8-G9 -> 43299000 | H10: =H8-H9 -> 44327970 | I10: =I8-I9 -> 45387809 | J10: =J8-J9 -> 46479443 | K10: =K8-K9 -> 47603827 | L10: =L8-L9 -> 48761941 | M10: =M8-M9 -> 52427125
A11: Fixed operating costs | F11: ='Capital Requirements'!$B$20 -> 15392250 | G11: ='Capital Requirements'!$B$20 -> 15392250 | H11: ='Capital Requirements'!$B$20 -> 15392250 | I11: ='Capital Requirements'!$B$20 -> 15392250 | J11: ='Capital Requirements'!$B$20 -> 15392250 | K11: ='Capital Requirements'!$B$20 -> 15392250 | L11: ='Capital Requirements'!$B$20 -> 15392250 | M11: ='Capital Requirements'!$B$20 -> 15392250
A12: Depreciation | F12: ='Capital Requirements'!$B$23 -> 5000000 | G12: ='Capital Requirements'!$B$23 -> 5000000 | H12: ='Capital Requirements'!$B$23 -> 5000000 | I12: ='Capital Requirements'!$B$23 -> 5000000 | J12: ='Capital Requirements'!$B$23 -> 5000000 | K12: ='Capital Requirements'!$B$23 -> 5000000 | L12: ='Capital Requirements'!$B$23 -> 5000000 | M12: ='Capital Requirements'!$B$23 -> 5000000
A13: EBIT Operating Income Before Taxes | F13: =F10-F11-F12 -> 15607750 | G13: =G10-G11-G12 -> 22906750 | H13: =H10-H11-H12 -> 23935720 | I13: =I10-I11-I12 -> 24995559 | J13: =J10-J11-J12 -> 26087193 | K13: =K10-K11-K12 -> 27211577 | L13: =L10-L11-L12 -> 28369691 | M13: =M10-M11-M12 -> 32034875
A14: Taxes on Operating Income | F14: =F13*0.21 -> 3277627.5 | G14: =G13*0.21 -> 4810417.5 | H14: =H13*0.21 -> 5026501.2 | I14: =I13*0.21 -> 5249067.4 | J14: =J13*0.21 -> 5478310.6 | K14: =K13*0.21 -> 5714431.1 | L14: =L13*0.21 -> 5957635.2 | M14: =M13*0.21 -> 6727323.7
A15: Net Operating Profit After Taxes | F15: =F13-F14 -> 12330122 | G15: =G13-G14 -> 18096332 | H15: =H13-H14 -> 18909219 | I15: =I13-I14 -> 19746492 | J15: =J13-J14 -> 20608883 | K15: =K13-K14 -> 21497146 | L15: =L13-L14 -> 22412056 | M15: =M13-M14 -> 25307551
A16: Add back depreciation | F16: =F12 -> 5000000 | G16: =G12 -> 5000000 | H16: =H12 -> 5000000 | I16: =I12 -> 5000000 | J16: =J12 -> 5000000 | K16: =K12 -> 5000000 | L16: =L12 -> 5000000 | M16: =M12 -> 5000000
A17: Net Cash Flow | E17: =+E6 -> -55450000 | F17: =F15+F16 -> 17330122 | G17: =G15+G16 -> 23096332 | H17: =H15+H16 -> 23909219 | I17: =I15+I16 -> 24746492 | J17: =J15+J16 -> 25608883 | K17: =K15+K16 -> 26497146 | L17: =L15+L16 -> 27412056 | M17: =M15+M16 -> 30307551
A18: Cumulative Cash Flow | F18: =E17+F17 -> -38119878 | G18: =F18+G17 -> -15023545 | H18: =G18+H17 -> 8885673.8 | I18: =H18+I17 -> 33632165 | J18: =I18+J17 -> 59241048 | K18: =J18+K17 -> 85738194 | L18: =K18+L17 -> 1.1315025e+08 | M18: =L18+M17 -> 1.434578e+08
A20: Key Output and Appraisal of the Proposed Project
A22: NPV | D22: =NPV('Capital Requirements'!D41,F17:M17)+E17 -> 82648362
A23: IRR | D23: =IRR(E17:M17) -> 0.37457444
A24: Payback Period | D24: =2+(ABS(G18)/H17) -> 2.6283578
A26: DCF
A27: Year | B27: Cash Flow (CF) | C27: Discount Rate (r) | D27: Discounted Cash Flow (DCF)
A28: 0 | B28: =+E6 -> -55450000 | C28: =+'Capital Requirements'!$D$41 -> 0.0825 | D28: =B28/(1+C28)^A28 -> -55450000
A29: 1 | B29: 17330122 | C29: =+'Capital Requirements'!$D$41 -> 0.0825 | D29: =B29/(1+C29)^A29 -> 16009351
A30: 2 | B30: 23096332 | C30: =+'Capital Requirements'!$D$41 -> 0.0825 | D30: =B30/(1+C30)^A30 -> 19710027
A31: 3 | B31: 23909219 | C31: =+'Capital Requirements'!$D$41 -> 0.0825 | D31: =B31/(1+C31)^A31 -> 18848712
A32: 4 | B32: 24746492 | C32: =+'Capital Requirements'!$D$41 -> 0.0825 | D32: =B32/(1+C32)^A32 -> 18021960
A33: 5 | B33: 25608883 | C33: =+'Capital Requirements'!$D$41 -> 0.0825 | D33: =B33/(1+C33)^A33 -> 17228644
A34: 6 | B34: 26497146 | C34: =+'Capital Requirements'!$D$41 -> 0.0825 | D34: =B34/(1+C34)^A34 -> 16467651
A35: 7 | B35: 27412056 | C35: =+'Capital Requirements'!$D$41 -> 0.0825 | D35: =B35/(1+C35)^A35 -> 15737882
A36: 8 | B36: 30307551 | C36: =+'Capital Requirements'!$D$41 -> 0.0825 | D36: =B36/(1+C36)^A36 -> 16074135
A37: Total DCF | D37: =SUM(D28:D36) -> 82648362

Sheet RPG
A1: RPG Games
A3: Projected Net Cash | E3: Years
A4: Flows (Time line of annual cash flows) | E4: 0 | F4: 1 | G4: 2 | H4: 3 | I4: 4 | J4: 5 | K4: 6 | L4: 7 | M4: 8
A5: Investment Outlays at Time Zero
A6: Initial Investment (opportunity cost) | E6: =-'Capital Requirements'!C9 -> -71795000
A7: Operating Cash Flows over the Project's Life
A8: Sales revenue | F8: 54000000 | G8: 64948500 | H8: 66491955 | I8: 68081714 | J8: 69719165 | K8: 71405740 | L8: 73142912 | M8: 78640687
A9: Cost of Good Sold | F9: =F8*0.12 -> 6480000 | G9: =G8*0.12 -> 7793820 | H9: =H8*0.12 -> 7979034.6 | I9: =I8*0.12 -> 8169805.6 | J9: =J8*0.12 -> 8366299.8 | K9: =K8*0.12 -> 8568688.8 | L9: =L8*0.12 -> 8777149.5 | M9: =M8*0.12 -> 9436882.5
A10: Gross Profits | F10: =F8-F9 -> 47520000 | G10: =G8-G9 -> 57154680 | H10: =H8-H9 -> 58512920 | I10: =I8-I9 -> 59911908 | J10: =J8-J9 -> 61352865 | K10: =K8-K9 -> 62837051 | L10: =L8-L9 -> 64365763 | M10: =M8-M9 -> 69203805
A11: Fixed operating costs | F11: ='Capital Requirements'!$C$20 -> 18439320 | G11: ='Capital Requirements'!$C$20 -> 18439320 | H11: ='Capital Requirements'!$C$20 -> 18439320 | I11: ='Capital Requirements'!$C$20 -> 18439320 | J11: ='Capital Requirements'!$C$20 -> 18439320 | K11: ='Capital Requirements'!$C$20 -> 18439320 | L11: ='Capital Requirements'!$C$20 -> 18439320 | M11: ='Capital Requirements'!$C$20 -> 18439320
A12: Depreciation | F12: ='Capital Requirements'!$C$23 -> 7000000 | G12: ='Capital Requirements'!$C$23 -> 7000000 | H12: ='Capital Requirements'!$C$23 -> 7000000 | I12: ='Capital Requirements'!$C$23 -> 7000000 | J12: ='Capital Requirements'!$C$23 -> 7000000 | K12: ='Capital Requirements'!$C$23 -> 7000000 | L12: ='Capital Requirements'!$C$23 -> 7000000 | M12: ='Capital Requirements'!$C$23 -> 7000000
A13: EBIT Operating Income Before Taxes | F13: =F10-F11-F12 -> 22080680 | G13: =G10-G11-G12 -> 31715360 | H13: =H10-H11-H12 -> 33073600 | I13: =I10-I11-I12 -> 34472588 | J13: =J10-J11-J12 -> 35913545 | K13: =K10-K11-K12 -> 37397731 | L13: =L10-L11-L12 -> 38926443 | M13: =M10-M11-M12 -> 43764485
A14: Taxes on Operating Income | F14: =F13*0.21 -> 4636942.8 | G14: =G13*0.21 -> 6660225.6 | H14: =H13*0.21 -> 6945456.1 | I14: =I13*0.21 -> 7239243.5 | J14: =J13*0.21 -> 7541844.5 | K14: =K13*0.21 -> 7853523.6 | L14: =L13*0.21 -> 8174553 | M14: =M13*0.21 -> 9190541.8
A15: Net Operating Profit After Taxes | F15: =F13-F14 -> 17443737 | G15: =G13-G14 -> 25055134 | H15: =H13-H14 -> 26128144 | I15: =I13-I14 -> 27233345 | J15: =J13-J14 -> 28371701 | K15: =K13-K14 -> 29544208 | L15: =L13-L14 -> 30751890 | M15: =M13-M14 -> 34573943
A16: Add back depreciation | F16: ='Capital Requirements'!$C$23 -> 7000000 | G16: ='Capital Requirements'!$C$23 -> 7000000 | H16: ='Capital Requirements'!$C$23 -> 7000000 | I16: ='Capital Requirements'!$C$23 -> 7000000 | J16: ='Capital Requirements'!$C$23 -> 7000000 | K16: ='Capital Requirements'!$C$23 -> 7000000 | L16: ='Capital Requirements'!$C$23 -> 7000000 | M16: ='Capital Requirements'!$C$23 -> 7000000
A17: Net Cash Flow | E17: =E6 -> -71795000 | F17: =F15+F16 -> 24443737 | G17: =G15+G16 -> 32055134 | H17: =H15+H16 -> 33128144 | I17: =I15+I16 -> 34233345 | J17: =J15+J16 -> 35371701 | K17: =K15+K16 -> 36544208 | L17: =L15+L16 -> 37751890 | M17: =M15+M16 -> 41573943
A18: Cumulative Cash Flow | F18: =E17+F17 -> -47351263 | G18: =F18+G17 -> -15296128 | H18: =G18+H17 -> 17832016 | I18: =H18+I17 -> 52065360 | J18: =I18+J17 -> 87437061 | K18: =J18+K17 -> 1.2398127e+08 | L18: =K18+L17 -> 1.6173316e+08 | M18: =L18+M17 -> 2.033071e+08
A20: Key Output and Appraisal of the Proposed Project
A22: NPV | D22: =NPV('Capital Requirements'!D42,F17:M17)+E17 -> 1.1749809e+08
A23: IRR | D23: =IRR(E17:M17) -> 0.40507981
A24: Payback Period | D24: =2+(ABS(G18)/H17) -> 2.4617261
A26: DCF
A27: Year | B27: Cash Flow (CF) | C27: Discount Rate (r) | D27: Discounted Cash Flow (DCF)
A28: 0 | B28: =E6 -> -71795000 | C28: ='Capital Requirements'!$D$42 -> 0.085 | D28: =B28/(1+C28)^A28 -> -71795000
A29: 1 | B29: 24443737 | C29: ='Capital Requirements'!$D$42 -> 0.085 | D29: =B29/(1+C29)^A29 -> 22528790
A30: 2 | B30: 32055134 | C30: ='Capital Requirements'!$D$42 -> 0.085 | D30: =B30/(1+C30)^A30 -> 27229403
A31: 3 | B31: 33128144 | C31: ='Capital Requirements'!$D$42 -> 0.085 | D31: =B31/(1+C31)^A31 -> 25936292
A32: 4 | B32: 34233345 | C32: ='Capital Requirements'!$D$42 -> 0.085 | D32: =B32/(1+C32)^A32 -> 24701901
A33: 5 | B33: 35371701 | C33: ='Capital Requirements'!$D$42 -> 0.085 | D33: =B33/(1+C33)^A33 -> 23523788
A34: 6 | B34: 36544208 | C34: ='Capital Requirements'!$D$42 -> 0.085 | D34: =B34/(1+C34)^A34 -> 22399593
A35: 7 | B35: 37751890 | C35: ='Capital Requirements'!$D$42 -> 0.085 | D35: =B35/(1+C35)^A35 -> 21327037
A36: 8 | B36: 41573943 | C36: ='Capital Requirements'!$D$42 -> 0.085 | D36: =B36/(1+C36)^A36 -> 21646282
A37: Total DCF | D37: =SUM(D28:D36) -> 1.1749809e+08

Sheet Craft
A1: Craft Games
A3: Projected Net Cash | E3: Years
A4: Flows (Time line of annual cash flows) | E4: 0 | F4: 1 | G4: 2 | H4: 3 | I4: 4 | J4: 5 | K4: 6 | L4: 7 | M4: 8
A5: Investment Outlays at Time Zero
A6: Initial Investment (opportunity cost) | E6: =-'Capital Requirements'!D9 -> -93174500
A7: Operating Cash Flows over the Project's Life
A8: Sales revenue | F8: 68000000 | G8: 81787000 | H8: 83730610 | I8: 85732528 | J8: 87794504 | K8: 89918339 | L8: 92105889 | M8: 99029014
A9: Cost of Good Sold | F9: =F8*0.11 -> 7480000 | G9: =G8*0.11 -> 8996570 | H9: =H8*0.11 -> 9210367.1 | I9: =I8*0.11 -> 9430578.1 | J9: =J8*0.11 -> 9657395.5 | K9: =K8*0.11 -> 9891017.3 | L9: =L8*0.11 -> 10131648 | M9: =M8*0.11 -> 10893192
A10: Gross Profits | F10: =F8-F9 -> 60520000 | G10: =G8-G9 -> 72790430 | H10: =H8-H9 -> 74520243 | I10: =I8-I9 -> 76301950 | J10: =J8-J9 -> 78137109 | K10: =K8-K9 -> 80027322 | L10: =L8-L9 -> 81974242 | M10: =M8-M9 -> 88135822
A11: Fixed operating costs | F11: ='Capital Requirements'!$D$20 -> 21492038 | G11: ='Capital Requirements'!$D$20 -> 21492038 | H11: ='Capital Requirements'!$D$20 -> 21492038 | I11: ='Capital Requirements'!$D$20 -> 21492038 | J11: ='Capital Requirements'!$D$20 -> 21492038 | K11: ='Capital Requirements'!$D$20 -> 21492038 | L11: ='Capital Requirements'!$D$20 -> 21492038 | M11: ='Capital Requirements'!$D$20 -> 21492038
A12: Depreciation | F12: ='Capital Requirements'!$D$23 -> 10000000 | G12: ='Capital Requirements'!$D$23 -> 10000000 | H12: ='Capital Requirements'!$D$23 -> 10000000 | I12: ='Capital Requirements'!$D$23 -> 10000000 | J12: ='Capital Requirements'!$D$23 -> 10000000 | K12: ='Capital Requirements'!$D$23 -> 10000000 | L12: ='Capital Requirements'!$D$23 -> 10000000 | M12: ='Capital Requirements'!$D$23 -> 10000000
A13: EBIT Operating Income Before Taxes | F13: =F10-F11-F12 -> 29027962 | G13: =G10-G11-G12 -> 41298392 | H13: =H10-H11-H12 -> 43028205 | I13: =I10-I11-I12 -> 44809912 | J13: =J10-J11-J12 -> 46645070 | K13: =K10-K11-K12 -> 48535284 | L13: =L10-L11-L12 -> 50482203 | M13: =M10-M11-M12 -> 56643784
A14: Taxes on Operating Income | F14: =F13*0.21 -> 6095871.9 | G14: =G13*0.21 -> 8672662.2 | H14: =H13*0.21 -> 9035922.9 | I14: =I13*0.21 -> 9410081.5 | J14: =J13*0.21 -> 9795464.8 | K14: =K13*0.21 -> 10192410 | L14: =L13*0.21 -> 10601263 | M14: =M13*0.21 -> 11895195
A15: Net Operating Profit After Taxes | F15: =F13-F14 -> 22932090 | G15: =G13-G14 -> 32625729 | H15: =H13-H14 -> 33992282 | I15: =I13-I14 -> 35399830 | J15: =J13-J14 -> 36849606 | K15: =K13-K14 -> 38342874 | L15: =L13-L14 -> 39880941 | M15: =M13-M14 -> 44748589
A16: Add back depreciation | F16: =F12 -> 10000000 | G16: =G12 -> 10000000 | H16: =H12 -> 10000000 | I16: =I12 -> 10000000 | J16: =J12 -> 10000000 | K16: =K12 -> 10000000 | L16: =L12 -> 10000000 | M16: =M12 -> 10000000
A17: Net Cash Flow | E17: =E6 -> -93174500 | F17: =F15+F16 -> 32932090 | G17: =G15+G16 -> 42625729 | H17: =H15+H16 -> 43992282 | I17: =I15+I16 -> 45399830 | J17: =J15+J16 -> 46849606 | K17: =K15+K16 -> 48342874 | L17: =L15+L16 -> 49880941 | M17: =M15+M16 -> 54748589
A18: Cumulative Cash Flow | F18: =E17+F17 -> -60242410 | G18: =F18+G17 -> -17616681 | H18: =G18+H17 -> 26375601 | I18: =H18+I17 -> 71775431 | J18: =I18+J17 -> 1.1862504e+08 | K18: =J18+K17 -> 1.6696791e+08 | L18: =K18+L17 -> 2.1684885e+08 | M18: =L18+M17 -> 2.7159744e+08
A20: Key Output and Appraisal of the Proposed Project
A22: NPV | D22: =NPV('Capital Requirements'!D43,F17:M17)+E17 -> 1.555547e+08
A23: IRR | D23: =IRR(E17:M17) -> 0.41655263
A24: Payback Period | D24: =2+(ABS(G18)/H17) -> 2.4004494
A26: DCF
A27: Year | B27: Cash Flow (CF) | C27: Discount Rate (r) | D27: Discounted Cash Flow (DCF)
A28: 0 | B28: =E6 -> -93174500 | C28: ='Capital Requirements'!$D$43 -> 0.0875 | D28: =B28/(1+C28)^A28 -> -93174500
A29: 1 | B29: 32932090 | C29: ='Capital Requirements'!$D$43 -> 0.0875 | D29: =B29/(1+C29)^A29 -> 30282381
A30: 2 | B30: 42625729 | C30: ='Capital Requirements'!$D$43 -> 0.0875 | D30: =B30/(1+C30)^A30 -> 36042366
A31: 3 | B31: 43992282 | C31: ='Capital Requirements'!$D$43 -> 0.0875 | D31: =B31/(1+C31)^A31 -> 34204929
A32: 4 | B32: 45399830 | C32: ='Capital Requirements'!$D$43 -> 0.0875 | D32: =B32/(1+C32)^A32 -> 32459152
A33: 5 | B33: 46849606 | C33: ='Capital Requirements'!$D$43 -> 0.0875 | D33: =B33/(1+C33)^A33 -> 30800631
A34: 6 | B34: 48342874 | C34: ='Capital Requirements'!$D$43 -> 0.0875 | D34: =B34/(1+C34)^A34 -> 29225158
A35: 7 | B35: 49880941 | C35: ='Capital Requirements'!$D$43 -> 0.0875 | D35: =B35/(1+C35)^A35 -> 27728717
A36: 8 | B36: 54748589 | C36: ='Capital Requirements'!$D$43 -> 0.0875 | D36: =B36/(1+C36)^A36 -> 27985870
A37: Total DCF | D37: =SUM(D28:D36) -> 1.555547e+08

Sheet Action
A1: Action Games
A3: Projected Net Cash | E3: Years
A4: Flows (Time line of annual cash flows) | E4: 0 | F4: 1 | G4: 2 | H4: 3 | I4: 4 | J4: 5 | K4: 6 | L4: 7 | M4: 8
A5: Investment Outlays at Time Zero
A6: Initial Investment (opportunity cost) | E6: =-'Capital Requirements'!E9 -> -1.1119767e+08
A7: Operating Cash Flows over the Project's Life
A8: Sales revenue | F8: 82000000 | G8: 98625500 | H8: 100969265 | I8: 1.0338334e+08 | J8: 1.0586984e+08 | K8: 1.0843094e+08 | L8: 1.1106887e+08 | M8: 1.1941734e+08
A9: Cost of Good Sold | F9: =F8*0.09 -> 7380000 | G9: =G8*0.09 -> 8876295 | H9: =H8*0.09 -> 9087233.8 | I9: =I8*0.09 -> 9304500.9 | J9: =J8*0.09 -> 9528285.9 | K9: =K8*0.09 -> 9758784.5 | L9: =L8*0.09 -> 9996198 | M9: =M8*0.09 -> 10747561
A10: Gross Profits | F10: =F8-F9 -> 74620000 | G10: =G8-G9 -> 89749205 | H10: =H8-H9 -> 91882031 | I10: =I8-I9 -> 94078842 | J10: =J8-J9 -> 96341557 | K10: =K8-K9 -> 98672154 | L10: =L8-L9 -> 1.0107267e+08 | M10: =M8-M9 -> 1.0866978e+08
A11: Fixed operating costs | F11: ='Capital Requirements'!$E$20 -> 24540991 | G11: ='Capital Requirements'!$E$20 -> 24540991 | H11: ='Capital Requirements'!$E$20 -> 24540991 | I11: ='Capital Requirements'!$E$20 -> 24540991 | J11: ='Capital Requirements'!$E$20 -> 24540991 | K11: ='Capital Requirements'!$E$20 -> 24540991 | L11: ='Capital Requirements'!$E$20 -> 24540991 | M11: ='Capital Requirements'!$E$20 -> 24540991
A12: Depreciation | F12: ='Capital Requirements'!$E$23 -> 12333333 | G12: ='Capital Requirements'!$E$23 -> 12333333 | H12: ='Capital Requirements'!$E$23 -> 12333333 | I12: ='Capital Requirements'!$E$23 -> 12333333 | J12: ='Capital Requirements'!$E$23 -> 12333333 | K12: ='Capital Requirements'!$E$23 -> 12333333 | L12: ='Capital Requirements'!$E$23 -> 12333333 | M12: ='Capital Requirements'!$E$23 -> 12333333
A13: EBIT Operating Income Before Taxes | F13: =F10-F11-F12 -> 37745675 | G13: =G10-G11-G12 -> 52874880 | H13: =H10-H11-H12 -> 55007707 | I13: =I10-I11-I12 -> 57204518 | J13: =J10-J11-J12 -> 59467233 | K13: =K10-K11-K12 -> 61797830 | L13: =L10-L11-L12 -> 64198344 | M13: =M10-M11-M12 -> 71795455
A14: Taxes on Operating Income | F14: =F13*0.21 -> 7926591.8 | G14: =G13*0.21 -> 11103725 | H14: =H13*0.21 -> 11551618 | I14: =I13*0.21 -> 12012949 | J14: =J13*0.21 -> 12488119 | K14: =K13*0.21 -> 12977544 | L14: =L13*0.21 -> 13481652 | M14: =M13*0.21 -> 15077046
A15: Net Operating Profit After Taxes | F15: =F13-F14 -> 29819084 | G15: =G13-G14 -> 41771156 | H15: =H13-H14 -> 43456088 | I15: =I13-I14 -> 45191569 | J15: =J13-J14 -> 46979114 | K15: =K13-K14 -> 48820285 | L15: =L13-L14 -> 50716692 | M15: =M13-M14 -> 56718409
A16: Add back depreciation | F16: =F12 -> 12333333 | G16: =G12 -> 12333333 | H16: =H12 -> 12333333 | I16: =I12 -> 12333333 | J16: =J12 -> 12333333 | K16: =K12 -> 12333333 | L16: =L12 -> 12333333 | M16: =M12 -> 12333333
A17: Net Cash Flow | E17: =E6 -> -1.1119767e+08 | F17: =F15+F16 -> 42152417 | G17: =G15+G16 -> 54104489 | H17: =H15+H16 -> 55789422 | I17: =I15+I16 -> 57524902 | J17: =J15+J16 -> 59312447 | K17: =K15+K16 -> 61153619 | L17: =L15+L16 -> 63050025 | M17: =M15+M16 -> 69051743
A18: Cumulative Cash Flow | F18: =E17+F17 -> -69045250 | G18: =F18+G17 -> -14940761 | H18: =G18+H17 -> 40848661 | I18: =H18+I17 -> 98373563 | J18: =I18+J17 -> 1.5768601e+08 | K18: =J18+K17 -> 2.1883963e+08 | L18: =K18+L17 -> 2.8188965e+08 | M18: =L18+M17 -> 3.509414e+08
A20: Key Output and Appraisal of the Proposed Project
A22: NPV | D22: =NPV('Capital Requirements'!$D$44,F17:M17)+E17 -> 2.0100289e+08
A23: IRR | D23: =IRR(E17:M17) -> 0.44554643
A24: Payback Period | D24: =2+(ABS(G18)/H17) -> 2.2678063
A26: DCF
A27: Year | B27: Cash Flow (CF) | C27: Discount Rate (r) | D27: Discounted Cash Flow (DCF)
A28: 0 | B28: =E17 -> -1.1119767e+08 | C28: ='Capital Requirements'!$D$44 -> 0.09 | D28: =B28/(1+C28)^A28 -> -1.1119767e+08
A29: 1 | B29: 42152417 | C29: ='Capital Requirements'!$D$44 -> 0.09 | D29: =B29/(1+C29)^A29 -> 38671942
A30: 2 | B30: 54104489 | C30: ='Capital Requirements'!$D$44 -> 0.09 | D30: =B30/(1+C30)^A30 -> 45538666
A31: 3 | B31: 55789422 | C31: ='Capital Requirements'!$D$44 -> 0.09 | D31: =B31/(1+C31)^A31 -> 43079670
A32: 4 | B32: 57524902 | C32: ='Capital Requirements'!$D$44 -> 0.09 | D32: =B32/(1+C32)^A32 -> 40752091
A33: 5 | B33: 59312447 | C33: ='Capital Requirements'!$D$44 -> 0.09 | D33: =B33/(1+C33)^A33 -> 38549021
A34: 6 | B34: 61153619 | C34: ='Capital Requirements'!$D$44 -> 0.09 | D34: =B34/(1+C34)^A34 -> 36463905
A35: 7 | B35: 63050025 | C35: ='Capital Requirements'!$D$44 -> 0.09 | D35: =B35/(1+C35)^A35 -> 34490523
A36: 8 | B36: 69051743 | C36: ='Capital Requirements'!$D$44 -> 0.09 | D36: =B36/(1+C36)^A36 -> 34654741
A37: Total DCF | D37: =SUM(D28:D36) -> 2.0100289e+08

Sheet Starting New
A1: Starting A New Company From Scratch DCF
A3: Projected Net Cash | E3: Years
A4: Flows (Time line of annual cash flows) | E4: 0 | F4: 1 | G4: 2 | H4: 3 | I4: 4 | J4: 5 | K4: 6 | L4: 7 | M4: 8
A5: Investment Outlays at Time Zero
A6: Initial Investment (opportunity cost) | E6: =-'Capital Requirements'!F9 -> -21197000
A7: Operating Cash Flows over the Project's Life
A8: Sales revenue | F8: 1850000 | G8: 4912500 | H8: 8303125 | I8: 29682031 | J8: 41784570 | K8: 69015283 | L8: 93522925 | M8: 1.0822751e+08
A9: Cost of Good Sold | F9: =F8*0.05 -> 92500 | G9: =G8*0.05 -> 245625 | H9: =H8*0.05 -> 415156.25 | I9: =I8*0.05 -> 1484101.6 | J9: =J8*0.05 -> 2089228.5 | K9: =K8*0.05 -> 3450764.2 | L9: =L8*0.05 -> 4676146.2 | M9: =M8*0.05 -> 5411375.5
A10: Gross Profits | F10: =F8-F9 -> 1757500 | G10: =G8-G9 -> 4666875 | H10: =H8-H9 -> 7887968.8 | I10: =I8-I9 -> 28197930 | J10: =J8-J9 -> 39695342 | K10: =K8-K9 -> 65564519 | L10: =L8-L9 -> 88846779 | M10: =M8-M9 -> 1.0281613e+08
A11: Fixed operating costs | F11: ='Capital Requirements'!$F$20 -> 11392250 | G11: ='Capital Requirements'!$F$20 -> 11392250 | H11: ='Capital Requirements'!$F$20 -> 11392250 | I11: ='Capital Requirements'!$F$20 -> 11392250 | J11: ='Capital Requirements'!$F$20 -> 11392250 | K11: ='Capital Requirements'!$F$20 -> 11392250 | L11: ='Capital Requirements'!$F$20 -> 11392250 | M11: ='Capital Requirements'!$F$20 -> 11392250
A12: Depreciation | F12: ='Capital Requirements'!$F$23 -> 2000000 | G12: ='Capital Requirements'!$F$23 -> 2000000 | H12: ='Capital Requirements'!$F$23 -> 2000000 | I12: ='Capital Requirements'!$F$23 -> 2000000 | J12: ='Capital Requirements'!$F$23 -> 2000000 | K12: ='Capital Requirements'!$F$23 -> 2000000 | L12: ='Capital Requirements'!$F$23 -> 2000000 | M12: ='Capital Requirements'!$F$23 -> 2000000
A13: EBIT Operating Income Before Taxes | F13: =F10-F11-F12 -> -11634750 | G13: =G10-G11-G12 -> -8725375 | H13: =H10-H11-H12 -> -5504281.2 | I13: =I10-I11-I12 -> 14805680 | J13: =J10-J11-J12 -> 26303092 | K13: =K10-K11-K12 -> 52172269 | L13: =L10-L11-L12 -> 75454529 | M13: =M10-M11-M12 -> 89423884
A14: Taxes on Operating Income | F14: =F13*0.21 -> -2443297.5 | G14: =G13*0.21 -> -1832328.8 | H14: =H13*0.21 -> -1155899.1 | I14: =I13*0.21 -> 3109192.7 | J14: =J13*0.21 -> 5523649.3 | K14: =K13*0.21 -> 10956176 | L14: =L13*0.21 -> 15845451 | M14: =M13*0.21 -> 18779016
A15: Net Operating Profit After Taxes | F15: =F13-F14 -> -9191452.5 | G15: =G13-G14 -> -6893046.2 | H15: =H13-H14 -> -4348382.2 | I15: =I13-I14 -> 11696487 | J15: =J13-J14 -> 20779443 | K15: =K13-K14 -> 41216093 | L15: =L13-L14 -> 59609078 | M15: =M13-M14 -> 70644869
A16: Add back depreciation | F16: =F12 -> 2000000 | G16: =G12 -> 2000000 | H16: =H12 -> 2000000 | I16: =I12 -> 2000000 | J16: =J12 -> 2000000 | K16: =K12 -> 2000000 | L16: =L12 -> 2000000 | M16: =M12 -> 2000000
A17: Net Cash Flow | E17: =E6 -> -21197000 | F17: =F15+F16 -> -7191452.5 | G17: =G15+G16 -> -4893046.2 | H17: =H15+H16 -> -2348382.2 | I17: =I15+I16 -> 13696487 | J17: =J15+J16 -> 22779443 | K17: =K15+K16 -> 43216093 | L17: =L15+L16 -> 61609078 | M17: =M15+M16 -> 72644869
A18: Cumulative Cash Flow | F18: =E17+F17 -> -28388452 | G18: =F18+G17 -> -33281499 | H18: =G18+H17 -> -35629881 | I18: =H18+I17 -> -21933394 | J18: =I18+J17 -> 846048.54 | K18: =J18+K17 -> 44062141 | L18: =K18+L17 -> 1.0567122e+08 | M18: =L18+M17 -> 1.7831609e+08
A20: Key Output and Appraisal of the Proposed Project
A22: NPV | D22: =NPV('Capital Requirements'!D45,F17:M17)+E17 -> 84949386
A23: IRR | D23: =IRR(E17:M17) -> 0.35233255
A24: Payback Period | D24: =4+(ABS(I18)/J17) -> 4.9628591
A26: DCF
A27: Year | B27: Cash Flow (CF) | C27: Discount Rate (r) | D27: Discounted Cash Flow (DCF)
A28: 0 | B28: =E17 -> -21197000 | C28: ='Capital Requirements'!$D$45 -> 0.0925 | D28: =B28/(1+C28)^A28 -> -21197000
A29: 1 | B29: -7191452.5 | C29: ='Capital Requirements'!$D$45 -> 0.0925 | D29: =B29/(1+C29)^A29 -> -6582565.2
A30: 2 | B30: -4893046.2 | C30: ='Capital Requirements'!$D$45 -> 0.0925 | D30: =B30/(1+C30)^A30 -> -4099552.3
A31: 3 | B31: -2348382.2 | C31: ='Capital Requirements'!$D$45 -> 0.0925 | D31: =B31/(1+C31)^A31 -> -1800961.5
A32: 4 | B32: 13696487 | C32: ='Capital Requirements'!$D$45 -> 0.0925 | D32: =B32/(1+C32)^A32 -> 9614427
A33: 5 | B33: 22779443 | C33: ='Capital Requirements'!$D$45 -> 0.0925 | D33: =B33/(1+C33)^A33 -> 14636454
A34: 6 | B34: 43216093 | C34: ='Capital Requirements'!$D$45 -> 0.0925 | D34: =B34/(1+C34)^A34 -> 25416563
A35: 7 | B35: 61609078 | C35: ='Capital Requirements'!$D$45 -> 0.0925 | D35: =B35/(1+C35)^A35 -> 33166114
A36: 8 | B36: 72644869 | C36: ='Capital Requirements'!$D$45 -> 0.0925 | D36: =B36/(1+C36)^A36 -> 35795908
A37: Total DCF | D37: =SUM(D28:D36) -> 84949386

Sheet Chart Data1
B2: Year | C2: Company | D2: Sales Revenue | E2: Costs of Goods Sold | F2: Gross Profits | G2: Fixed operating costs | H2: EBIT | I2: Net Operating Profit | J2: Net Cash Flow | K2: DCF | L2: Maintenance & Cleaning | M2: Electric | N2: Garbage | O2: Gas | P2: Insurance | Q2: Labor | R2: Telephone
B3: 0 | C3: Family | D3: 0 | E3: 0 | F3: 0 | G3: 0 | H3: 0 | I3: 0 | J3: -55450000 | K3: -55450000 | L3: 0 | M3: 0 | N3: 0 | O3: 0 | P3: 0 | Q3: 0 | R3: 0
B4: 1 | C4: Family | D4: 40000000 | E4: 4000000 | F4: 36000000 | G4: 15392250 | H4: 15607750 | I4: 12330122 | J4: 17330122 | K4: 16009351 | L4: 350000 | M4: 15000 | N4: 1750 | O4: 3000 | P4: 20000 | Q4: 15000000 | R4: 2500
B5: 2 | C5: Family | D5: 48110000 | E5: 4811000 | F5: 43299000 | G5: 15392250 | H5: 22906750 | I5: 18096332 | J5: 23096332 | K5: 19710027 | L5: 350000 | M5: 15000 | N5: 1750 | O5: 3000 | P5: 20000 | Q5: 15000000 | R5: 2500
B6: 3 | C6: Family | D6: 49253300 | E6: 4925330 | F6: 44327970 | G6: 15392250 | H6: 23935720 | I6: 18909219 | J6: 23909219 | K6: 18848712 | L6: 350000 | M6: 15000 | N6: 1750 | O6: 3000 | P6: 20000 | Q6: 15000000 | R6: 2500
B7: 4 | C7: Family | D7: 50430899 | E7: 5043089.9 | F7: 45387809 | G7: 15392250 | H7: 24995559 | I7: 19746492 | J7: 24746492 | K7: 18021960 | L7: 350000 | M7: 15000 | N7: 1750 | O7: 3000 | P7: 20000 | Q7: 15000000 | R7: 2500 | T7: Row Labels | U7: Sales Revenue | V7: Gross Profits | W7: EBIT
B8: 5 | C8: Family | D8: 51643826 | E8: 5164382.6 | F8: 46479443 | G8: 15392250 | H8: 26087193 | I8: 20608883 | J8: 25608883 | K8: 17228644 | L8: 350000 | M8: 15000 | N8: 1750 | O8: 3000 | P8: 20000 | Q8: 15000000 | R8: 2500 | T8: Action | U8: 8.297651e+08 | V8: 7.5508624e+08 | W8: 4.6009164e+08
B9: 6 | C9: Family | D9: 52893141 | E9: 5289314.1 | F9: 47603827 | G9: 15392250 | H9: 27211577 | I9: 21497146 | J9: 26497146 | K9: 16467651 | L9: 350000 | M9: 15000 | N9: 1750 | O9: 3000 | P9: 20000 | Q9: 15000000 | R9: 2500 | T9: Craft | U9: 6.8809788e+08 | V9: 6.1240712e+08 | W9: 3.6047081e+08
B10: 7 | C10: Family | D10: 54179935 | E10: 5417993.5 | F10: 48761941 | G10: 15392250 | H10: 28369691 | I10: 22412056 | J10: 27412056 | K10: 15737882 | L10: 350000 | M10: 15000 | N10: 1750 | O10: 3000 | P10: 20000 | Q10: 15000000 | R10: 2500 | T10: Family | U10: 4.0476346e+08 | V10: 3.6428712e+08 | W10: 2.0114912e+08
B11: 8 | C11: Family | D11: 58252361 | E11: 5825236.1 | F11: 52427125 | G11: 15392250 | H11: 32034875 | I11: 25307551 | J11: 30307551 | K11: 16074135 | L11: 350000 | M11: 15000 | N11: 1750 | O11: 3000 | P11: 20000 | Q11: 15000000 | R11: 2500 | T11: RPG | U11: 5.4643067e+08 | V11: 4.8085899e+08 | W11: 2.7734443e+08
B12: 0 | C12: RPG | D12: 0 | E12: 0 | F12: 0 | G12: 0 | H12: 0 | I12: 0 | J12: -71795000 | K12: -71795000 | L12: 0 | M12: 0 | N12: 0 | O12: 0 | P12: 0 | Q12: 0 | R12: 0 | T12: Starting New | U12: 3.5729794e+08 | V12: 3.3943305e+08 | W12: 2.3229505e+08
B13: 1 | C13: RPG | D13: 54000000 | E13: 6480000 | F13: 47520000 | G13: 18439320 | H13: 22080680 | I13: 17443737 | J13: 24443737 | K13: 22528790 | L13: 392000 | M13: 16800 | N13: 1960 | O13: 3360 | P13: 22400 | Q13: 18000000 | R13: 2800 | T13: Grand Total | U13: 2.8263551e+09 | V13: 2.5520725e+09 | W13: 1.531351e+09
B14: 2 | C14: RPG | D14: 64948500 | E14: 7793820 | F14: 57154680 | G14: 18439320 | H14: 31715360 | I14: 25055134 | J14: 32055134 | K14: 27229403 | L14: 392000 | M14: 16800 | N14: 1960 | O14: 3360 | P14: 22400 | Q14: 18000000 | R14: 2800
B15: 3 | C15: RPG | D15: 66491955 | E15: 7979034.6 | F15: 58512920 | G15: 18439320 | H15: 33073600 | I15: 26128144 | J15: 33128144 | K15: 25936292 | L15: 392000 | M15: 16800 | N15: 1960 | O15: 3360 | P15: 22400 | Q15: 18000000 | R15: 2800
B16: 4 | C16: RPG | D16: 68081714 | E16: 8169805.6 | F16: 59911908 | G16: 18439320 | H16: 34472588 | I16: 27233345 | J16: 34233345 | K16: 24701901 | L16: 392000 | M16: 16800 | N16: 1960 | O16: 3360 | P16: 22400 | Q16: 18000000 | R16: 2800 | T16: Row Labels | U16: Sum of Family Games Software Company | V16: Sum of RPG Games Software Company | W16: Sum of Craft Games Software Company | X16: Sum of Action Games Software Company | Y16: Sum of Starting a New Game Software Company
B17: 5 | C17: RPG | D17: 69719165 | E17: 8366299.8 | F17: 61352865 | G17: 18439320 | H17: 35913545 | I17: 28371701 | J17: 35371701 | K17: 23523788 | L17: 392000 | M17: 16800 | N17: 1960 | O17: 3360 | P17: 22400 | Q17: 18000000 | R17: 2800 | T17: Building Maintenance & Cleaning | U17: 350000 | V17: 392000 | W17: 439040 | X17: 482720 | Y17: 350000
B18: 6 | C18: RPG | D18: 71405740 | E18: 8568688.8 | F18: 62837051 | G18: 18439320 | H18: 37397731 | I18: 29544208 | J18: 36544208 | K18: 22399593 | L18: 392000 | M18: 16800 | N18: 1960 | O18: 3360 | P18: 22400 | Q18: 18000000 | R18: 2800 | T18: Electric | U18: 15000 | V18: 16800 | W18: 18816 | X18: 20688 | Y18: 15000
B19: 7 | C19: RPG | D19: 73142912 | E19: 8777149.5 | F19: 64365763 | G19: 18439320 | H19: 38926443 | I19: 30751890 | J19: 37751890 | K19: 21327037 | L19: 392000 | M19: 16800 | N19: 1960 | O19: 3360 | P19: 22400 | Q19: 18000000 | R19: 2800 | T19: Garbage | U19: 1750 | V19: 1960 | W19: 2195.2 | X19: 2413.6 | Y19: 1750
B20: 8 | C20: RPG | D20: 78640687 | E20: 9436882.5 | F20: 69203805 | G20: 18439320 | H20: 43764485 | I20: 34573943 | J20: 41573943 | K20: 21646282 | L20: 392000 | M20: 16800 | N20: 1960 | O20: 3360 | P20: 22400 | Q20: 18000000 | R20: 2800 | T20: Gas | U20: 3000 | V20: 3360 | W20: 3763.2 | X20: 4137.6 | Y20: 3000
B21: 0 | C21: Craft | D21: 0 | E21: 0 | F21: 0 | G21: 0 | H21: 0 | I21: 0 | J21: -93174500 | K21: -93174500 | L21: 0 | M21: 0 | N21: 0 | O21: 0 | P21: 0 | Q21: 0 | R21: 0 | T21: Insurance | U21: 20000 | V21: 22400 | W21: 25088 | X21: 27584 | Y21: 20000
B22: 1 | C22: Craft | D22: 68000000 | E22: 7480000 | F22: 60520000 | G22: 21492038 | H22: 29027962 | I22: 22932090 | J22: 32932090 | K22: 30282381 | L22: 439040 | M22: 18816 | N22: 2195 | O22: 3763 | P22: 25088 | Q22: 21000000 | R22: 3136 | T22: Labor Costs For Employees | U22: 15000000 | V22: 18000000 | W22: 21000000 | X22: 24000000 | Y22: 11000000
B23: 2 | C23: Craft | D23: 81787000 | E23: 8996570 | F23: 72790430 | G23: 21492038 | H23: 41298392 | I23: 32625729 | J23: 42625729 | K23: 36042366 | L23: 439040 | M23: 18816 | N23: 2195 | O23: 3763 | P23: 25088 | Q23: 21000000 | R23: 3136 | T23: Telephone | U23: 2500 | V23: 2800 | W23: 3136 | X23: 3448 | Y23: 2500
B24: 3 | C24: Craft | D24: 83730610 | E24: 9210367.1 | F24: 74520243 | G24: 21492038 | H24: 43028205 | I24: 33992282 | J24: 43992282 | K24: 34204929 | L24: 439040 | M24: 18816 | N24: 2195 | O24: 3763 | P24: 25088 | Q24: 21000000 | R24: 3136 | T24: Grand Total | U24: 15392250 | V24: 18439320 | W24: 21492038 | X24: 24540991 | Y24: 11392250
B25: 4 | C25: Craft | D25: 85732528 | E25: 9430578.1 | F25: 76301950 | G25: 21492038 | H25: 44809912 | I25: 35399830 | J25: 45399830 | K25: 32459152 | L25: 439040 | M25: 18816 | N25: 2195 | O25: 3763 | P25: 25088 | Q25: 21000000 | R25: 3136
B26: 5 | C26: Craft | D26: 87794504 | E26: 9657395.5 | F26: 78137109 | G26: 21492038 | H26: 46645070 | I26: 36849606 | J26: 46849606 | K26: 30800631 | L26: 439040 | M26: 18816 | N26: 2195 | O26: 3763 | P26: 25088 | Q26: 21000000 | R26: 3136
B27: 6 | C27: Craft | D27: 89918339 | E27: 9891017.3 | F27: 80027322 | G27: 21492038 | H27: 48535284 | I27: 38342874 | J27: 48342874 | K27: 29225158 | L27: 439040 | M27: 18816 | N27: 2195 | O27: 3763 | P27: 25088 | Q27: 21000000 | R27: 3136
B28: 7 | C28: Craft | D28: 92105889 | E28: 10131648 | F28: 81974242 | G28: 21492038 | H28: 50482203 | I28: 39880941 | J28: 49880941 | K28: 27728717 | L28: 439040 | M28: 18816 | N28: 2195 | O28: 3763 | P28: 25088 | Q28: 21000000 | R28: 3136
B29: 8 | C29: Craft | D29: 99029014 | E29: 10893192 | F29: 88135822 | G29: 21492038 | H29: 56643784 | I29: 44748589 | J29: 54748589 | K29: 27985870 | L29: 439040 | M29: 18816 | N29: 2195 | O29: 3763 | P29: 25088 | Q29: 21000000 | R29: 3136
B30: 0 | C30: Action | D30: 0 | E30: 0 | F30: 0 | G30: 0 | H30: 0 | I30: 0 | J30: -1.1119767e+08 | K30: -1.1119767e+08 | L30: 0 | M30: 0 | N30: 0 | O30: 0 | P30: 0 | Q30: 0 | R30: 0
B31: 1 | C31: Action | D31: 82000000 | E31: 7380000 | F31: 74620000 | G31: 24540991 | H31: 37745675 | I31: 29819084 | J31: 42152417 | K31: 38671942 | L31: 482720 | M31: 20688 | N31: 2414 | O31: 4138 | P31: 27584 | Q31: 24000000 | R31: 3448
B32: 2 | C32: Action | D32: 98625500 | E32: 8876295 | F32: 89749205 | G32: 24540991 | H32: 52874880 | I32: 41771156 | J32: 54104489 | K32: 45538666 | L32: 482720 | M32: 20688 | N32: 2414 | O32: 4138 | P32: 27584 | Q32: 24000000 | R32: 3448
B33: 3 | C33: Action | D33: 100969265 | E33: 9087233.8 | F33: 91882031 | G33: 24540991 | H33: 55007707 | I33: 43456088 | J33: 55789422 | K33: 43079670 | L33: 482720 | M33: 20688 | N33: 2414 | O33: 4138 | P33: 27584 | Q33: 24000000 | R33: 3448
B34: 4 | C34: Action | D34: 1.0338334e+08 | E34: 9304500.9 | F34: 94078842 | G34: 24540991 | H34: 57204518 | I34: 45191569 | J34: 57524902 | K34: 40752091 | L34: 482720 | M34: 20688 | N34: 2414 | O34: 4138 | P34: 27584 | Q34: 24000000 | R34: 3448
B35: 5 | C35: Action | D35: 1.0586984e+08 | E35: 9528285.9 | F35: 96341557 | G35: 24540991 | H35: 59467233 | I35: 46979114 | J35: 59312447 | K35: 38549021 | L35: 482720 | M35: 20688 | N35: 2414 | O35: 4138 | P35: 27584 | Q35: 24000000 | R35: 3448
B36: 6 | C36: Action | D36: 1.0843094e+08 | E36: 9758784.5 | F36: 98672154 | G36: 24540991 | H36: 61797830 | I36: 48820285 | J36: 61153619 | K36: 36463905 | L36: 482720 | M36: 20688 | N36: 2414 | O36: 4138 | P36: 27584 | Q36: 24000000 | R36: 3448
... B47: 8 | C47: Starting New | D47: 1.0822751e+08 | E47: 5411375.5 | F47: 1.0281613e+08 | G47: 11392250 | H47: 89423884 | I47: 70644869 | J47: 72644869 | K47: 35795908 | L47: 350000 | M47: 15000 | N47: 1750 | O47: 3000 | P47: 20000 | Q47: 11000000 | R47: 2500
B50: Company | C50: Category | D50: Amount | F50: Company | G50: Action | J50: Company | K50: Action
B51: Family | C51: Electric | D51: 15000
B52: Family | C52: Garbage | D52: 1750 | F52: Row Labels | G52: Sum of Amount | J52: Row Labels | K52: Sum of DCF
B53: Family | C53: Gas | D53: 3000 | F53: Electric | G53: 20688 | J53: 0 | K53: -1.1119767e+08
...

Sheet Chart Data2
B1: Column Labels
B2: Sales Revenue | C2: Sales Revenue2 | D2: EBIT | E2: Total Sales Revenue | F2: Total Sales Revenue2 | G2: Total EBIT
A3: Row Labels | B3: Action | C3: Action | D3: Action
A4: 1 | B4: 82000000 | C4: 82000000 | D4: 37745675 | E4: 82000000 | F4: 82000000 | G4: 37745675
A5: 2 | B5: 98625500 | C5: 98625500 | D5: 52874880 | E5: 98625500 | F5: 98625500 | G5: 52874880
A6: 3 | B6: 100969265 | C6: 100969265 | D6: 55007707 | E6: 100969265 | F6: 100969265 | G6: 55007707
A7: 4 | B7: 1.0338334e+08 | C7: 1.0338334e+08 | D7: 57204518 | E7: 1.0338334e+08 | F7: 1.0338334e+08 | G7: 57204518
A8: 5 | B8: 1.0586984e+08 | C8: 1.0586984e+08 | D8: 59467233 | E8: 1.0586984e+08 | F8: 1.0586984e+08 | G8: 59467233
A9: 6 | B9: 1.0843094e+08 | C9: 1.0843094e+08 | D9: 61797830 | E9: 1.0843094e+08 | F9: 1.0843094e+08 | G9: 61797830
A10: 7 | B10: 1.1106887e+08 | C10: 1.1106887e+08 | D10: 64198344 | E10: 1.1106887e+08 | F10: 1.1106887e+08 | G10: 64198344
A11: 8 | B11: 1.1941734e+08 | C11: 1.1941734e+08 | D11: 71795455 | E11: 1.1941734e+08 | F11: 1.1941734e+08 | G11: 71795455
A12: Grand Total | B12: 8.297651e+08 | C12: 8.297651e+08 | D12: 4.6009164e+08 | E12: 8.297651e+08 | F12: 8.297651e+08 | G12: 4.6009164e+08
