Workbook
Name Slicer_Length_of_Service: #N/A
Name Slicer_Title: #N/A

Sheet Exe Sum & Dashboard
M3: DASHBOARD AREA

Sheet Memo

Sheet Total Comp Report
A1: Worker | B1: Title | C1: City | D1: Country | E1: Region | F1: Original Hire Date | G1: Current Date | H1: Level 2 Org | I1: Level 3 Org | J1: Level 4 Org | K1: 2021 Salary Currency | L1: 2021 Base Salary | M1: 2021 Reg Bonus | N1: 2021 Performance Fees | O1: 2021 Other Bonus 2 | P1: 2021 Total Bonus | Q1: 2021 Commissions | R1: 2021 Overtime | S1: 2021 Special Allowance | T1: Total 2021 Other Comp | U1: 2021 Equity Award | V1: 2021 Total Compensation | W1: 2022 Salary Currency | X1: 2022 Base Salary | Y1: 2022 Total Compensation | Z1: Length of Service | AA1: 2021 base Salaries in USD | AB1: 2021 Total Compensation USD | AC1: 2022 base Salaries in USD | AD1: 2022 Total Compensation USD | AE1: % increase in base salary from 2021 to 2022 | AF1: Total change in base salary from 2021 to 2022 | AG1: 2021 Variable Compensation | AH1: Base Salary Ratio | AI1: 2021 Equity Award USD | AJ1: 2021 Commisions USD | AK1: 2021 Overtime USD | AM1: # of Directors Who Earned Performance Fees | AN1: # of Directors Who Earned Bonuses | AO1: # of Employees Who Earned Overtime | AP1: Reg Bonus % | AQ1: Other Bonus % | AR1: 2022 Reg Bonus | AS1: 2022 Other Bonus 2 | AT1: 10% Strengthened USD | AU1: Strengthened USD Difference
A2: Employee 1 | B2: Director | C2: London | D2: United Kingdom | E2: EMEA | F2: 34547 | G2: 44896 | H2: Client Businesses Platform | I2: Z | J2: D | K2: GBP | L2: 132825 | M2: 71808 | N2: 1000 | O2: 500 | P2: =M2+N2+O2 -> 73308 | Q2: 3000 | R2: 0 | S2: 500 | T2: =+Q2+R2+S2 -> 3500 | U2: 15000 | V2: =L2+P2+T2+U2 -> 224633 | W2: GBP | X2: 146107.5 | Y2: =X2+AR2+AS2 -> 517861.3 | Z2: {=_xlfn.IFS(YEARFRAC(F2,G2)<1,"<1 Year",YEARFRAC(F2,G2)<=5,"1-5 Years",YEARFRAC(F2,G2)>5,">5 Years")} -> >5 Years | AA2: =L2*(_xlfn.XLOOKUP(K2,'FX rates'!$A$2:$A$38,'FX rates'!$B$2:$B$38)) -> 176743.59 | AB2: =V2*(_xlfn.XLOOKUP(K2,'FX rates'!$A$2:$A$38,'FX rates'!$B$2:$B$38)) -> 298907.9 | AC2: =X2*(_xlfn.XLOOKUP(W2,'FX rates'!$A$2:$A$38,'FX rates'!$B$2:$B$38)) -> 194417.94 | AD2: =Y2*(_xlfn.XLOOKUP(W2,'FX rates'!$A$2:$A$38,'FX rates'!$B$2:$B$38)) -> 689092.14 | AE2: =(AC2-AA2)/AA2 -> 0.1 | AF2: =X2-L2 -> 13282.5 | AG2: =AB2-AA2 -> 122164.32 | AH2: =AC2/X2 -> 1.33065 | AI2: =U2*(_xlfn.XLOOKUP(K2,'FX rates'!$A$2:$A$38,'FX rates'!$B$2:$B$38)) -> 19959.75 | AJ2: =Q2*(_xlfn.XLOOKUP(K2,'FX rates'!$A$2:$A$38,'FX rates'!$B$2:$B$38)) -> 3991.95 | AK2: =R2*(_xlfn.XLOOKUP(K2,'FX rates'!$A$2:$A$38,'FX rates'!$B$2:$B$38)) -> 0 | AM2: =COUNTIFS($B$2:$B$2001,"Director",$N$2:$N$2001,">0")+COUNTIFS($B$2:$B$2001,"Managing Director",$N$2:$N$2001,">0") -> 143 | AN2: =COUNTIFS($B$2:$B$2001,"Director",$P$2:$P$2001,">0")+COUNTIFS($B$2:$B$2001,"Managing Director",$P$2:$P$2001,">0") -> 1067 | AO2: =COUNTIFS($R$2:$R$2001,">0") -> 60 | AP2: =M2/L2 -> 0.54062112 | AQ2: =O2/L2 -> 0.0037643516 | AR2: =X2*(1+AP2) -> 225096.3 | AS2: =IF(AQ2>0,X2*(1+AQ2),"0") -> 146657.5 | AT2: =AD2*(0.9) -> 620182.92 | AU2: =AD2-AT2 -> 68909.214
A3: Employee 10 | B3: Associate | C3: Tokyo | D3: Japan | E3: Asia-Pacific | F3: 34431 | G3: 44896 | H3: Operating Platform | I3: J | J3: G | K3: JPY | L3: 12529836 | M3: 2096710 | N3: 0 | O3: 0 | P3: =M3+N3+O3 -> 2096710 | Q3: 0 | R3: 0 | S3: 0 | T3: =+Q3+R3+S3 -> 0 | U3: 0 | V3: =L3+P3+T3+U3 -> 14626546 | W3: JPY | X3: 12655134 | Y3: =X3+AR3+AS3 -> 27427946 | Z3: {=_xlfn.IFS(YEARFRAC(F3,G3)<1,"<1 Year",YEARFRAC(F3,G3)<=5,"1-5 Years",YEARFRAC(F3,G3)>5,">5 Years")} -> >5 Years | AA3: =L3*(_xlfn.XLOOKUP(K3,'FX rates'!$A$2:$A$38,'FX rates'!$B$2:$B$38)) -> 115328.23 | AB3: =V3*(_xlfn.XLOOKUP(K3,'FX rates'!$A$2:$A$38,'FX rates'!$B$2:$B$38)) -> 134626.96 | AC3: =X3*(_xlfn.XLOOKUP(W3,'FX rates'!$A$2:$A$38,'FX rates'!$B$2:$B$38)) -> 116481.52 | AD3: =Y3*(_xlfn.XLOOKUP(W3,'FX rates'!$A$2:$A$38,'FX rates'!$B$2:$B$38)) -> 252454.75 | AE3: =(AC3-AA3)/AA3 -> 0.01 | AF3: =X3-L3 -> 125298.36 | AG3: =AB3-AA3 -> 19298.725 | AH3: =AC3/X3 -> 0.0092042892 | AI3: =U3*(_xlfn.XLOOKUP(K3,'FX rates'!$A$2:$A$38,'FX rates'!$B$2:$B$38)) -> 0 | AJ3: =Q3*(_xlfn.XLOOKUP(K3,'FX rates'!$A$2:$A$38,'FX rates'!$B$2:$B$38)) -> 0 | AK3: =R3*(_xlfn.XLOOKUP(K3,'FX rates'!$A$2:$A$38,'FX rates'!$B$2:$B$38)) -> 0 | AP3: =M3/L3 -> 0.16733739 | AQ3: =O3/L3 -> 0 | AR3: =X3*(1+AP3) -> 14772811 | AS3: =IF(AQ3>0,X3*(1+AQ3),"0") -> 0 | AT3: =AD3*(0.9) -> 227209.27 | AU3: =AD3-AT3 -> 25245.475
A4: Employee 100 | B4: Director | C4: London | D4: United Kingdom | E4: EMEA | F4: 38740 | G4: 44896 | H4: Operating Platform | I4: A | J4: B | K4: GBP | L4: 138637.4 | M4: 32698.6 | N4: 0 | O4: 0 | P4: =M4+N4+O4 -> 32698.6 | Q4: 0 | R4: 0 | S4: 0 | T4: =+Q4+R4+S4 -> 0 | U4: 0 | V4: =L4+P4+T4+U4 -> 171336 | W4: GBP | X4: 155273.89 | Y4: =X4+AR4+AS4 -> 347170.21 | Z4: {=_xlfn.IFS(YEARFRAC(F4,G4)<1,"<1 Year",YEARFRAC(F4,G4)<=5,"1-5 Years",YEARFRAC(F4,G4)>5,">5 Years")} -> >5 Years | AA4: =L4*(_xlfn.XLOOKUP(K4,'FX rates'!$A$2:$A$38,'FX rates'!$B$2:$B$38)) -> 184477.86 | AB4: =V4*(_xlfn.XLOOKUP(K4,'FX rates'!$A$2:$A$38,'FX rates'!$B$2:$B$38)) -> 227988.25 | AC4: =X4*(_xlfn.XLOOKUP(W4,'FX rates'!$A$2:$A$38,'FX rates'!$B$2:$B$38)) -> 206615.2 | AD4: =Y4*(_xlfn.XLOOKUP(W4,'FX rates'!$A$2:$A$38,'FX rates'!$B$2:$B$38)) -> 461962.04 | AE4: =(AC4-AA4)/AA4 -> 0.12 | AF4: =X4-L4 -> 16636.488 | AG4: =AB4-AA4 -> 43510.392 | AH4: =AC4/X4 -> 1.33065 | AI4: =U4*(_xlfn.XLOOKUP(K4,'FX rates'!$A$2:$A$38,'FX rates'!$B$2:$B$38)) -> 0 | AJ4: =Q4*(_xlfn.XLOOKUP(K4,'FX rates'!$A$2:$A$38,'FX rates'!$B$2:$B$38)) -> 0 | AK4: =R4*(_xlfn.XLOOKUP(K4,'FX rates'!$A$2:$A$38,'FX rates'!$B$2:$B$38)) -> 0 | AP4: =M4/L4 -> 0.23585699 | AQ4: =O4/L4 -> 0 | AR4: =X4*(1+AP4) -> 191896.32 | AS4: =IF(AQ4>0,X4*(1+AQ4),"0") -> 0 | AT4: =AD4*(0.9) -> 415765.83 | AU4: =AD4-AT4 -> 46196.204
A5: Employee 1000 | B5: Specialist | C5: New York | D5: United States of America | E5: Americas | F5: 43622 | G5: 44896 | H5: Operating Platform | I5: S | J5: W | K5: USD | L5: 54439 | M5: 8602 | N5: 0 | O5: 0 | P5: =M5+N5+O5 -> 8602 | Q5: 0 | R5: 38370 | S5: 0 | T5: =+Q5+R5+S5 -> 38370 | U5: 0 | V5: =L5+P5+T5+U5 -> 101411 | W5: USD | X5: 54983.39 | Y5: =X5+AR5+AS5 -> 118654.8 | Z5: {=_xlfn.IFS(YEARFRAC(F5,G5)<1,"<1 Year",YEARFRAC(F5,G5)<=5,"1-5 Years",YEARFRAC(F5,G5)>5,">5 Years")} -> 1-5 Years | AA5: =L5*(_xlfn.XLOOKUP(K5,'FX rates'!$A$2:$A$38,'FX rates'!$B$2:$B$38)) -> 54439 | AB5: =V5*(_xlfn.XLOOKUP(K5,'FX rates'!$A$2:$A$38,'FX rates'!$B$2:$B$38)) -> 101411 | AC5: =X5*(_xlfn.XLOOKUP(W5,'FX rates'!$A$2:$A$38,'FX rates'!$B$2:$B$38)) -> 54983.39 | AD5: =Y5*(_xlfn.XLOOKUP(W5,'FX rates'!$A$2:$A$38,'FX rates'!$B$2:$B$38)) -> 118654.8 | AE5: =(AC5-AA5)/AA5 -> 0.01 | AF5: =X5-L5 -> 544.39 | AG5: =AB5-AA5 -> 46972 | AH5: =AC5/X5 -> 1 | AI5: =U5*(_xlfn.XLOOKUP(K5,'FX rates'!$A$2:$A$38,'FX rates'!$B$2:$B$38)) -> 0 | AJ5: =Q5*(_xlfn.XLOOKUP(K5,'FX rates'!$A$2:$A$38,'FX rates'!$B$2:$B$38)) -> 0 | AK5: =R5*(_xlfn.XLOOKUP(K5,'FX rates'!$A$2:$A$38,'FX rates'!$B$2:$B$38)) -> 38370 | AP5: =M5/L5 -> 0.15801172 | AQ5: =O5/L5 -> 0 | AR5: =X5*(1+AP5) -> 63671.41 | AS5: =IF(AQ5>0,X5*(1+AQ5),"0") -> 0 | AT5: =AD5*(0.9) -> 106789.32 | AU5: =AD5-AT5 -> 11865.48
A6: Employee 1001 | B6: Vice President | C6: Philadelphia | D6: United States of America | E6: Americas | F6: 43622 | G6: 44896 | H6: Investments Platform | I6: U | J6: H | K6: USD | L6: 170775 | M6: 63360 | N6: 0 | O6: 0 | P6: =M6+N6+O6 -> 63360 | Q6: 0 | R6: 0 | S6: 0 | T6: =+Q6+R6+S6 -> 0 | U6: 0 | V6: =L6+P6+T6+U6 -> 234135 | W6: USD | X6: 172482.75 | Y6: =X6+AR6+AS6 -> 408959.1 | Z6: {=_xlfn.IFS(YEARFRAC(F6,G6)<1,"<1 Year",YEARFRAC(F6,G6)<=5,"1-5 Years",YEARFRAC(F6,G6)>5,">5 Years")} -> 1-5 Years | AA6: =L6*(_xlfn.XLOOKUP(K6,'FX rates'!$A$2:$A$38,'FX rates'!$B$2:$B$38)) -> 170775 | AB6: =V6*(_xlfn.XLOOKUP(K6,'FX rates'!$A$2:$A$38,'FX rates'!$B$2:$B$38)) -> 234135 | AC6: =X6*(_xlfn.XLOOKUP(W6,'FX rates'!$A$2:$A$38,'FX rates'!$B$2:$B$38)) -> 172482.75 | AD6: =Y6*(_xlfn.XLOOKUP(W6,'FX rates'!$A$2:$A$38,'FX rates'!$B$2:$B$38)) -> 408959.1 | AE6: =(AC6-AA6)/AA6 -> 0.01 | AF6: =X6-L6 -> 1707.75 | AG6: =AB6-AA6 -> 63360 | AH6: =AC6/X6 -> 1 | AI6: =U6*(_xlfn.XLOOKUP(K6,'FX rates'!$A$2:$A$38,'FX rates'!$B$2:$B$38)) -> 0 | AJ6: =Q6*(_xlfn.XLOOKUP(K6,'FX rates'!$A$2:$A$38,'FX rates'!$B$2:$B$38)) -> 0 | AK6: =R6*(_xlfn.XLOOKUP(K6,'FX rates'!$A$2:$A$38,'FX rates'!$B$2:$B$38)) -> 0 | AP6: =M6/L6 -> 0.37101449 | AQ6: =O6/L6 -> 0 | AR6: =X6*(1+AP6) -> 236476.35 | AS6: =IF(AQ6>0,X6*(1+AQ6),"0") -> 0 | AT6: =AD6*(0.9) -> 368063.19 | AU6: =AD6-AT6 -> 40895.91
A7: Employee 1002 | B7: Director | C7: Wilmington | D7: United States of America | E7: Americas | F7: 43622 | G7: 44896 | H7: Operating Platform | I7: B | J7: T | K7: USD | L7: 161095 | M7: 72930 | N7: 0 | O7: 0 | P7: =M7+N7+O7 -> 72930 | Q7: 0 | R7: 0 | S7: 0 | T7: =+Q7+R7+S7 -> 0 | U7: 0 | V7: =L7+P7+T7+U7 -> 234025 | W7: USD | X7: 169149.75 | Y7: =X7+AR7+AS7 -> 414876 | Z7: {=_xlfn.IFS(YEARFRAC(F7,G7)<1,"<1 Year",YEARFRAC(F7,G7)<=5,"1-5 Years",YEARFRAC(F7,G7)>5,">5 Years")} -> 1-5 Years | AA7: =L7*(_xlfn.XLOOKUP(K7,'FX rates'!$A$2:$A$38,'FX rates'!$B$2:$B$38)) -> 161095 | AB7: =V7*(_xlfn.XLOOKUP(K7,'FX rates'!$A$2:$A$38,'FX rates'!$B$2:$B$38)) -> 234025 | AC7: =X7*(_xlfn.XLOOKUP(W7,'FX rates'!$A$2:$A$38,'FX rates'!$B$2:$B$38)) -> 169149.75 | AD7: =Y7*(_xlfn.XLOOKUP(W7,'FX rates'!$A$2:$A$38,'FX rates'!$B$2:$B$38)) -> 414876 | AE7: =(AC7-AA7)/AA7 -> 0.05 | AF7: =X7-L7 -> 8054.75 | AG7: =AB7-AA7 -> 72930 | AH7: =AC7/X7 -> 1 | AI7: =U7*(_xlfn.XLOOKUP(K7,'FX rates'!$A$2:$A$38,'FX rates'!$B$2:$B$38)) -> 0 | AJ7: =Q7*(_xlfn.XLOOKUP(K7,'FX rates'!$A$2:$A$38,'FX rates'!$B$2:$B$38)) -> 0 | AK7: =R7*(_xlfn.XLOOKUP(K7,'FX rates'!$A$2:$A$38,'FX rates'!$B$2:$B$38)) -> 0 | AP7: =M7/L7 -> 0.45271424 | AQ7: =O7/L7 -> 0 | AR7: =X7*(1+AP7) -> 245726.25 | AS7: =IF(AQ7>0,X7*(1+AQ7),"0") -> 0 | AT7: =AD7*(0.9) -> 373388.4 | AU7: =AD7-AT7 -> 41487.6
A8: Employee 1003 | B8: Managing Director | C8: New York | D8: United States of America | E8: Americas | F8: 43615 | G8: 44896 | H8: Corporate and Risk Platform | I8: E | J8: V | K8: USD | L8: 297000 | M8: 372680 | N8: 0 | O8: 0 | P8: =M8+N8+O8 -> 372680 | Q8: 0 | R8: 0 | S8: 0 | T8: =+Q8+R8+S8 -> 0 | U8: 106000 | V8: =L8+P8+T8+U8 -> 775680 | W8: USD | X8: 302940 | Y8: =X8+AR8+AS8 -> 986013.6 | Z8: {=_xlfn.IFS(YEARFRAC(F8,G8)<1,"<1 Year",YEARFRAC(F8,G8)<=5,"1-5 Years",YEARFRAC(F8,G8)>5,">5 Years")} -> 1-5 Years | AA8: =L8*(_xlfn.XLOOKUP(K8,'FX rates'!$A$2:$A$38,'FX rates'!$B$2:$B$38)) -> 297000 | AB8: =V8*(_xlfn.XLOOKUP(K8,'FX rates'!$A$2:$A$38,'FX rates'!$B$2:$B$38)) -> 775680 | AC8: =X8*(_xlfn.XLOOKUP(W8,'FX rates'!$A$2:$A$38,'FX rates'!$B$2:$B$38)) -> 302940 | AD8: =Y8*(_xlfn.XLOOKUP(W8,'FX rates'!$A$2:$A$38,'FX rates'!$B$2:$B$38)) -> 986013.6 | AE8: =(AC8-AA8)/AA8 -> 0.02 | AF8: =X8-L8 -> 5940 | AG8: =AB8-AA8 -> 478680 | AH8: =AC8/X8 -> 1 | AI8: =U8*(_xlfn.XLOOKUP(K8,'FX rates'!$A$2:$A$38,'FX rates'!$B$2:$B$38)) -> 106000 | AJ8: =Q8*(_xlfn.XLOOKUP(K8,'FX rates'!$A$2:$A$38,'FX rates'!$B$2:$B$38)) -> 0 | AK8: =R8*(_xlfn.XLOOKUP(K8,'FX rates'!$A$2:$A$38,'FX rates'!$B$2:$B$38)) -> 0 | AP8: =M8/L8 -> 1.2548148 | AQ8: =O8/L8 -> 0 | AR8: =X8*(1+AP8) -> 683073.6 | AS8: =IF(AQ8>0,X8*(1+AQ8),"0") -> 0 | AT8: =AD8*(0.9) -> 887412.24 | AU8: =AD8-AT8 -> 98601.36
A9: Employee 1004 | B9: Director | C9: Tokyo | D9: Japan | E9: Asia-Pacific | F9: 43615 | G9: 44896 | H9: Investments Platform | I9: Z | J9: G | K9: JPY | L9: 22572000 | M9: 39479000 | N9: 0 | O9: 0 | P9: =M9+N9+O9 -> 39479000 | Q9: 0 | R9: 0 | S9: 0 | T9: =+Q9+R9+S9 -> 0 | U9: 0 | V9: =L9+P9+T9+U9 -> 62051000 | W9: JPY | X9: 23700600 | Y9: =X9+AR9+AS9 -> 88854150 | Z9: {=_xlfn.IFS(YEARFRAC(F9,G9)<1,"<1 Year",YEARFRAC(F9,G9)<=5,"1-5 Years",YEARFRAC(F9,G9)>5,">5 Years")} -> 1-5 Years | AA9: =L9*(_xlfn.XLOOKUP(K9,'FX rates'!$A$2:$A$38,'FX rates'!$B$2:$B$38)) -> 207759.22 | AB9: =V9*(_xlfn.XLOOKUP(K9,'FX rates'!$A$2:$A$38,'FX rates'!$B$2:$B$38)) -> 571135.35 | AC9: =X9*(_xlfn.XLOOKUP(W9,'FX rates'!$A$2:$A$38,'FX rates'!$B$2:$B$38)) -> 218147.18 | AD9: =Y9*(_xlfn.XLOOKUP(W9,'FX rates'!$A$2:$A$38,'FX rates'!$B$2:$B$38)) -> 817839.29 | AE9: =(AC9-AA9)/AA9 -> 0.05 | AF9: =X9-L9 -> 1128600 | AG9: =AB9-AA9 -> 363376.13 | AH9: =AC9/X9 -> 0.0092042892 | AI9: =U9*(_xlfn.XLOOKUP(K9,'FX rates'!$A$2:$A$38,'FX rates'!$B$2:$B$38)) -> 0 | AJ9: =Q9*(_xlfn.XLOOKUP(K9,'FX rates'!$A$2:$A$38,'FX rates'!$B$2:$B$38)) -> 0 | AK9: =R9*(_xlfn.XLOOKUP(K9,'FX rates'!$A$2:$A$38,'FX rates'!$B$2:$B$38)) -> 0 | AP9: =M9/L9 -> 1.7490253 | AQ9: =O9/L9 -> 0 | AR9: =X9*(1+AP9) -> 65153550 | AS9: =IF(AQ9>0,X9*(1+AQ9),"0") -> 0 | AT9: =AD9*(0.9) -> 736055.36 | AU9: =AD9-AT9 -> 81783.929
A10: Employee 1005 | B10: Director | C10: Boston | D10: United States of America | E10: Americas | F10: 43622 | G10: 44896 | H10: Client Businesses Platform | I10: I | J10: D | K10: USD | L10: 166650 | M10: 65450 | N10: 0 | O10: 0 | P10: =M10+N10+O10 -> 65450 | Q10: 0 | R10: 0 | S10: 0 | T10: =+Q10+R10+S10 -> 0 | U10: 0 | V10: =L10+P10+T10+U10 -> 232100 | W10: USD | X10: 173316 | Y10: =X10+AR10+AS10 -> 414700 | Z10: {=_xlfn.IFS(YEARFRAC(F10,G10)<1,"<1 Year",YEARFRAC(F10,G10)<=5,"1-5 Years",YEARFRAC(F10,G10)>5,">5 Years")} -> 1-5 Years | AA10: =L10*(_xlfn.XLOOKUP(K10,'FX rates'!$A$2:$A$38,'FX rates'!$B$2:$B$38)) -> 166650 | AB10: =V10*(_xlfn.XLOOKUP(K10,'FX rates'!$A$2:$A$38,'FX rates'!$B$2:$B$38)) -> 232100 | AC10: =X10*(_xlfn.XLOOKUP(W10,'FX rates'!$A$2:$A$38,'FX rates'!$B$2:$B$38)) -> 173316 | AD10: =Y10*(_xlfn.XLOOKUP(W10,'FX rates'!$A$2:$A$38,'FX rates'!$B$2:$B$38)) -> 414700 | AE10: =(AC10-AA10)/AA10 -> 0.04 | AF10: =X10-L10 -> 6666 | AG10: =AB10-AA10 -> 65450 | AH10: =AC10/X10 -> 1 | AI10: =U10*(_xlfn.XLOOKUP(K10,'FX rates'!$A$2:$A$38,'FX rates'!$B$2:$B$38)) -> 0 | AJ10: =Q10*(_xlfn.XLOOKUP(K10,'FX rates'!$A$2:$A$38,'FX rates'!$B$2:$B$38)) -> 0 | AK10: =R10*(_xlfn.XLOOKUP(K10,'FX rates'!$A$2:$A$38,'FX rates'!$B$2:$B$38)) -> 0 | AP10: =M10/L10 -> 0.39273927 | AQ10: =O10/L10 -> 0 | AR10: =X10*(1+AP10) -> 241384 | AS10: =IF(AQ10>0,X10*(1+AQ10),"0") -> 0 | AT10: =AD10*(0.9) -> 373230 | AU10: =AD10-AT10 -> 41470
A11: Employee 1006 | B11: Vice President | C11: Hong Kong | D11: Hong Kong | E11: Asia-Pacific | F11: 43622 | G11: 44896 | H11: Operating Platform | I11: X | J11: Q | K11: HKD | L11: 1266526.8 | M11: 239184 | N11: 0 | O11: 0 | P11: =M11+N11+O11 -> 239184 | Q11: 0 | R11: 0 | S11: 0 | T11: =+Q11+R11+S11 -> 0 | U11: 0 | V11: =L11+P11+T11+U11 -> 1505710.8 | W11: HKD | X11: 1393179.5 | Y11: =X11+AR11+AS11 -> 3049461.4 | Z11: {=_xlfn.IFS(YEARFRAC(F11,G11)<1,"<1 Year",YEARFRAC(F11,G11)<=5,"1-5 Years",YEARFRAC(F11,G11)>5,">5 Years")} -> 1-5 Years | AA11: =L11*(_xlfn.XLOOKUP(K11,'FX rates'!$A$2:$A$38,'FX rates'!$B$2:$B$38)) -> 161461.32 | AB11: =V11*(_xlfn.XLOOKUP(K11,'FX rates'!$A$2:$A$38,'FX rates'!$B$2:$B$38)) -> 191953.34 | AC11: =X11*(_xlfn.XLOOKUP(W11,'FX rates'!$A$2:$A$38,'FX rates'!$B$2:$B$38)) -> 177607.45 | AD11: =Y11*(_xlfn.XLOOKUP(W11,'FX rates'!$A$2:$A$38,'FX rates'!$B$2:$B$38)) -> 388756.13 | AE11: =(AC11-AA11)/AA11 -> 0.1 | AF11: =X11-L11 -> 126652.68 | AG11: =AB11-AA11 -> 30492.023 | AH11: =AC11/X11 -> 0.12748354 | AI11: =U11*(_xlfn.XLOOKUP(K11,'FX rates'!$A$2:$A$38,'FX rates'!$B$2:$B$38)) -> 0 | AJ11: =Q11*(_xlfn.XLOOKUP(K11,'FX rates'!$A$2:$A$38,'FX rates'!$B$2:$B$38)) -> 0 | AK11: =R11*(_xlfn.XLOOKUP(K11,'FX rates'!$A$2:$A$38,'FX rates'!$B$2:$B$38)) -> 0 | AP11: =M11/L11 -> 0.18885033 | AQ11: =O11/L11 -> 0 | AR11: =X11*(1+AP11) -> 1656281.9 | AS11: =IF(AQ11>0,X11*(1+AQ11),"0") -> 0 | AT11: =AD11*(0.9) -> 349880.51 | AU11: =AD11-AT11 -> 38875.613
A12: Employee 1007 | B12: Managing Director | C12: Princeton | D12: United States of America | E12: Americas | F12: 43615 | G12: 44896 | H12: Regional Platform | I12: A | J12: X | K12: USD | L12: 235400 | M12: 445500 | N12: 0 | O12: 0 | P12: =M12+N12+O12 -> 445500 | Q12: 0 | R12: 0 | S12: 0 | T12: =+Q12+R12+S12 -> 0 | U12: 318000 | V12: =L12+P12+T12+U12 -> 998900 | W12: USD | X12: 242462 | Y12: =X12+AR12+AS12 -> 943789 | Z12: {=_xlfn.IFS(YEARFRAC(F12,G12)<1,"<1 Year",YEARFRAC(F12,G12)<=5,"1-5 Years",YEARFRAC(F12,G12)>5,">5 Years")} -> 1-5 Years | AA12: =L12*(_xlfn.XLOOKUP(K12,'FX rates'!$A$2:$A$38,'FX rates'!$B$2:$B$38)) -> 235400 | AB12: =V12*(_xlfn.XLOOKUP(K12,'FX rates'!$A$2:$A$38,'FX rates'!$B$2:$B$38)) -> 998900 | AC12: =X12*(_xlfn.XLOOKUP(W12,'FX rates'!$A$2:$A$38,'FX rates'!$B$2:$B$38)) -> 242462 | AD12: =Y12*(_xlfn.XLOOKUP(W12,'FX rates'!$A$2:$A$38,'FX rates'!$B$2:$B$38)) -> 943789 | AE12: =(AC12-AA12)/AA12 -> 0.03 | AF12: =X12-L12 -> 7062 | AG12: =AB12-AA12 -> 763500 | AH12: =AC12/X12 -> 1 | AI12: =U12*(_xlfn.XLOOKUP(K12,'FX rates'!$A$2:$A$38,'FX rates'!$B$2:$B$38)) -> 318000 | AJ12: =Q12*(_xlfn.XLOOKUP(K12,'FX rates'!$A$2:$A$38,'FX rates'!$B$2:$B$38)) -> 0 | AK12: =R12*(_xlfn.XLOOKUP(K12,'FX rates'!$A$2:$A$38,'FX rates'!$B$2:$B$38)) -> 0 | AP12: =M12/L12 -> 1.8925234 | AQ12: =O12/L12 -> 0 | AR12: =X12*(1+AP12) -> 701327 | AS12: =IF(AQ12>0,X12*(1+AQ12),"0") -> 0 | AT12: =AD12*(0.9) -> 849410.1 | AU12: =AD12-AT12 -> 94378.9
A13: Employee 1008 | B13: Vice President | C13: Edinburgh | D13: United Kingdom | E13: EMEA | F13: 43622 | G13: 44896 | H13: Operating Platform | I13: L | J13: T | K13: GBP | L13: 76715.1 | M13: 12487.2 | N13: 0 | O13: 0 | P13: =M13+N13+O13 -> 12487.2 | Q13: 0 | R13: 0 | S13: 0 | T13: =+Q13+R13+S13 -> 0 | U13: 0 | V13: =L13+P13+T13+U13 -> 89202.3 | W13: GBP | X13: 85920.912 | Y13: =X13+AR13+AS13 -> 185827.49 | Z13: {=_xlfn.IFS(YEARFRAC(F13,G13)<1,"<1 Year",YEARFRAC(F13,G13)<=5,"1-5 Years",YEARFRAC(F13,G13)>5,">5 Years")} -> 1-5 Years | AA13: =L13*(_xlfn.XLOOKUP(K13,'FX rates'!$A$2:$A$38,'FX rates'!$B$2:$B$38)) -> 102080.95 | AB13: =V13*(_xlfn.XLOOKUP(K13,'FX rates'!$A$2:$A$38,'FX rates'!$B$2:$B$38)) -> 118697.04 | AC13: =X13*(_xlfn.XLOOKUP(W13,'FX rates'!$A$2:$A$38,'FX rates'!$B$2:$B$38)) -> 114330.66 | AD13: =Y13*(_xlfn.XLOOKUP(W13,'FX rates'!$A$2:$A$38,'FX rates'!$B$2:$B$38)) -> 247271.35 | AE13: =(AC13-AA13)/AA13 -> 0.12 | AF13: =X13-L13 -> 9205.812 | AG13: =AB13-AA13 -> 16616.093 | AH13: =AC13/X13 -> 1.33065 | AI13: =U13*(_xlfn.XLOOKUP(K13,'FX rates'!$A$2:$A$38,'FX rates'!$B$2:$B$38)) -> 0 | AJ13: =Q13*(_xlfn.XLOOKUP(K13,'FX rates'!$A$2:$A$38,'FX rates'!$B$2:$B$38)) -> 0 | AK13: =R13*(_xlfn.XLOOKUP(K13,'FX rates'!$A$2:$A$38,'FX rates'!$B$2:$B$38)) -> 0 | AP13: =M13/L13 -> 0.16277369 | AQ13: =O13/L13 -> 0 | AR13: =X13*(1+AP13) -> 99906.576 | AS13: =IF(AQ13>0,X13*(1+AQ13),"0") -> 0 | AT13: =AD13*(0.9) -> 222544.21 | AU13: =AD13-AT13 -> 24727.135
A14: Employee 1009 | B14: Managing Director | C14: New York | D14: United States of America | E14: Americas | F14: 43622 | G14: 44896 | H14: Corporate and Risk Platform | I14: T | J14: H | K14: USD | L14: 258940 | M14: 303490 | N14: 0 | O14: 0 | P14: =M14+N14+O14 -> 303490 | Q14: 0 | R14: 0 | S14: 0 | T14: =+Q14+R14+S14 -> 0 | U14: 0 | V14: =L14+P14+T14+U14 -> 562430 | W14: USD | X14: 266708.2 | Y14: =X14+AR14+AS14 -> 846011.1 | Z14: {=_xlfn.IFS(YEARFRAC(F14,G14)<1,"<1 Year",YEARFRAC(F14,G14)<=5,"1-5 Years",YEARFRAC(F14,G14)>5,">5 Years")} -> 1-5 Years | AA14: =L14*(_xlfn.XLOOKUP(K14,'FX rates'!$A$2:$A$38,'FX rates'!$B$2:$B$38)) -> 258940 | AB14: =V14*(_xlfn.XLOOKUP(K14,'FX rates'!$A$2:$A$38,'FX rates'!$B$2:$B$38)) -> 562430 | AC14: =X14*(_xlfn.XLOOKUP(W14,'FX rates'!$A$2:$A$38,'FX rates'!$B$2:$B$38)) -> 266708.2 | AD14: =Y14*(_xlfn.XLOOKUP(W14,'FX rates'!$A$2:$A$38,'FX rates'!$B$2:$B$38)) -> 846011.1 | AE14: =(AC14-AA14)/AA14 -> 0.03 | AF14: =X14-L14 -> 7768.2 | AG14: =AB14-AA14 -> 303490 | AH14: =AC14/X14 -> 1 | AI14: =U14*(_xlfn.XLOOKUP(K14,'FX rates'!$A$2:$A$38,'FX rates'!$B$2:$B$38)) -> 0 | AJ14: =Q14*(_xlfn.XLOOKUP(K14,'FX rates'!$A$2:$A$38,'FX rates'!$B$2:$B$38)) -> 0 | AK14: =R14*(_xlfn.XLOOKUP(K14,'FX rates'!$A$2:$A$38,'FX rates'!$B$2:$B$38)) -> 0 | AP14: =M14/L14 -> 1.1720476 | AQ14: =O14/L14 -> 0 | AR14: =X14*(1+AP14) -> 579302.9 | AS14: =IF(AQ14>0,X14*(1+AQ14),"0") -> 0 | AT14: =AD14*(0.9) -> 761409.99 | AU14: =AD14-AT14 -> 84601.11
... A1122: Employee 206 | B1122: Vice President | C1122: London | D1122: United Kingdom | E1122: EMEA | F1122: 41491 | G1122: 44896 | H1122: Operating Platform | I1122: V | J1122: U | K1122: GBP | L1122: 101832.5 | M1122: 12804 | N1122: 0 | O1122: 0 | P1122: =M1122+N1122+O1122 -> 12804 | Q1122: 0 | R1122: 0 | S1122: 0 | T1122: =+Q1122+R1122+S1122 -> 0 | U1122: 0 | V1122: =L1122+P1122+T1122+U1122 -> 114636.5 | W1122: GBP | X1122: 109979.1 | Y1122: =X1122+AR1122+AS1122 -> 233786.52 | Z1122: {=_xlfn.IFS(YEARFRAC(F1122,G1122)<1,"<1 Year",YEARFRAC(F1122,G1122)<=5,"1-5 Years",YEARFRAC(F1122,G1122)>5,">5 Years")} -> >5 Years | AA1122: =L1122*(_xlfn.XLOOKUP(K1122,'FX rates'!$A$2:$A$38,'FX rates'!$B$2:$B$38)) -> 135503.42 | AB1122: =V1122*(_xlfn.XLOOKUP(K1122,'FX rates'!$A$2:$A$38,'FX rates'!$B$2:$B$38)) -> 152541.06 | AC1122: =X1122*(_xlfn.XLOOKUP(W1122,'FX rates'!$A$2:$A$38,'FX rates'!$B$2:$B$38)) -> 146343.69 | AD1122: =Y1122*(_xlfn.XLOOKUP(W1122,'FX rates'!$A$2:$A$38,'FX rates'!$B$2:$B$38)) -> 311088.03 | AE1122: =(AC1122-AA1122)/AA1122 -> 0.08 | AF1122: =X1122-L1122 -> 8146.6 | AG1122: =AB1122-AA1122 -> 17037.643 | AH1122: =AC1122/X1122 -> 1.33065 | AI1122: =U1122*(_xlfn.XLOOKUP(K1122,'FX rates'!$A$2:$A$38,'FX rates'!$B$2:$B$38)) -> 0 | AJ1122: =Q1122*(_xlfn.XLOOKUP(K1122,'FX rates'!$A$2:$A$38,'FX rates'!$B$2:$B$38)) -> 0 | AK1122: =R1122*(_xlfn.XLOOKUP(K1122,'FX rates'!$A$2:$A$38,'FX rates'!$B$2:$B$38)) -> 0 | AP1122: =M1122/L1122 -> 0.12573589 | AQ1122: =O1122/L1122 -> 0 | AR1122: =X1122*(1+AP1122) -> 123807.42 | AS1122: =IF(AQ1122>0,X1122*(1+AQ1122),"0") -> 0 | AT1122: =AD1122*(0.9) -> 279979.23 | AU1122: =AD1122-AT1122 -> 31108.803
A1123: Employee 207 | B1123: Director | D1123: United Arab Emirates | E1123: EMEA | F1123: 41485 | G1123: 44896 | H1123: Client Businesses Platform | I1123: U | J1123: S | K1123: AED | L1123: 738100 | M1123: 403056.5 | N1123: 0 | O1123: 0 | P1123: =M1123+N1123+O1123 -> 403056.5 | Q1123: 0 | R1123: 0 | S1123: 315120 | T1123: =+Q1123+R1123+S1123 -> 315120 | U1123: 0 | V1123: =L1123+P1123+T1123+U1123 -> 1456276.5 | W1123: AED | X1123: 775005 | Y1123: =X1123+AR1123+AS1123 -> 1973219.3 | Z1123: {=_xlfn.IFS(YEARFRAC(F1123,G1123)<1,"<1 Year",YEARFRAC(F1123,G1123)<=5,"1-5 Years",YEARFRAC(F1123,G1123)>5,">5 Years")} -> >5 Years | AA1123: =L1123*(_xlfn.XLOOKUP(K1123,'FX rates'!$A$2:$A$38,'FX rates'!$B$2:$B$38)) -> 200944.69 | AB1123: =V1123*(_xlfn.XLOOKUP(K1123,'FX rates'!$A$2:$A$38,'FX rates'!$B$2:$B$38)) -> 396465.3 | AC1123: =X1123*(_xlfn.XLOOKUP(W1123,'FX rates'!$A$2:$A$38,'FX rates'!$B$2:$B$38)) -> 210991.93 | AD1123: =Y1123*(_xlfn.XLOOKUP(W1123,'FX rates'!$A$2:$A$38,'FX rates'!$B$2:$B$38)) -> 537200.86 | AE1123: =(AC1123-AA1123)/AA1123 -> 0.05 | AF1123: =X1123-L1123 -> 36905 | AG1123: =AB1123-AA1123 -> 195520.6 | AH1123: =AC1123/X1123 -> 0.27224589 | AI1123: =U1123*(_xlfn.XLOOKUP(K1123,'FX rates'!$A$2:$A$38,'FX rates'!$B$2:$B$38)) -> 0 | AJ1123: =Q1123*(_xlfn.XLOOKUP(K1123,'FX rates'!$A$2:$A$38,'FX rates'!$B$2:$B$38)) -> 0 | AK1123: =R1123*(_xlfn.XLOOKUP(K1123,'FX rates'!$A$2:$A$38,'FX rates'!$B$2:$B$38)) -> 0 | AP1123: =M1123/L1123 -> 0.54607303 | AQ1123: =O1123/L1123 -> 0 | AR1123: =X1123*(1+AP1123) -> 1198214.3 | AS1123: =IF(AQ1123>0,X1123*(1+AQ1123),"0") -> 0 | AT1123: =AD1123*(0.9) -> 483480.77 | AU1123: =AD1123-AT1123 -> 53720.086
A1124: Employee 208 | B1124: Vice President | C1124: Princeton | D1124: United States of America | E1124: Americas | F1124: 41505 | G1124: 44896 | H1124: ETF and Index Investments Platform | I1124: A | J1124: Y | K1124: USD | L1124: 130295 | M1124: 51150 | N1124: 0 | O1124: 0 | P1124: =M1124+N1124+O1124 -> 51150 | Q1124: 0 | R1124: 0 | S1124: 0 | T1124: =+Q1124+R1124+S1124 -> 0 | U1124: 0 | V1124: =L1124+P1124+T1124+U1124 -> 181445 | W1124: USD | X1124: 142021.55 | Y1124: =X1124+AR1124+AS1124 -> 339796.6 | Z1124: {=_xlfn.IFS(YEARFRAC(F1124,G1124)<1,"<1 Year",YEARFRAC(F1124,G1124)<=5,"1-5 Years",YEARFRAC(F1124,G1124)>5,">5 Years")} -> >5 Years | AA1124: =L1124*(_xlfn.XLOOKUP(K1124,'FX rates'!$A$2:$A$38,'FX rates'!$B$2:$B$38)) -> 130295 | AB1124: =V1124*(_xlfn.XLOOKUP(K1124,'FX rates'!$A$2:$A$38,'FX rates'!$B$2:$B$38)) -> 181445 | AC1124: =X1124*(_xlfn.XLOOKUP(W1124,'FX rates'!$A$2:$A$38,'FX rates'!$B$2:$B$38)) -> 142021.55 | AD1124: =Y1124*(_xlfn.XLOOKUP(W1124,'FX rates'!$A$2:$A$38,'FX rates'!$B$2:$B$38)) -> 339796.6 | AE1124: =(AC1124-AA1124)/AA1124 -> 0.09 | AF1124: =X1124-L1124 -> 11726.55 | AG1124: =AB1124-AA1124 -> 51150 | AH1124: =AC1124/X1124 -> 1 | AI1124: =U1124*(_xlfn.XLOOKUP(K1124,'FX rates'!$A$2:$A$38,'FX rates'!$B$2:$B$38)) -> 0 | AJ1124: =Q1124*(_xlfn.XLOOKUP(K1124,'FX rates'!$A$2:$A$38,'FX rates'!$B$2:$B$38)) -> 0 | AK1124: =R1124*(_xlfn.XLOOKUP(K1124,'FX rates'!$A$2:$A$38,'FX rates'!$B$2:$B$38)) -> 0 | AP1124: =M1124/L1124 -> 0.3925707 | AQ1124: =O1124/L1124 -> 0 | AR1124: =X1124*(1+AP1124) -> 197775.05 | AS1124: =IF(AQ1124>0,X1124*(1+AQ1124),"0") -> 0 | AT1124: =AD1124*(0.9) -> 305816.94 | AU1124: =AD1124-AT1124 -> 33979.66
A1125: Employee 209 | B1125: Vice President | C1125: Frankfurt | D1125: Germany | E1125: EMEA | F1125: 41820 | G1125: 44896 | H1125: Client Businesses Platform | I1125: F | J1125: Q | K1125: EUR | L1125: 107910 | M1125: 16495.6 | N1125: 0 | O1125: 0 | P1125: =M1125+N1125+O1125 -> 16495.6 | Q1125: 0 | R1125: 0 | S1125: 0 | T1125: =+Q1125+R1125+S1125 -> 0 | U1125: 0 | V1125: =L1125+P1125+T1125+U1125 -> 124405.6 | W1125: EUR | X1125: 123017.4 | Y1125: =X1125+AR1125+AS1125 -> 264839.78 | Z1125: {=_xlfn.IFS(YEARFRAC(F1125,G1125)<1,"<1 Year",YEARFRAC(F1125,G1125)<=5,"1-5 Years",YEARFRAC(F1125,G1125)>5,">5 Years")} -> >5 Years | AA1125: =L1125*(_xlfn.XLOOKUP(K1125,'FX rates'!$A$2:$A$38,'FX rates'!$B$2:$B$38)) -> 125963.34 | AB1125: =V1125*(_xlfn.XLOOKUP(K1125,'FX rates'!$A$2:$A$38,'FX rates'!$B$2:$B$38)) -> 145218.66 | AC1125: =X1125*(_xlfn.XLOOKUP(W1125,'FX rates'!$A$2:$A$38,'FX rates'!$B$2:$B$38)) -> 143598.21 | AD1125: =Y1125*(_xlfn.XLOOKUP(W1125,'FX rates'!$A$2:$A$38,'FX rates'!$B$2:$B$38)) -> 309147.48 | AE1125: =(AC1125-AA1125)/AA1125 -> 0.14 | AF1125: =X1125-L1125 -> 15107.4 | AG1125: =AB1125-AA1125 -> 19255.314 | AH1125: =AC1125/X1125 -> 1.1673 | AI1125: =U1125*(_xlfn.XLOOKUP(K1125,'FX rates'!$A$2:$A$38,'FX rates'!$B$2:$B$38)) -> 0 | AJ1125: =Q1125*(_xlfn.XLOOKUP(K1125,'FX rates'!$A$2:$A$38,'FX rates'!$B$2:$B$38)) -> 0 | AK1125: =R1125*(_xlfn.XLOOKUP(K1125,'FX rates'!$A$2:$A$38,'FX rates'!$B$2:$B$38)) -> 0 | AP1125: =M1125/L1125 -> 0.15286442 | AQ1125: =O1125/L1125 -> 0 | AR1125: =X1125*(1+AP1125) -> 141822.38 | AS1125: =IF(AQ1125>0,X1125*(1+AQ1125),"0") -> 0 | AT1125: =AD1125*(0.9) -> 278232.73 | AU1125: =AD1125-AT1125 -> 30914.748
A1126: Employee 21 | B1126: Vice President | C1126: London | D1126: United Kingdom | E1126: EMEA | F1126: 39335 | G1126: 44896 | H1126: Regional Platform | I1126: K | J1126: Y | K1126: GBP | L1126: 77748 | M1126: 20146.5 | N1126: 0 | O1126: 0 | P1126: =M1126+N1126+O1126 -> 20146.5 | Q1126: 0 | R1126: 0 | S1126: 0 | T1126: =+Q1126+R1126+S1126 -> 0 | U1126: 0 | V1126: =L1126+P1126+T1126+U1126 -> 97894.5 | W1126: GBP | X1126: 87077.76 | Y1126: =X1126+AR1126+AS1126 -> 196719.6 | Z1126: {=_xlfn.IFS(YEARFRAC(F1126,G1126)<1,"<1 Year",YEARFRAC(F1126,G1126)<=5,"1-5 Years",YEARFRAC(F1126,G1126)>5,">5 Years")} -> >5 Years | AA1126: =L1126*(_xlfn.XLOOKUP(K1126,'FX rates'!$A$2:$A$38,'FX rates'!$B$2:$B$38)) -> 103455.38 | AB1126: =V1126*(_xlfn.XLOOKUP(K1126,'FX rates'!$A$2:$A$38,'FX rates'!$B$2:$B$38)) -> 130263.32 | AC1126: =X1126*(_xlfn.XLOOKUP(W1126,'FX rates'!$A$2:$A$38,'FX rates'!$B$2:$B$38)) -> 115870.02 | AD1126: =Y1126*(_xlfn.XLOOKUP(W1126,'FX rates'!$A$2:$A$38,'FX rates'!$B$2:$B$38)) -> 261764.94 | AE1126: =(AC1126-AA1126)/AA1126 -> 0.12 | AF1126: =X1126-L1126 -> 9329.76 | AG1126: =AB1126-AA1126 -> 26807.94 | AH1126: =AC1126/X1126 -> 1.33065 | AI1126: =U1126*(_xlfn.XLOOKUP(K1126,'FX rates'!$A$2:$A$38,'FX rates'!$B$2:$B$38)) -> 0 | AJ1126: =Q1126*(_xlfn.XLOOKUP(K1126,'FX rates'!$A$2:$A$38,'FX rates'!$B$2:$B$38)) -> 0 | AK1126: =R1126*(_xlfn.XLOOKUP(K1126,'FX rates'!$A$2:$A$38,'FX rates'!$B$2:$B$38)) -> 0 | AP1126: =M1126/L1126 -> 0.25912564 | AQ1126: =O1126/L1126 -> 0 | AR1126: =X1126*(1+AP1126) -> 109641.84 | AS1126: =IF(AQ1126>0,X1126*(1+AQ1126),"0") -> 0 | AT1126: =AD1126*(0.9) -> 235588.44 | AU1126: =AD1126-AT1126 -> 26176.494
A1127: Employee 210 | B1127: Vice President | C1127: Gurgaon | D1127: India | E1127: Asia-Pacific | F1127: 41505 | G1127: 44896 | H1127: Corporate and Risk Platform | I1127: O | J1127: H | K1127: INR | L1127: 4284280 | M1127: 1044384 | N1127: 0 | O1127: 0 | P1127: =M1127+N1127+O1127 -> 1044384 | Q1127: 0 | R1127: 0 | S1127: 0 | T1127: =+Q1127+R1127+S1127 -> 0 | U1127: 0 | V1127: =L1127+P1127+T1127+U1127 -> 5328664 | W1127: INR | X1127: 4755550.8 | Y1127: =X1127+AR1127+AS1127 -> 10670368 | Z1127: {=_xlfn.IFS(YEARFRAC(F1127,G1127)<1,"<1 Year",YEARFRAC(F1127,G1127)<=5,"1-5 Years",YEARFRAC(F1127,G1127)>5,">5 Years")} -> >5 Years | AA1127: =L1127*(_xlfn.XLOOKUP(K1127,'FX rates'!$A$2:$A$38,'FX rates'!$B$2:$B$38)) -> 63487.274 | AB1127: =V1127*(_xlfn.XLOOKUP(K1127,'FX rates'!$A$2:$A$38,'FX rates'!$B$2:$B$38)) -> 78963.642 | AC1127: =X1127*(_xlfn.XLOOKUP(W1127,'FX rates'!$A$2:$A$38,'FX rates'!$B$2:$B$38)) -> 70470.875 | AD1127: =Y1127*(_xlfn.XLOOKUP(W1127,'FX rates'!$A$2:$A$38,'FX rates'!$B$2:$B$38)) -> 158120.52 | AE1127: =(AC1127-AA1127)/AA1127 -> 0.11 | AF1127: =X1127-L1127 -> 471270.8 | AG1127: =AB1127-AA1127 -> 15476.368 | AH1127: =AC1127/X1127 -> 0.014818657 | AI1127: =U1127*(_xlfn.XLOOKUP(K1127,'FX rates'!$A$2:$A$38,'FX rates'!$B$2:$B$38)) -> 0 | AJ1127: =Q1127*(_xlfn.XLOOKUP(K1127,'FX rates'!$A$2:$A$38,'FX rates'!$B$2:$B$38)) -> 0 | AK1127: =R1127*(_xlfn.XLOOKUP(K1127,'FX rates'!$A$2:$A$38,'FX rates'!$B$2:$B$38)) -> 0 | AP1127: =M1127/L1127 -> 0.24377118 | AQ1127: =O1127/L1127 -> 0 | AR1127: =X1127*(1+AP1127) -> 5914817 | AS1127: =IF(AQ1127>0,X1127*(1+AQ1127),"0") -> 0 | AT1127: =AD1127*(0.9) -> 142308.47 | AU1127: =AD1127-AT1127 -> 15812.052
A1128: Employee 211 | B1128: Managing Director | C1128: Milan | D1128: Italy | E1128: EMEA | F1128: 41505 | G1128: 44896 | H1128: Client Businesses Platform | I1128: H | J1128: N | K1128: EUR | L1128: 250800 | M1128: 223245 | N1128: 0 | O1128: 0 | P1128: =M1128+N1128+O1128 -> 223245 | Q1128: 0 | R1128: 0 | S1128: 0 | T1128: =+Q1128+R1128+S1128 -> 0 | U1128: 0 | V1128: =L1128+P1128+T1128+U1128 -> 474045 | W1128: EUR | X1128: 283404 | Y1128: =X1128+AR1128+AS1128 -> 819074.85 | Z1128: {=_xlfn.IFS(YEARFRAC(F1128,G1128)<1,"<1 Year",YEARFRAC(F1128,G1128)<=5,"1-5 Years",YEARFRAC(F1128,G1128)>5,">5 Years")} -> >5 Years | AA1128: =L1128*(_xlfn.XLOOKUP(K1128,'FX rates'!$A$2:$A$38,'FX rates'!$B$2:$B$38)) -> 292758.84 | AB1128: =V1128*(_xlfn.XLOOKUP(K1128,'FX rates'!$A$2:$A$38,'FX rates'!$B$2:$B$38)) -> 553352.73 | AC1128: =X1128*(_xlfn.XLOOKUP(W1128,'FX rates'!$A$2:$A$38,'FX rates'!$B$2:$B$38)) -> 330817.49 | AD1128: =Y1128*(_xlfn.XLOOKUP(W1128,'FX rates'!$A$2:$A$38,'FX rates'!$B$2:$B$38)) -> 956106.07 | AE1128: =(AC1128-AA1128)/AA1128 -> 0.13 | AF1128: =X1128-L1128 -> 32604 | AG1128: =AB1128-AA1128 -> 260593.89 | AH1128: =AC1128/X1128 -> 1.1673 | AI1128: =U1128*(_xlfn.XLOOKUP(K1128,'FX rates'!$A$2:$A$38,'FX rates'!$B$2:$B$38)) -> 0 | AJ1128: =Q1128*(_xlfn.XLOOKUP(K1128,'FX rates'!$A$2:$A$38,'FX rates'!$B$2:$B$38)) -> 0 | AK1128: =R1128*(_xlfn.XLOOKUP(K1128,'FX rates'!$A$2:$A$38,'FX rates'!$B$2:$B$38)) -> 0 | AP1128: =M1128/L1128 -> 0.89013158 | AQ1128: =O1128/L1128 -> 0 | AR1128: =X1128*(1+AP1128) -> 535670.85 | AS1128: =IF(AQ1128>0,X1128*(1+AQ1128),"0") -> 0 | AT1128: =AD1128*(0.9) -> 860495.47 | AU1128: =AD1128-AT1128 -> 95610.607
A1129: Employee 212 | B1129: Associate | C1129: San Francisco | D1129: United States of America | E1129: Americas | F1129: 41526 | G1129: 44896 | H1129: Operating Platform | I1129: B | J1129: B | K1129: USD | L1129: 156634.5 | M1129: 16830 | N1129: 0 | O1129: 0 | P1129: =M1129+N1129+O1129 -> 16830 | Q1129: 0 | R1129: 3994 | S1129: 0 | T1129: =+Q1129+R1129+S1129 -> 3994 | U1129: 0 | V1129: =L1129+P1129+T1129+U1129 -> 177458.5 | W1129: USD | X1129: 169165.26 | Y1129: =X1129+AR1129+AS1129 -> 356506.92 | Z1129: {=_xlfn.IFS(YEARFRAC(F1129,G1129)<1,"<1 Year",YEARFRAC(F1129,G1129)<=5,"1-5 Years",YEARFRAC(F1129,G1129)>5,">5 Years")} -> >5 Years | AA1129: =L1129*(_xlfn.XLOOKUP(K1129,'FX rates'!$A$2:$A$38,'FX rates'!$B$2:$B$38)) -> 156634.5 | AB1129: =V1129*(_xlfn.XLOOKUP(K1129,'FX rates'!$A$2:$A$38,'FX rates'!$B$2:$B$38)) -> 177458.5 | AC1129: =X1129*(_xlfn.XLOOKUP(W1129,'FX rates'!$A$2:$A$38,'FX rates'!$B$2:$B$38)) -> 169165.26 | AD1129: =Y1129*(_xlfn.XLOOKUP(W1129,'FX rates'!$A$2:$A$38,'FX rates'!$B$2:$B$38)) -> 356506.92 | AE1129: =(AC1129-AA1129)/AA1129 -> 0.08 | AF1129: =X1129-L1129 -> 12530.76 | AG1129: =AB1129-AA1129 -> 20824 | AH1129: =AC1129/X1129 -> 1 | AI1129: =U1129*(_xlfn.XLOOKUP(K1129,'FX rates'!$A$2:$A$38,'FX rates'!$B$2:$B$38)) -> 0 | AJ1129: =Q1129*(_xlfn.XLOOKUP(K1129,'FX rates'!$A$2:$A$38,'FX rates'!$B$2:$B$38)) -> 0 | AK1129: =R1129*(_xlfn.XLOOKUP(K1129,'FX rates'!$A$2:$A$38,'FX rates'!$B$2:$B$38)) -> 3994 | AP1129: =M1129/L1129 -> 0.10744759 | AQ1129: =O1129/L1129 -> 0 | AR1129: =X1129*(1+AP1129) -> 187341.66 | AS1129: =IF(AQ1129>0,X1129*(1+AQ1129),"0") -> 0 | AT1129: =AD1129*(0.9) -> 320856.23 | AU1129: =AD1129-AT1129 -> 35650.692
A1130: Employee 213 | B1130: Vice President | C1130: Singapore | D1130: Singapore | E1130: Asia-Pacific | F1130: 41526 | G1130: 44896 | H1130: Client Businesses Platform | I1130: H | J1130: O | K1130: SGD | L1130: 202716.8 | M1130: 40672.5 | N1130: 0 | O1130: 0 | P1130: =M1130+N1130+O1130 -> 40672.5 | Q1130: 0 | R1130: 0 | S1130: 0 | T1130: =+Q1130+R1130+S1130 -> 0 | U1130: 0 | V1130: =L1130+P1130+T1130+U1130 -> 243389.3 | W1130: SGD | X1130: 227042.82 | Y1130: =X1130+AR1130+AS1130 -> 499638.83 | Z1130: {=_xlfn.IFS(YEARFRAC(F1130,G1130)<1,"<1 Year",YEARFRAC(F1130,G1130)<=5,"1-5 Years",YEARFRAC(F1130,G1130)>5,">5 Years")} -> >5 Years | AA1130: =L1130*(_xlfn.XLOOKUP(K1130,'FX rates'!$A$2:$A$38,'FX rates'!$B$2:$B$38)) -> 151569.63 | AB1130: =V1130*(_xlfn.XLOOKUP(K1130,'FX rates'!$A$2:$A$38,'FX rates'!$B$2:$B$38)) -> 181980.11 | AC1130: =X1130*(_xlfn.XLOOKUP(W1130,'FX rates'!$A$2:$A$38,'FX rates'!$B$2:$B$38)) -> 169757.98 | AD1130: =Y1130*(_xlfn.XLOOKUP(W1130,'FX rates'!$A$2:$A$38,'FX rates'!$B$2:$B$38)) -> 373575.71 | AE1130: =(AC1130-AA1130)/AA1130 -> 0.12 | AF1130: =X1130-L1130 -> 24326.016 | AG1130: =AB1130-AA1130 -> 30410.483 | AH1130: =AC1130/X1130 -> 0.7476915 | AI1130: =U1130*(_xlfn.XLOOKUP(K1130,'FX rates'!$A$2:$A$38,'FX rates'!$B$2:$B$38)) -> 0 | AJ1130: =Q1130*(_xlfn.XLOOKUP(K1130,'FX rates'!$A$2:$A$38,'FX rates'!$B$2:$B$38)) -> 0 | AK1130: =R1130*(_xlfn.XLOOKUP(K1130,'FX rates'!$A$2:$A$38,'FX rates'!$B$2:$B$38)) -> 0 | AP1130: =M1130/L1130 -> 0.20063705 | AQ1130: =O1130/L1130 -> 0 | AR1130: =X1130*(1+AP1130) -> 272596.02 | AS1130: =IF(AQ1130>0,X1130*(1+AQ1130),"0") -> 0 | AT1130: =AD1130*(0.9) -> 336218.14 | AU1130: =AD1130-AT1130 -> 37357.571
A1131: Employee 214 | B1131: Vice President | C1131: Philadelphia | D1131: United States of America | E1131: Americas | F1131: 41568 | G1131: 44896 | H1131: Investments Platform | I1131: J | J1131: O | K1131: USD | L1131: 139150 | M1131: 19800 | N1131: 0 | O1131: 0 | P1131: =M1131+N1131+O1131 -> 19800 | Q1131: 0 | R1131: 0 | S1131: 0 | T1131: =+Q1131+R1131+S1131 -> 0 | U1131: 0 | V1131: =L1131+P1131+T1131+U1131 -> 158950 | W1131: USD | X1131: 147499 | Y1131: =X1131+AR1131+AS1131 -> 315986 | Z1131: {=_xlfn.IFS(YEARFRAC(F1131,G1131)<1,"<1 Year",YEARFRAC(F1131,G1131)<=5,"1-5 Years",YEARFRAC(F1131,G1131)>5,">5 Years")} -> >5 Years | AA1131: =L1131*(_xlfn.XLOOKUP(K1131,'FX rates'!$A$2:$A$38,'FX rates'!$B$2:$B$38)) -> 139150 | AB1131: =V1131*(_xlfn.XLOOKUP(K1131,'FX rates'!$A$2:$A$38,'FX rates'!$B$2:$B$38)) -> 158950 | AC1131: =X1131*(_xlfn.XLOOKUP(W1131,'FX rates'!$A$2:$A$38,'FX rates'!$B$2:$B$38)) -> 147499 | AD1131: =Y1131*(_xlfn.XLOOKUP(W1131,'FX rates'!$A$2:$A$38,'FX rates'!$B$2:$B$38)) -> 315986 | AE1131: =(AC1131-AA1131)/AA1131 -> 0.06 | AF1131: =X1131-L1131 -> 8349 | AG1131: =AB1131-AA1131 -> 19800 | AH1131: =AC1131/X1131 -> 1 | AI1131: =U1131*(_xlfn.XLOOKUP(K1131,'FX rates'!$A$2:$A$38,'FX rates'!$B$2:$B$38)) -> 0 | AJ1131: =Q1131*(_xlfn.XLOOKUP(K1131,'FX rates'!$A$2:$A$38,'FX rates'!$B$2:$B$38)) -> 0 | AK1131: =R1131*(_xlfn.XLOOKUP(K1131,'FX rates'!$A$2:$A$38,'FX rates'!$B$2:$B$38)) -> 0 | AP1131: =M1131/L1131 -> 0.14229249 | AQ1131: =O1131/L1131 -> 0 | AR1131: =X1131*(1+AP1131) -> 168487 | AS1131: =IF(AQ1131>0,X1131*(1+AQ1131),"0") -> 0 | AT1131: =AD1131*(0.9) -> 284387.4 | AU1131: =AD1131-AT1131 -> 31598.6
A1132: Employee 215 | B1132: Director | C1132: London | D1132: United Kingdom | E1132: EMEA | F1132: 41561 | G1132: 44896 | H1132: Investments Platform | I1132: Q | J1132: W | K1132: GBP | L1132: 120054 | M1132: 94435 | N1132: 0 | O1132: 0 | P1132: =M1132+N1132+O1132 -> 94435 | Q1132: 0 | R1132: 0 | S1132: 0 | T1132: =+Q1132+R1132+S1132 -> 0 | U1132: 0 | V1132: =L1132+P1132+T1132+U1132 -> 214489 | W1132: GBP | X1132: 122455.08 | Y1132: =X1132+AR1132+AS1132 -> 341233.86 | Z1132: {=_xlfn.IFS(YEARFRAC(F1132,G1132)<1,"<1 Year",YEARFRAC(F1132,G1132)<=5,"1-5 Years",YEARFRAC(F1132,G1132)>5,">5 Years")} -> >5 Years | AA1132: =L1132*(_xlfn.XLOOKUP(K1132,'FX rates'!$A$2:$A$38,'FX rates'!$B$2:$B$38)) -> 159749.86 | AB1132: =V1132*(_xlfn.XLOOKUP(K1132,'FX rates'!$A$2:$A$38,'FX rates'!$B$2:$B$38)) -> 285409.79 | AC1132: =X1132*(_xlfn.XLOOKUP(W1132,'FX rates'!$A$2:$A$38,'FX rates'!$B$2:$B$38)) -> 162944.85 | AD1132: =Y1132*(_xlfn.XLOOKUP(W1132,'FX rates'!$A$2:$A$38,'FX rates'!$B$2:$B$38)) -> 454062.84 | AE1132: =(AC1132-AA1132)/AA1132 -> 0.02 | AF1132: =X1132-L1132 -> 2401.08 | AG1132: =AB1132-AA1132 -> 125659.93 | AH1132: =AC1132/X1132 -> 1.33065 | AI1132: =U1132*(_xlfn.XLOOKUP(K1132,'FX rates'!$A$2:$A$38,'FX rates'!$B$2:$B$38)) -> 0 | AJ1132: =Q1132*(_xlfn.XLOOKUP(K1132,'FX rates'!$A$2:$A$38,'FX rates'!$B$2:$B$38)) -> 0 | AK1132: =R1132*(_xlfn.XLOOKUP(K1132,'FX rates'!$A$2:$A$38,'FX rates'!$B$2:$B$38)) -> 0 | AP1132: =M1132/L1132 -> 0.78660436 | AQ1132: =O1132/L1132 -> 0 | AR1132: =X1132*(1+AP1132) -> 218778.78 | AS1132: =IF(AQ1132>0,X1132*(1+AQ1132),"0") -> 0 | AT1132: =AD1132*(0.9) -> 408656.55 | AU1132: =AD1132-AT1132 -> 45406.284
A1133: Employee 216 | B1133: Director | C1133: New York | D1133: United States of America | E1133: Americas | F1133: 41561 | G1133: 44896 | H1133: Operating Platform | I1133: D | J1133: U | K1133: USD | L1133: 215820 | M1133: 268840 | N1133: 0 | O1133: 0 | P1133: =M1133+N1133+O1133 -> 268840 | Q1133: 0 | R1133: 0 | S1133: 0 | T1133: =+Q1133+R1133+S1133 -> 0 | U1133: 0 | V1133: =L1133+P1133+T1133+U1133 -> 484660 | W1133: USD | X1133: 248193 | Y1133: =X1133+AR1133+AS1133 -> 805552 | Z1133: {=_xlfn.IFS(YEARFRAC(F1133,G1133)<1,"<1 Year",YEARFRAC(F1133,G1133)<=5,"1-5 Years",YEARFRAC(F1133,G1133)>5,">5 Years")} -> >5 Years | AA1133: =L1133*(_xlfn.XLOOKUP(K1133,'FX rates'!$A$2:$A$38,'FX rates'!$B$2:$B$38)) -> 215820 | AB1133: =V1133*(_xlfn.XLOOKUP(K1133,'FX rates'!$A$2:$A$38,'FX rates'!$B$2:$B$38)) -> 484660 | AC1133: =X1133*(_xlfn.XLOOKUP(W1133,'FX rates'!$A$2:$A$38,'FX rates'!$B$2:$B$38)) -> 248193 | AD1133: =Y1133*(_xlfn.XLOOKUP(W1133,'FX rates'!$A$2:$A$38,'FX rates'!$B$2:$B$38)) -> 805552 | AE1133: =(AC1133-AA1133)/AA1133 -> 0.15 | AF1133: =X1133-L1133 -> 32373 | AG1133: =AB1133-AA1133 -> 268840 | AH1133: =AC1133/X1133 -> 1 | AI1133: =U1133*(_xlfn.XLOOKUP(K1133,'FX rates'!$A$2:$A$38,'FX rates'!$B$2:$B$38)) -> 0 | AJ1133: =Q1133*(_xlfn.XLOOKUP(K1133,'FX rates'!$A$2:$A$38,'FX rates'!$B$2:$B$38)) -> 0 | AK1133: =R1133*(_xlfn.XLOOKUP(K1133,'FX rates'!$A$2:$A$38,'FX rates'!$B$2:$B$38)) -> 0 | AP1133: =M1133/L1133 -> 1.2456677 | AQ1133: =O1133/L1133 -> 0 | AR1133: =X1133*(1+AP1133) -> 557359 | AS1133: =IF(AQ1133>0,X1133*(1+AQ1133),"0") -> 0 | AT1133: =AD1133*(0.9) -> 724996.8 | AU1133: =AD1133-AT1133 -> 80555.2
A1134: Employee 217 | B1134: Director | C1134: Princeton | D1134: United States of America | E1134: Americas | F1134: 41568 | G1134: 44896 | H1134: Operating Platform | I1134: J | J1134: X | K1134: USD | L1134: 185977 | M1134: 55440 | N1134: 0 | O1134: 0 | P1134: =M1134+N1134+O1134 -> 55440 | Q1134: 0 | R1134: 0 | S1134: 0 | T1134: =+Q1134+R1134+S1134 -> 0 | U1134: 0 | V1134: =L1134+P1134+T1134+U1134 -> 241417 | W1134: USD | X1134: 189696.54 | Y1134: =X1134+AR1134+AS1134 -> 435941.88 | Z1134: {=_xlfn.IFS(YEARFRAC(F1134,G1134)<1,"<1 Year",YEARFRAC(F1134,G1134)<=5,"1-5 Years",YEARFRAC(F1134,G1134)>5,">5 Years")} -> >5 Years | AA1134: =L1134*(_xlfn.XLOOKUP(K1134,'FX rates'!$A$2:$A$38,'FX rates'!$B$2:$B$38)) -> 185977 | AB1134: =V1134*(_xlfn.XLOOKUP(K1134,'FX rates'!$A$2:$A$38,'FX rates'!$B$2:$B$38)) -> 241417 | AC1134: =X1134*(_xlfn.XLOOKUP(W1134,'FX rates'!$A$2:$A$38,'FX rates'!$B$2:$B$38)) -> 189696.54 | AD1134: =Y1134*(_xlfn.XLOOKUP(W1134,'FX rates'!$A$2:$A$38,'FX rates'!$B$2:$B$38)) -> 435941.88 | AE1134: =(AC1134-AA1134)/AA1134 -> 0.02 | AF1134: =X1134-L1134 -> 3719.54 | AG1134: =AB1134-AA1134 -> 55440 | AH1134: =AC1134/X1134 -> 1 | AI1134: =U1134*(_xlfn.XLOOKUP(K1134,'FX rates'!$A$2:$A$38,'FX rates'!$B$2:$B$38)) -> 0 | AJ1134: =Q1134*(_xlfn.XLOOKUP(K1134,'FX rates'!$A$2:$A$38,'FX rates'!$B$2:$B$38)) -> 0 | AK1134: =R1134*(_xlfn.XLOOKUP(K1134,'FX rates'!$A$2:$A$38,'FX rates'!$B$2:$B$38)) -> 0 | AP1134: =M1134/L1134 -> 0.29810138 | AQ1134: =O1134/L1134 -> 0 | AR1134: =X1134*(1+AP1134) -> 246245.34 | AS1134: =IF(AQ1134>0,X1134*(1+AQ1134),"0") -> 0 | AT1134: =AD1134*(0.9) -> 392347.69 | AU1134: =AD1134-AT1134 -> 43594.188
A1135: Employee 218 | B1135: Vice President | C1135: New York | D1135: United States of America | E1135: Americas | F1135: 41575 | G1135: 44896 | H1135: Investments Platform | I1135: N | J1135: X | K1135: USD | L1135: 175560 | M1135: 200640 | N1135: 0 | O1135: 0 | P1135: =M1135+N1135+O1135 -> 200640 | Q1135: 0 | R1135: 0 | S1135: 0 | T1135: =+Q1135+R1135+S1135 -> 0 | U1135: 0 | V1135: =L1135+P1135+T1135+U1135 -> 376200 | W1135: USD | X1135: 189604.8 | Y1135: =X1135+AR1135+AS1135 -> 595900.8 | Z1135: {=_xlfn.IFS(YEARFRAC(F1135,G1135)<1,"<1 Year",YEARFRAC(F1135,G1135)<=5,"1-5 Years",YEARFRAC(F1135,G1135)>5,">5 Years")} -> >5 Years | AA1135: =L1135*(_xlfn.XLOOKUP(K1135,'FX rates'!$A$2:$A$38,'FX rates'!$B$2:$B$38)) -> 175560 | AB1135: =V1135*(_xlfn.XLOOKUP(K1135,'FX rates'!$A$2:$A$38,'FX rates'!$B$2:$B$38)) -> 376200 | AC1135: =X1135*(_xlfn.XLOOKUP(W1135,'FX rates'!$A$2:$A$38,'FX rates'!$B$2:$B$38)) -> 189604.8 | AD1135: =Y1135*(_xlfn.XLOOKUP(W1135,'FX rates'!$A$2:$A$38,'FX rates'!$B$2:$B$38)) -> 595900.8 | AE1135: =(AC1135-AA1135)/AA1135 -> 0.08 | AF1135: =X1135-L1135 -> 14044.8 | AG1135: =AB1135-AA1135 -> 200640 | AH1135: =AC1135/X1135 -> 1 | AI1135: =U1135*(_xlfn.XLOOKUP(K1135,'FX rates'!$A$2:$A$38,'FX rates'!$B$2:$B$38)) -> 0 | AJ1135: =Q1135*(_xlfn.XLOOKUP(K1135,'FX rates'!$A$2:$A$38,'FX rates'!$B$2:$B$38)) -> 0 | AK1135: =R1135*(_xlfn.XLOOKUP(K1135,'FX rates'!$A$2:$A$38,'FX rates'!$B$2:$B$38)) -> 0 | AP1135: =M1135/L1135 -> 1.1428571 | AQ1135: =O1135/L1135 -> 0 | AR1135: =X1135*(1+AP1135) -> 406296 | AS1135: =IF(AQ1135>0,X1135*(1+AQ1135),"0") -> 0 | AT1135: =AD1135*(0.9) -> 536310.72 | AU1135: =AD1135-AT1135 -> 59590.08
... A2001: Employee 999 | B2001: Director | C2001: Edinburgh | D2001: United Kingdom | E2001: EMEA | F2001: 43622 | G2001: 44896 | H2001: Client Businesses Platform | I2001: O | J2001: K | K2001: GBP | L2001: 127050 | M2001: 40837.5 | N2001: 0 | O2001: 0 | P2001: =M2001+N2001+O2001 -> 40837.5 | Q2001: 0 | R2001: 0 | S2001: 0 | T2001: =+Q2001+R2001+S2001 -> 0 | U2001: 0 | V2001: =L2001+P2001+T2001+U2001 -> 167887.5 | W2001: GBP | X2001: 129591 | Y2001: =X2001+AR2001+AS2001 -> 300836.25 | Z2001: {=_xlfn.IFS(YEARFRAC(F2001,G2001)<1,"<1 Year",YEARFRAC(F2001,G2001)<=5,"1-5 Years",YEARFRAC(F2001,G2001)>5,">5 Years")} -> 1-5 Years | AA2001: =L2001*(_xlfn.XLOOKUP(K2001,'FX rates'!$A$2:$A$38,'FX rates'!$B$2:$B$38)) -> 169059.08 | AB2001: =V2001*(_xlfn.XLOOKUP(K2001,'FX rates'!$A$2:$A$38,'FX rates'!$B$2:$B$38)) -> 223399.5 | AC2001: =X2001*(_xlfn.XLOOKUP(W2001,'FX rates'!$A$2:$A$38,'FX rates'!$B$2:$B$38)) -> 172440.26 | AD2001: =Y2001*(_xlfn.XLOOKUP(W2001,'FX rates'!$A$2:$A$38,'FX rates'!$B$2:$B$38)) -> 400307.76 | AE2001: =(AC2001-AA2001)/AA2001 -> 0.02 | AF2001: =X2001-L2001 -> 2541 | AG2001: =AB2001-AA2001 -> 54340.419 | AH2001: =AC2001/X2001 -> 1.33065 | AI2001: =U2001*(_xlfn.XLOOKUP(K2001,'FX rates'!$A$2:$A$38,'FX rates'!$B$2:$B$38)) -> 0 | AJ2001: =Q2001*(_xlfn.XLOOKUP(K2001,'FX rates'!$A$2:$A$38,'FX rates'!$B$2:$B$38)) -> 0 | AK2001: =R2001*(_xlfn.XLOOKUP(K2001,'FX rates'!$A$2:$A$38,'FX rates'!$B$2:$B$38)) -> 0 | AP2001: =M2001/L2001 -> 0.32142857 | AQ2001: =O2001/L2001 -> 0 | AR2001: =X2001*(1+AP2001) -> 171245.25 | AS2001: =IF(AQ2001>0,X2001*(1+AQ2001),"0") -> 0 | AT2001: =AD2001*(0.9) -> 360276.98 | AU2001: =AD2001-AT2001 -> 40030.776
AT2003: Bonus Question - | AU2003: =SUM(AU2:AU2001) -> 1.1779905e+08

Sheet FX rates
A1: Currency | B1: FX rate
A2: AUD | B2: 0.75665
A3: AED | B3: 0.27224589
A4: BHD | B4: 2.6476039
A5: USD | B5: 1
A6: BRL | B6: 0.26852486
A7: CAD | B7: 0.77089115
A8: CLP | B8: 0.0015831176
A9: CNY | B9: 0.15622559
A10: COP | B10: 0.00034625979
A11: DKK | B11: 0.15682462
A12: EUR | B12: 1.1673
A13: DEM | B13: 0.59681895
... A38: UYU | B38: 0.03202562

Sheet Total Compensation Pivots
A3: Row Labels | B3: Average of 2021 Total Compensation USD | D3: Row Labels | E3: Average of 2021 Total Compensation USD
A4: Administrative Assistant | D4: Administrative Assistant | E4: 104556.14
A5: Australia | D5: Analyst | E5: 91665.651
A6: Asia-Pacific | D6: Associate | E6: 118628.42
A7: Client Businesses Platform | B7: 24492.95 | D7: Director | E7: 388124.62
A8: Asia-Pacific Total | B8: 24492.95 | D8: Employee Fixed Term | E8: 215759.86
A9: Australia Total | B9: 24492.95 | D9: Executive Assistant | E9: 165257.67
A10: Hong Kong | B10: 114326.6 | D10: FutureAdvisor | E10: 193105.77
A11: Italy | D11: Managing Director | E11: 1547275.2
A12: EMEA | D12: Specialist | E12: 88770.683
A13: Regional Platform | B13: 33674.113 | D13: Vice President | E13: 203115.98
A14: EMEA Total | B14: 33674.113 | D14: Grand Total | E14: 515825.97
A15: Italy Total | B15: 33674.113
A16: Japan | D16: Row Labels | E16: Average of 2021 Total Compensation USD
A17: Asia-Pacific | D17: United States of America | E17: 559927.58
A18: Client Businesses Platform | B18: 97855.401 | D18: Ireland | E18: 537961.7 | I18: United States of America | J18: 559927.58
A19: Asia-Pacific Total | B19: 97855.401 | D19: United Kingdom | E19: 535862.99 | I19: Ireland | J19: 537961.7
A20: Japan Total | B20: 97855.401 | D20: Singapore | E20: 410464.14 | I20: United Kingdom | J20: 535862.99
A21: Singapore | D21: Switzerland | E21: 400189.73 | I21: Singapore | J21: 410464.14
A22: Asia-Pacific | D22: United Arab Emirates | E22: 396465.3 | I22: Switzerland | J22: 400189.73
A23: Regional Platform | B23: 89944.297 | D23: Hungary | E23: 393153.85 | I23: United Arab Emirates | J23: 396465.3
A24: Asia-Pacific Total | B24: 89944.297 | D24: France | E24: 382101.65 | I24: Hungary | J24: 393153.85
A25: Singapore Total | B25: 89944.297 | D25: Israel | E25: 366797.18 | I25: France | J25: 382101.65
A26: United Kingdom | D26: Hong Kong | E26: 356580.01 | I26: Israel | J26: 366797.18
A27: EMEA | D27: Colombia | E27: 351619.69 | I27: Hong Kong | J27: 356580.01
A28: Client Businesses Platform | B28: 83926.091 | D28: Chile | E28: 329818.06 | I28: Colombia | J28: 351619.69
A29: Corporate and Risk Platform | B29: 88499.136 | D29: Canada | E29: 293910.9 | I29: Chile | J29: 329818.06
A30: ETF and Index Investments Platform | B30: 96707.65 | D30: Italy | E30: 276058.53 | I30: Canada | J30: 293910.9
A31: Investments Platform | B31: 82404.593 | D31: Belgium | E31: 271732.51 | I31: Italy | J31: 276058.53
A32: Operating Platform | B32: 96312.447 | D32: Netherlands | E32: 270444.54 | I32: Belgium | J32: 271732.51
A33: Regional Platform | B33: 55013.728 | D33: Australia | E33: 261418.1 | I33: Netherlands | J33: 270444.54
A34: EMEA Total | B34: 84553.105 | D34: Japan | E34: 254492.66 | I34: Australia | J34: 261418.1
A35: United Kingdom Total | B35: 84553.105 | D35: Austria | E35: 252645.74 | I35: Japan | J35: 254492.66
A36: United States of America | D36: Korea, Republic of | E36: 234625.26 | I36: Austria | J36: 252645.74
A37: Americas | D37: Spain | E37: 212772.76 | I37: Korea, Republic of | J37: 234625.26
A38: Client Businesses Platform | B38: 114970.52 | D38: Germany | E38: 202407.84 | I38: Spain | J38: 212772.76
A39: Corporate and Risk Platform | B39: 104109.75 | D39: South Africa | E39: 187256.22 | I39: Germany | J39: 202407.84
A40: ETF and Index Investments Platform | B40: 155750 | D40: Taiwan | E40: 167733.04 | I40: South Africa | J40: 187256.22
A41: Investments Platform | B41: 119623.38 | D41: Mexico | E41: 154706.53 | I41: Taiwan | J41: 167733.04
A42: Operating Platform | B42: 103777.55 | D42: Denmark | E42: 128556.76 | I42: Mexico | J42: 154706.53
...

Sheet Employee Count Pivots
A3: Row Labels | B3: Count of Worker | D3: Row Labels | E3: Count of Worker
A4: Administrative Assistant | D4: Administrative Assistant | E4: 53
A5: Australia | D5: Analyst | E5: 19
A6: Asia-Pacific | D6: Associate | E6: 208
A7: Client Businesses Platform | B7: 1 | D7: Director | E7: 687
A8: Asia-Pacific Total | B8: 1 | D8: Employee Fixed Term | E8: 2
A9: Australia Total | B9: 1 | D9: Executive Assistant | E9: 28
A10: Hong Kong | D10: FutureAdvisor | E10: 4
A11: Asia-Pacific | D11: Managing Director | E11: 391
A12: Client Businesses Platform | B12: 1 | D12: Specialist | E12: 11
A13: Corporate and Risk Platform | B13: 1 | D13: Vice President | E13: 597
A14: Investments Platform | B14: 1 | D14: Grand Total | E14: 2000
A15: Asia-Pacific Total | B15: 3
A16: Hong Kong Total | B16: 3 | D16: Row Labels | E16: Count of Worker
A17: Italy | D17: Australia | E17: 38
A18: EMEA | D18: Austria | E18: 2
A19: Regional Platform | B19: 1 | D19: Belgium | E19: 2
A20: EMEA Total | B20: 1 | D20: Canada | E20: 24
A21: Italy Total | B21: 1 | D21: Chile | E21: 1
A22: Japan | D22: Colombia | E22: 1
A23: Asia-Pacific | D23: Denmark | E23: 2
A24: Client Businesses Platform | B24: 1 | D24: France | E24: 4
A25: Asia-Pacific Total | B25: 1 | D25: Germany | E25: 16
A26: Japan Total | B26: 1 | D26: Hong Kong | E26: 45
A27: Singapore | D27: Hungary | E27: 1
A28: Asia-Pacific | D28: India | E28: 18
A29: Regional Platform | B29: 1 | D29: Ireland | E29: 2
A30: Asia-Pacific Total | B30: 1 | D30: Israel | E30: 2
A31: Singapore Total | B31: 1 | D31: Italy | E31: 4
A32: United Kingdom | D32: Japan | E32: 65
A33: EMEA | D33: Korea, Republic of | E33: 4
A34: Client Businesses Platform | B34: 3 | D34: Mexico | E34: 1
A35: Corporate and Risk Platform | B35: 1 | D35: Netherlands | E35: 6
A36: ETF and Index Investments Platform | B36: 2 | D36: Singapore | E36: 33
A37: Investments Platform | B37: 4 | D37: South Africa | E37: 1
A38: Operating Platform | B38: 1 | D38: Spain | E38: 1
A39: Regional Platform | B39: 1 | D39: Switzerland | E39: 5
A40: EMEA Total | B40: 12 | D40: Taiwan | E40: 3
A41: United Kingdom Total | B41: 12 | D41: United Arab Emirates | E41: 1
A42: United States of America | D42: United Kingdom | E42: 437
...

Sheet Regional Analysis of SM
A1: Length of Service | B1: >5 Years
A3: Row Labels | B3: Sum of 2021 Total Compensation
A4: Director
A5: Americas | B5: 2.8721001e+08
A6: Asia-Pacific | B6: 8.4244034e+08
A7: EMEA | B7: 18974360
A8: Director Total | B8: 1.1486247e+09
A9: Managing Director
A10: Americas | B10: 1.2653561e+08
A11: Asia-Pacific | B11: 20619146
A12: EMEA | B12: 71257943
A13: Managing Director Total | B13: 2.184127e+08
A14: Grand Total | B14: 1.3670374e+09
